Workbook

Sheet Parametros
A1: Análisis nodal: IPR de Vogel y VLP simplificada (modelo didáctico)
A2: Datos de ejemplo (sintéticos) con fines didácticos. Celdas azules sobre fondo crema = entradas editables; el resto son fórmulas.
A4: Parámetro | B4: Valor | C4: Unidad
A5: Presión de reservorio pr | B5: 250 | C5: bar
A6: Índice de productividad J | B6: 1.5 | C6: m³/d/bar
A7: Corte de agua | B7: 0 | C7: fracción
A8: Presión en boca de pozo | B8: 10 | C8: bar
A9: Gas inyectado (gas lift) | B9: 0 | C9: m³/m³
A10: Diámetro de tubing | B10: 3.5 | C10: pulgadas
A11: Profundidad vertical | B11: 2000 | C11: m
A12: Densidad del petróleo | B12: 800 | C12: kg/m³
A13: Densidad del agua | B13: 1030 | C13: kg/m³
A15: qmáx de Vogel = J·pr/1,8 | B15: =B6*B5/1.8 -> 208.33333 | C15: m³/d
A17: Modelo didáctico: columna de mezcla aligerada por el gas y fricción escalada con el caudal y el diámetro. No reemplaza a un simulador de flujo multifásico calibrado con datos del pozo.

Sheet Curvas
A1: Curvas IPR y VLP
A2: Datos de ejemplo (sintéticos) con fines didácticos. Celdas azules sobre fondo crema = entradas editables; el resto son fórmulas.
A4: Caudal (m³/d) | B4: IPR: Pwf (bar) | C4: VLP: Pwf (bar) | D4: IPR − VLP | E4: Antes del cruce (1/0)
A5: =0/100*Parametros!$B$15 -> 0 | B5: =IF(A5>=Parametros!$B$15,0,Parametros!$B$5*(-0.2+SQRT(0.04+3.2*(1-A5/Parametros!$B$15)))/1.6) -> 250 | C5: =Parametros!$B$8+(Parametros!$B$12*(1-Parametros!$B$7)+Parametros!$B$13*Parametros!$B$7)*(1-0.55*Parametros!$B$9/(Parametros!$B$9+150))*9.81*Parametros!$B$11/100000+5*(A5/200)^1.8*(3.5/Parametros!$B$10)^4.8 -> 166.96 | D5: =B5-C5 -> 83.04 | E5: =IF(D5>0,1,0) -> 1
A6: =1/100*Parametros!$B$15 -> 2.0833333 | B6: =IF(A6>=Parametros!$B$15,0,Parametros!$B$5*(-0.2+SQRT(0.04+3.2*(1-A6/Parametros!$B$15)))/1.6) -> 248.60766 | C6: =Parametros!$B$8+(Parametros!$B$12*(1-Parametros!$B$7)+Parametros!$B$13*Parametros!$B$7)*(1-0.55*Parametros!$B$9/(Parametros!$B$9+150))*9.81*Parametros!$B$11/100000+5*(A6/200)^1.8*(3.5/Parametros!$B$10)^4.8 -> 166.96135 | D6: =B6-C6 -> 81.646313 | E6: =IF(D6>0,1,0) -> 1
A7: =2/100*Parametros!$B$15 -> 4.1666667 | B7: =IF(A7>=Parametros!$B$15,0,Parametros!$B$5*(-0.2+SQRT(0.04+3.2*(1-A7/Parametros!$B$15)))/1.6) -> 247.20837 | C7: =Parametros!$B$8+(Parametros!$B$12*(1-Parametros!$B$7)+Parametros!$B$13*Parametros!$B$7)*(1-0.55*Parametros!$B$9/(Parametros!$B$9+150))*9.81*Parametros!$B$11/100000+5*(A7/200)^1.8*(3.5/Parametros!$B$10)^4.8 -> 166.96471 | D7: =B7-C7 -> 80.243661 | E7: =IF(D7>0,1,0) -> 1
A8: =3/100*Parametros!$B$15 -> 6.25 | B8: =IF(A8>=Parametros!$B$15,0,Parametros!$B$5*(-0.2+SQRT(0.04+3.2*(1-A8/Parametros!$B$15)))/1.6) -> 245.802 | C8: =Parametros!$B$8+(Parametros!$B$12*(1-Parametros!$B$7)+Parametros!$B$13*Parametros!$B$7)*(1-0.55*Parametros!$B$9/(Parametros!$B$9+150))*9.81*Parametros!$B$11/100000+5*(A8/200)^1.8*(3.5/Parametros!$B$10)^4.8 -> 166.96977 | D8: =B8-C8 -> 78.832238 | E8: =IF(D8>0,1,0) -> 1
A9: =4/100*Parametros!$B$15 -> 8.3333333 | B9: =IF(A9>=Parametros!$B$15,0,Parametros!$B$5*(-0.2+SQRT(0.04+3.2*(1-A9/Parametros!$B$15)))/1.6) -> 244.38846 | C9: =Parametros!$B$8+(Parametros!$B$12*(1-Parametros!$B$7)+Parametros!$B$13*Parametros!$B$7)*(1-0.55*Parametros!$B$9/(Parametros!$B$9+150))*9.81*Parametros!$B$11/100000+5*(A9/200)^1.8*(3.5/Parametros!$B$10)^4.8 -> 166.97639 | D9: =B9-C9 -> 77.412073 | E9: =IF(D9>0,1,0) -> 1
A10: =5/100*Parametros!$B$15 -> 10.416667 | B10: =IF(A10>=Parametros!$B$15,0,Parametros!$B$5*(-0.2+SQRT(0.04+3.2*(1-A10/Parametros!$B$15)))/1.6) -> 242.96764 | C10: =Parametros!$B$8+(Parametros!$B$12*(1-Parametros!$B$7)+Parametros!$B$13*Parametros!$B$7)*(1-0.55*Parametros!$B$9/(Parametros!$B$9+150))*9.81*Parametros!$B$11/100000+5*(A10/200)^1.8*(3.5/Parametros!$B$10)^4.8 -> 166.98449 | D10: =B10-C10 -> 75.983145 | E10: =IF(D10>0,1,0) -> 1
A11: =6/100*Parametros!$B$15 -> 12.5 | B11: =IF(A11>=Parametros!$B$15,0,Parametros!$B$5*(-0.2+SQRT(0.04+3.2*(1-A11/Parametros!$B$15)))/1.6) -> 241.53941 | C11: =Parametros!$B$8+(Parametros!$B$12*(1-Parametros!$B$7)+Parametros!$B$13*Parametros!$B$7)*(1-0.55*Parametros!$B$9/(Parametros!$B$9+150))*9.81*Parametros!$B$11/100000+5*(A11/200)^1.8*(3.5/Parametros!$B$10)^4.8 -> 166.99401 | D11: =B11-C11 -> 74.545405 | E11: =IF(D11>0,1,0) -> 1
A12: =7/100*Parametros!$B$15 -> 14.583333 | B12: =IF(A12>=Parametros!$B$15,0,Parametros!$B$5*(-0.2+SQRT(0.04+3.2*(1-A12/Parametros!$B$15)))/1.6) -> 240.10367 | C12: =Parametros!$B$8+(Parametros!$B$12*(1-Parametros!$B$7)+Parametros!$B$13*Parametros!$B$7)*(1-0.55*Parametros!$B$9/(Parametros!$B$9+150))*9.81*Parametros!$B$11/100000+5*(A12/200)^1.8*(3.5/Parametros!$B$10)^4.8 -> 167.00488 | D12: =B12-C12 -> 73.098786 | E12: =IF(D12>0,1,0) -> 1
A13: =8/100*Parametros!$B$15 -> 16.666667 | B13: =IF(A13>=Parametros!$B$15,0,Parametros!$B$5*(-0.2+SQRT(0.04+3.2*(1-A13/Parametros!$B$15)))/1.6) -> 238.66029 | C13: =Parametros!$B$8+(Parametros!$B$12*(1-Parametros!$B$7)+Parametros!$B$13*Parametros!$B$7)*(1-0.55*Parametros!$B$9/(Parametros!$B$9+150))*9.81*Parametros!$B$11/100000+5*(A13/200)^1.8*(3.5/Parametros!$B$10)^4.8 -> 167.01707 | D13: =B13-C13 -> 71.643211 | E13: =IF(D13>0,1,0) -> 1
A14: =9/100*Parametros!$B$15 -> 18.75 | B14: =IF(A14>=Parametros!$B$15,0,Parametros!$B$5*(-0.2+SQRT(0.04+3.2*(1-A14/Parametros!$B$15)))/1.6) -> 237.20914 | C14: =Parametros!$B$8+(Parametros!$B$12*(1-Parametros!$B$7)+Parametros!$B$13*Parametros!$B$7)*(1-0.55*Parametros!$B$9/(Parametros!$B$9+150))*9.81*Parametros!$B$11/100000+5*(A14/200)^1.8*(3.5/Parametros!$B$10)^4.8 -> 167.03055 | D14: =B14-C14 -> 70.178591 | E14: =IF(D14>0,1,0) -> 1
A15: =10/100*Parametros!$B$15 -> 20.833333 | B15: =IF(A15>=Parametros!$B$15,0,Parametros!$B$5*(-0.2+SQRT(0.04+3.2*(1-A15/Parametros!$B$15)))/1.6) -> 235.75012 | C15: =Parametros!$B$8+(Parametros!$B$12*(1-Parametros!$B$7)+Parametros!$B$13*Parametros!$B$7)*(1-0.55*Parametros!$B$9/(Parametros!$B$9+150))*9.81*Parametros!$B$11/100000+5*(A15/200)^1.8*(3.5/Parametros!$B$10)^4.8 -> 167.04529 | D15: =B15-C15 -> 68.70483 | E15: =IF(D15>0,1,0) -> 1
A16: =11/100*Parametros!$B$15 -> 22.916667 | B16: =IF(A16>=Parametros!$B$15,0,Parametros!$B$5*(-0.2+SQRT(0.04+3.2*(1-A16/Parametros!$B$15)))/1.6) -> 234.28307 | C16: =Parametros!$B$8+(Parametros!$B$12*(1-Parametros!$B$7)+Parametros!$B$13*Parametros!$B$7)*(1-0.55*Parametros!$B$9/(Parametros!$B$9+150))*9.81*Parametros!$B$11/100000+5*(A16/200)^1.8*(3.5/Parametros!$B$10)^4.8 -> 167.06125 | D16: =B16-C16 -> 67.221824 | E16: =IF(D16>0,1,0) -> 1
A17: =12/100*Parametros!$B$15 -> 25 | B17: =IF(A17>=Parametros!$B$15,0,Parametros!$B$5*(-0.2+SQRT(0.04+3.2*(1-A17/Parametros!$B$15)))/1.6) -> 232.80788 | C17: =Parametros!$B$8+(Parametros!$B$12*(1-Parametros!$B$7)+Parametros!$B$13*Parametros!$B$7)*(1-0.55*Parametros!$B$9/(Parametros!$B$9+150))*9.81*Parametros!$B$11/100000+5*(A17/200)^1.8*(3.5/Parametros!$B$10)^4.8 -> 167.07842 | D17: =B17-C17 -> 65.729462 | E17: =IF(D17>0,1,0) -> 1
A18: =13/100*Parametros!$B$15 -> 27.083333 | B18: =IF(A18>=Parametros!$B$15,0,Parametros!$B$5*(-0.2+SQRT(0.04+3.2*(1-A18/Parametros!$B$15)))/1.6) -> 231.32439 | C18: =Parametros!$B$8+(Parametros!$B$12*(1-Parametros!$B$7)+Parametros!$B$13*Parametros!$B$7)*(1-0.55*Parametros!$B$9/(Parametros!$B$9+150))*9.81*Parametros!$B$11/100000+5*(A18/200)^1.8*(3.5/Parametros!$B$10)^4.8 -> 167.09677 | D18: =B18-C18 -> 64.227628 | E18: =IF(D18>0,1,0) -> 1
A19: =14/100*Parametros!$B$15 -> 29.166667 | B19: =IF(A19>=Parametros!$B$15,0,Parametros!$B$5*(-0.2+SQRT(0.04+3.2*(1-A19/Parametros!$B$15)))/1.6) -> 229.83248 | C19: =Parametros!$B$8+(Parametros!$B$12*(1-Parametros!$B$7)+Parametros!$B$13*Parametros!$B$7)*(1-0.55*Parametros!$B$9/(Parametros!$B$9+150))*9.81*Parametros!$B$11/100000+5*(A19/200)^1.8*(3.5/Parametros!$B$10)^4.8 -> 167.11628 | D19: =B19-C19 -> 62.716199 | E19: =IF(D19>0,1,0) -> 1
A20: =15/100*Parametros!$B$15 -> 31.25 | B20: =IF(A20>=Parametros!$B$15,0,Parametros!$B$5*(-0.2+SQRT(0.04+3.2*(1-A20/Parametros!$B$15)))/1.6) -> 228.332 | C20: =Parametros!$B$8+(Parametros!$B$12*(1-Parametros!$B$7)+Parametros!$B$13*Parametros!$B$7)*(1-0.55*Parametros!$B$9/(Parametros!$B$9+150))*9.81*Parametros!$B$11/100000+5*(A20/200)^1.8*(3.5/Parametros!$B$10)^4.8 -> 167.13695 | D20: =B20-C20 -> 61.195048 | E20: =IF(D20>0,1,0) -> 1
A21: =16/100*Parametros!$B$15 -> 33.333333 | B21: =IF(A21>=Parametros!$B$15,0,Parametros!$B$5*(-0.2+SQRT(0.04+3.2*(1-A21/Parametros!$B$15)))/1.6) -> 226.82279 | C21: =Parametros!$B$8+(Parametros!$B$12*(1-Parametros!$B$7)+Parametros!$B$13*Parametros!$B$7)*(1-0.55*Parametros!$B$9/(Parametros!$B$9+150))*9.81*Parametros!$B$11/100000+5*(A21/200)^1.8*(3.5/Parametros!$B$10)^4.8 -> 167.15875 | D21: =B21-C21 -> 59.66404 | E21: =IF(D21>0,1,0) -> 1
A22: =17/100*Parametros!$B$15 -> 35.416667 | B22: =IF(A22>=Parametros!$B$15,0,Parametros!$B$5*(-0.2+SQRT(0.04+3.2*(1-A22/Parametros!$B$15)))/1.6) -> 225.3047 | C22: =Parametros!$B$8+(Parametros!$B$12*(1-Parametros!$B$7)+Parametros!$B$13*Parametros!$B$7)*(1-0.55*Parametros!$B$9/(Parametros!$B$9+150))*9.81*Parametros!$B$11/100000+5*(A22/200)^1.8*(3.5/Parametros!$B$10)^4.8 -> 167.18166 | D22: =B22-C22 -> 58.123036 | E22: =IF(D22>0,1,0) -> 1
A23: =18/100*Parametros!$B$15 -> 37.5 | B23: =IF(A23>=Parametros!$B$15,0,Parametros!$B$5*(-0.2+SQRT(0.04+3.2*(1-A23/Parametros!$B$15)))/1.6) -> 223.77757 | C23: =Parametros!$B$8+(Parametros!$B$12*(1-Parametros!$B$7)+Parametros!$B$13*Parametros!$B$7)*(1-0.55*Parametros!$B$9/(Parametros!$B$9+150))*9.81*Parametros!$B$11/100000+5*(A23/200)^1.8*(3.5/Parametros!$B$10)^4.8 -> 167.20568 | D23: =B23-C23 -> 56.571891 | E23: =IF(D23>0,1,0) -> 1
A24: =19/100*Parametros!$B$15 -> 39.583333 | B24: =IF(A24>=Parametros!$B$15,0,Parametros!$B$5*(-0.2+SQRT(0.04+3.2*(1-A24/Parametros!$B$15)))/1.6) -> 222.24125 | C24: =Parametros!$B$8+(Parametros!$B$12*(1-Parametros!$B$7)+Parametros!$B$13*Parametros!$B$7)*(1-0.55*Parametros!$B$9/(Parametros!$B$9+150))*9.81*Parametros!$B$11/100000+5*(A24/200)^1.8*(3.5/Parametros!$B$10)^4.8 -> 167.23079 | D24: =B24-C24 -> 55.010454 | E24: =IF(D24>0,1,0) -> 1
A25: =20/100*Parametros!$B$15 -> 41.666667 | B25: =IF(A25>=Parametros!$B$15,0,Parametros!$B$5*(-0.2+SQRT(0.04+3.2*(1-A25/Parametros!$B$15)))/1.6) -> 220.69555 | C25: =Parametros!$B$8+(Parametros!$B$12*(1-Parametros!$B$7)+Parametros!$B$13*Parametros!$B$7)*(1-0.55*Parametros!$B$9/(Parametros!$B$9+150))*9.81*Parametros!$B$11/100000+5*(A25/200)^1.8*(3.5/Parametros!$B$10)^4.8 -> 167.25699 | D25: =B25-C25 -> 53.438569 | E25: =IF(D25>0,1,0) -> 1
A26: =21/100*Parametros!$B$15 -> 43.75 | B26: =IF(A26>=Parametros!$B$15,0,Parametros!$B$5*(-0.2+SQRT(0.04+3.2*(1-A26/Parametros!$B$15)))/1.6) -> 219.14032 | C26: =Parametros!$B$8+(Parametros!$B$12*(1-Parametros!$B$7)+Parametros!$B$13*Parametros!$B$7)*(1-0.55*Parametros!$B$9/(Parametros!$B$9+150))*9.81*Parametros!$B$11/100000+5*(A26/200)^1.8*(3.5/Parametros!$B$10)^4.8 -> 167.28425 | D26: =B26-C26 -> 51.856073 | E26: =IF(D26>0,1,0) -> 1
A27: =22/100*Parametros!$B$15 -> 45.833333 | B27: =IF(A27>=Parametros!$B$15,0,Parametros!$B$5*(-0.2+SQRT(0.04+3.2*(1-A27/Parametros!$B$15)))/1.6) -> 217.57537 | C27: =Parametros!$B$8+(Parametros!$B$12*(1-Parametros!$B$7)+Parametros!$B$13*Parametros!$B$7)*(1-0.55*Parametros!$B$9/(Parametros!$B$9+150))*9.81*Parametros!$B$11/100000+5*(A27/200)^1.8*(3.5/Parametros!$B$10)^4.8 -> 167.31257 | D27: =B27-C27 -> 50.262798 | E27: =IF(D27>0,1,0) -> 1
A28: =23/100*Parametros!$B$15 -> 47.916667 | B28: =IF(A28>=Parametros!$B$15,0,Parametros!$B$5*(-0.2+SQRT(0.04+3.2*(1-A28/Parametros!$B$15)))/1.6) -> 216.00051 | C28: =Parametros!$B$8+(Parametros!$B$12*(1-Parametros!$B$7)+Parametros!$B$13*Parametros!$B$7)*(1-0.55*Parametros!$B$9/(Parametros!$B$9+150))*9.81*Parametros!$B$11/100000+5*(A28/200)^1.8*(3.5/Parametros!$B$10)^4.8 -> 167.34194 | D28: =B28-C28 -> 48.658568 | E28: =IF(D28>0,1,0) -> 1
A29: =24/100*Parametros!$B$15 -> 50 | B29: =IF(A29>=Parametros!$B$15,0,Parametros!$B$5*(-0.2+SQRT(0.04+3.2*(1-A29/Parametros!$B$15)))/1.6) -> 214.41555 | C29: =Parametros!$B$8+(Parametros!$B$12*(1-Parametros!$B$7)+Parametros!$B$13*Parametros!$B$7)*(1-0.55*Parametros!$B$9/(Parametros!$B$9+150))*9.81*Parametros!$B$11/100000+5*(A29/200)^1.8*(3.5/Parametros!$B$10)^4.8 -> 167.37235 | D29: =B29-C29 -> 47.043204 | E29: =IF(D29>0,1,0) -> 1
A30: =25/100*Parametros!$B$15 -> 52.083333 | B30: =IF(A30>=Parametros!$B$15,0,Parametros!$B$5*(-0.2+SQRT(0.04+3.2*(1-A30/Parametros!$B$15)))/1.6) -> 212.8203 | C30: =Parametros!$B$8+(Parametros!$B$12*(1-Parametros!$B$7)+Parametros!$B$13*Parametros!$B$7)*(1-0.55*Parametros!$B$9/(Parametros!$B$9+150))*9.81*Parametros!$B$11/100000+5*(A30/200)^1.8*(3.5/Parametros!$B$10)^4.8 -> 167.40379 | D30: =B30-C30 -> 45.416516 | E30: =IF(D30>0,1,0) -> 1
A31: =26/100*Parametros!$B$15 -> 54.166667 | B31: =IF(A31>=Parametros!$B$15,0,Parametros!$B$5*(-0.2+SQRT(0.04+3.2*(1-A31/Parametros!$B$15)))/1.6) -> 211.21456 | C31: =Parametros!$B$8+(Parametros!$B$12*(1-Parametros!$B$7)+Parametros!$B$13*Parametros!$B$7)*(1-0.55*Parametros!$B$9/(Parametros!$B$9+150))*9.81*Parametros!$B$11/100000+5*(A31/200)^1.8*(3.5/Parametros!$B$10)^4.8 -> 167.43625 | D31: =B31-C31 -> 43.778311 | E31: =IF(D31>0,1,0) -> 1
A32: =27/100*Parametros!$B$15 -> 56.25 | B32: =IF(A32>=Parametros!$B$15,0,Parametros!$B$5*(-0.2+SQRT(0.04+3.2*(1-A32/Parametros!$B$15)))/1.6) -> 209.59811 | C32: =Parametros!$B$8+(Parametros!$B$12*(1-Parametros!$B$7)+Parametros!$B$13*Parametros!$B$7)*(1-0.55*Parametros!$B$9/(Parametros!$B$9+150))*9.81*Parametros!$B$11/100000+5*(A32/200)^1.8*(3.5/Parametros!$B$10)^4.8 -> 167.46973 | D32: =B32-C32 -> 42.128385 | E32: =IF(D32>0,1,0) -> 1
A33: =28/100*Parametros!$B$15 -> 58.333333 | B33: =IF(A33>=Parametros!$B$15,0,Parametros!$B$5*(-0.2+SQRT(0.04+3.2*(1-A33/Parametros!$B$15)))/1.6) -> 207.97074 | C33: =Parametros!$B$8+(Parametros!$B$12*(1-Parametros!$B$7)+Parametros!$B$13*Parametros!$B$7)*(1-0.55*Parametros!$B$9/(Parametros!$B$9+150))*9.81*Parametros!$B$11/100000+5*(A33/200)^1.8*(3.5/Parametros!$B$10)^4.8 -> 167.50421 | D33: =B33-C33 -> 40.46653 | E33: =IF(D33>0,1,0) -> 1
A34: =29/100*Parametros!$B$15 -> 60.416667 | B34: =IF(A34>=Parametros!$B$15,0,Parametros!$B$5*(-0.2+SQRT(0.04+3.2*(1-A34/Parametros!$B$15)))/1.6) -> 206.33222 | C34: =Parametros!$B$8+(Parametros!$B$12*(1-Parametros!$B$7)+Parametros!$B$13*Parametros!$B$7)*(1-0.55*Parametros!$B$9/(Parametros!$B$9+150))*9.81*Parametros!$B$11/100000+5*(A34/200)^1.8*(3.5/Parametros!$B$10)^4.8 -> 167.53969 | D34: =B34-C34 -> 38.792529 | E34: =IF(D34>0,1,0) -> 1
A35: =30/100*Parametros!$B$15 -> 62.5 | B35: =IF(A35>=Parametros!$B$15,0,Parametros!$B$5*(-0.2+SQRT(0.04+3.2*(1-A35/Parametros!$B$15)))/1.6) -> 204.68233 | C35: =Parametros!$B$8+(Parametros!$B$12*(1-Parametros!$B$7)+Parametros!$B$13*Parametros!$B$7)*(1-0.55*Parametros!$B$9/(Parametros!$B$9+150))*9.81*Parametros!$B$11/100000+5*(A35/200)^1.8*(3.5/Parametros!$B$10)^4.8 -> 167.57617 | D35: =B35-C35 -> 37.106157 | E35: =IF(D35>0,1,0) -> 1
A36: =31/100*Parametros!$B$15 -> 64.583333 | B36: =IF(A36>=Parametros!$B$15,0,Parametros!$B$5*(-0.2+SQRT(0.04+3.2*(1-A36/Parametros!$B$15)))/1.6) -> 203.02081 | C36: =Parametros!$B$8+(Parametros!$B$12*(1-Parametros!$B$7)+Parametros!$B$13*Parametros!$B$7)*(1-0.55*Parametros!$B$9/(Parametros!$B$9+150))*9.81*Parametros!$B$11/100000+5*(A36/200)^1.8*(3.5/Parametros!$B$10)^4.8 -> 167.61363 | D36: =B36-C36 -> 35.407179 | E36: =IF(D36>0,1,0) -> 1
A37: =32/100*Parametros!$B$15 -> 66.666667 | B37: =IF(A37>=Parametros!$B$15,0,Parametros!$B$5*(-0.2+SQRT(0.04+3.2*(1-A37/Parametros!$B$15)))/1.6) -> 201.34743 | C37: =Parametros!$B$8+(Parametros!$B$12*(1-Parametros!$B$7)+Parametros!$B$13*Parametros!$B$7)*(1-0.55*Parametros!$B$9/(Parametros!$B$9+150))*9.81*Parametros!$B$11/100000+5*(A37/200)^1.8*(3.5/Parametros!$B$10)^4.8 -> 167.65207 | D37: =B37-C37 -> 33.695353 | E37: =IF(D37>0,1,0) -> 1
A38: =33/100*Parametros!$B$15 -> 68.75 | B38: =IF(A38>=Parametros!$B$15,0,Parametros!$B$5*(-0.2+SQRT(0.04+3.2*(1-A38/Parametros!$B$15)))/1.6) -> 199.66192 | C38: =Parametros!$B$8+(Parametros!$B$12*(1-Parametros!$B$7)+Parametros!$B$13*Parametros!$B$7)*(1-0.55*Parametros!$B$9/(Parametros!$B$9+150))*9.81*Parametros!$B$11/100000+5*(A38/200)^1.8*(3.5/Parametros!$B$10)^4.8 -> 167.69149 | D38: =B38-C38 -> 31.970428 | E38: =IF(D38>0,1,0) -> 1
A39: =34/100*Parametros!$B$15 -> 70.833333 | B39: =IF(A39>=Parametros!$B$15,0,Parametros!$B$5*(-0.2+SQRT(0.04+3.2*(1-A39/Parametros!$B$15)))/1.6) -> 197.96401 | C39: =Parametros!$B$8+(Parametros!$B$12*(1-Parametros!$B$7)+Parametros!$B$13*Parametros!$B$7)*(1-0.55*Parametros!$B$9/(Parametros!$B$9+150))*9.81*Parametros!$B$11/100000+5*(A39/200)^1.8*(3.5/Parametros!$B$10)^4.8 -> 167.73187 | D39: =B39-C39 -> 30.232141 | E39: =IF(D39>0,1,0) -> 1
A40: =35/100*Parametros!$B$15 -> 72.916667 | B40: =IF(A40>=Parametros!$B$15,0,Parametros!$B$5*(-0.2+SQRT(0.04+3.2*(1-A40/Parametros!$B$15)))/1.6) -> 196.25343 | C40: =Parametros!$B$8+(Parametros!$B$12*(1-Parametros!$B$7)+Parametros!$B$13*Parametros!$B$7)*(1-0.55*Parametros!$B$9/(Parametros!$B$9+150))*9.81*Parametros!$B$11/100000+5*(A40/200)^1.8*(3.5/Parametros!$B$10)^4.8 -> 167.77321 | D40: =B40-C40 -> 28.480221 | E40: =IF(D40>0,1,0) -> 1
A41: =36/100*Parametros!$B$15 -> 75 | B41: =IF(A41>=Parametros!$B$15,0,Parametros!$B$5*(-0.2+SQRT(0.04+3.2*(1-A41/Parametros!$B$15)))/1.6) -> 194.5299 | C41: =Parametros!$B$8+(Parametros!$B$12*(1-Parametros!$B$7)+Parametros!$B$13*Parametros!$B$7)*(1-0.55*Parametros!$B$9/(Parametros!$B$9+150))*9.81*Parametros!$B$11/100000+5*(A41/200)^1.8*(3.5/Parametros!$B$10)^4.8 -> 167.81551 | D41: =B41-C41 -> 26.714386 | E41: =IF(D41>0,1,0) -> 1
...

Sheet Resultados
A1: Punto de operación
A2: Datos de ejemplo (sintéticos) con fines didácticos. Celdas azules sobre fondo crema = entradas editables; el resto son fórmulas.
A4: Indicador | B4: Valor | C4: Unidad
A5: Puntos de la IPR por encima de la VLP | B5: =SUM(Curvas!E5:E105) -> 51
A6: Caudal de líquido en el punto de operación | B6: =IF(B5=0,0,INDEX(Curvas!A5:A105,MIN(B5+1,101))) -> 106.25 | C6: m³/d
A7: Presión de fondo fluyente | B7: =IF(B5=0,0,INDEX(Curvas!B5:B105,MIN(B5+1,101))) -> 166.88584 | C7: bar
A8: Caudal de petróleo | B8: =B6*(1-Parametros!B7) -> 106.25 | C8: m³/d
A9: ¿Surge el pozo? | B9: =IF(B5=0,"No: requiere levantamiento","Sí") -> Sí
A11: La resolución del cruce es del 1 % del caudal máximo. Si B5 es cero, la VLP está por encima de la IPR desde el primer punto y el pozo no surge.

Sheet GasLift
A1: Rendimiento del gas lift: caudal contra gas inyectado
A2: Datos de ejemplo (sintéticos) con fines didácticos. Celdas azules sobre fondo crema = entradas editables; el resto son fórmulas.
A4: Gas inyectado (m³/m³) | B4: Puntos IPR sobre VLP | C4: Caudal de líquido (m³/d) | D4: Ganancia marginal (m³/d por 50 m³/m³) | G4: Matriz de VLP por gas inyectado (bar)
A5: 0 | B5: =SUMPRODUCT(--(Curvas!$B$5:$B$105>G$6:G$106)) -> 51 | C5: =IF(B5=0,0,INDEX($F$6:$F$106,MIN(B5+1,101))) -> 106.25 | F5: Q \ GLR | G5: 0 | H5: 50 | I5: 100 | J5: 150 | K5: 200 | L5: 250 | M5: 300 | N5: 350 | O5: 400
A6: 50 | B6: =SUMPRODUCT(--(Curvas!$B$5:$B$105>H$6:H$106)) -> 61 | C6: =IF(B6=0,0,INDEX($F$6:$F$106,MIN(B6+1,101))) -> 127.08333 | D6: =C6-C5 -> 20.833333 | F6: =Curvas!A5 -> 0 | G6: =Parametros!$B$8+(Parametros!$B$12*(1-Parametros!$B$7)+Parametros!$B$13*Parametros!$B$7)*(1-0.55*G$5/(G$5+150))*9.81*Parametros!$B$11/100000+5*($F6/200)^1.8*(3.5/Parametros!$B$10)^4.8 -> 166.96 | H6: =Parametros!$B$8+(Parametros!$B$12*(1-Parametros!$B$7)+Parametros!$B$13*Parametros!$B$7)*(1-0.55*H$5/(H$5+150))*9.81*Parametros!$B$11/100000+5*($F6/200)^1.8*(3.5/Parametros!$B$10)^4.8 -> 145.378 | I6: =Parametros!$B$8+(Parametros!$B$12*(1-Parametros!$B$7)+Parametros!$B$13*Parametros!$B$7)*(1-0.55*I$5/(I$5+150))*9.81*Parametros!$B$11/100000+5*($F6/200)^1.8*(3.5/Parametros!$B$10)^4.8 -> 132.4288 | J6: =Parametros!$B$8+(Parametros!$B$12*(1-Parametros!$B$7)+Parametros!$B$13*Parametros!$B$7)*(1-0.55*J$5/(J$5+150))*9.81*Parametros!$B$11/100000+5*($F6/200)^1.8*(3.5/Parametros!$B$10)^4.8 -> 123.796 | K6: =Parametros!$B$8+(Parametros!$B$12*(1-Parametros!$B$7)+Parametros!$B$13*Parametros!$B$7)*(1-0.55*K$5/(K$5+150))*9.81*Parametros!$B$11/100000+5*($F6/200)^1.8*(3.5/Parametros!$B$10)^4.8 -> 117.62971 | L6: =Parametros!$B$8+(Parametros!$B$12*(1-Parametros!$B$7)+Parametros!$B$13*Parametros!$B$7)*(1-0.55*L$5/(L$5+150))*9.81*Parametros!$B$11/100000+5*($F6/200)^1.8*(3.5/Parametros!$B$10)^4.8 -> 113.005 | M6: =Parametros!$B$8+(Parametros!$B$12*(1-Parametros!$B$7)+Parametros!$B$13*Parametros!$B$7)*(1-0.55*M$5/(M$5+150))*9.81*Parametros!$B$11/100000+5*($F6/200)^1.8*(3.5/Parametros!$B$10)^4.8 -> 109.408 | N6: =Parametros!$B$8+(Parametros!$B$12*(1-Parametros!$B$7)+Parametros!$B$13*Parametros!$B$7)*(1-0.55*N$5/(N$5+150))*9.81*Parametros!$B$11/100000+5*($F6/200)^1.8*(3.5/Parametros!$B$10)^4.8 -> 106.5304 | O6: =Parametros!$B$8+(Parametros!$B$12*(1-Parametros!$B$7)+Parametros!$B$13*Parametros!$B$7)*(1-0.55*O$5/(O$5+150))*9.81*Parametros!$B$11/100000+5*($F6/200)^1.8*(3.5/Parametros!$B$10)^4.8 -> 104.176
A7: 100 | B7: =SUMPRODUCT(--(Curvas!$B$5:$B$105>I$6:I$106)) -> 66 | C7: =IF(B7=0,0,INDEX($F$6:$F$106,MIN(B7+1,101))) -> 137.5 | D7: =C7-C6 -> 10.416667 | F7: =Curvas!A6 -> 2.0833333 | G7: =Parametros!$B$8+(Parametros!$B$12*(1-Parametros!$B$7)+Parametros!$B$13*Parametros!$B$7)*(1-0.55*G$5/(G$5+150))*9.81*Parametros!$B$11/100000+5*($F7/200)^1.8*(3.5/Parametros!$B$10)^4.8 -> 166.96135 | H7: =Parametros!$B$8+(Parametros!$B$12*(1-Parametros!$B$7)+Parametros!$B$13*Parametros!$B$7)*(1-0.55*H$5/(H$5+150))*9.81*Parametros!$B$11/100000+5*($F7/200)^1.8*(3.5/Parametros!$B$10)^4.8 -> 145.37935 | I7: =Parametros!$B$8+(Parametros!$B$12*(1-Parametros!$B$7)+Parametros!$B$13*Parametros!$B$7)*(1-0.55*I$5/(I$5+150))*9.81*Parametros!$B$11/100000+5*($F7/200)^1.8*(3.5/Parametros!$B$10)^4.8 -> 132.43015 | J7: =Parametros!$B$8+(Parametros!$B$12*(1-Parametros!$B$7)+Parametros!$B$13*Parametros!$B$7)*(1-0.55*J$5/(J$5+150))*9.81*Parametros!$B$11/100000+5*($F7/200)^1.8*(3.5/Parametros!$B$10)^4.8 -> 123.79735 | K7: =Parametros!$B$8+(Parametros!$B$12*(1-Parametros!$B$7)+Parametros!$B$13*Parametros!$B$7)*(1-0.55*K$5/(K$5+150))*9.81*Parametros!$B$11/100000+5*($F7/200)^1.8*(3.5/Parametros!$B$10)^4.8 -> 117.63107 | L7: =Parametros!$B$8+(Parametros!$B$12*(1-Parametros!$B$7)+Parametros!$B$13*Parametros!$B$7)*(1-0.55*L$5/(L$5+150))*9.81*Parametros!$B$11/100000+5*($F7/200)^1.8*(3.5/Parametros!$B$10)^4.8 -> 113.00635 | M7: =Parametros!$B$8+(Parametros!$B$12*(1-Parametros!$B$7)+Parametros!$B$13*Parametros!$B$7)*(1-0.55*M$5/(M$5+150))*9.81*Parametros!$B$11/100000+5*($F7/200)^1.8*(3.5/Parametros!$B$10)^4.8 -> 109.40935 | N7: =Parametros!$B$8+(Parametros!$B$12*(1-Parametros!$B$7)+Parametros!$B$13*Parametros!$B$7)*(1-0.55*N$5/(N$5+150))*9.81*Parametros!$B$11/100000+5*($F7/200)^1.8*(3.5/Parametros!$B$10)^4.8 -> 106.53175 | O7: =Parametros!$B$8+(Parametros!$B$12*(1-Parametros!$B$7)+Parametros!$B$13*Parametros!$B$7)*(1-0.55*O$5/(O$5+150))*9.81*Parametros!$B$11/100000+5*($F7/200)^1.8*(3.5/Parametros!$B$10)^4.8 -> 104.17735
A8: 150 | B8: =SUMPRODUCT(--(Curvas!$B$5:$B$105>J$6:J$106)) -> 70 | C8: =IF(B8=0,0,INDEX($F$6:$F$106,MIN(B8+1,101))) -> 145.83333 | D8: =C8-C7 -> 8.3333333 | F8: =Curvas!A7 -> 4.1666667 | G8: =Parametros!$B$8+(Parametros!$B$12*(1-Parametros!$B$7)+Parametros!$B$13*Parametros!$B$7)*(1-0.55*G$5/(G$5+150))*9.81*Parametros!$B$11/100000+5*($F8/200)^1.8*(3.5/Parametros!$B$10)^4.8 -> 166.96471 | H8: =Parametros!$B$8+(Parametros!$B$12*(1-Parametros!$B$7)+Parametros!$B$13*Parametros!$B$7)*(1-0.55*H$5/(H$5+150))*9.81*Parametros!$B$11/100000+5*($F8/200)^1.8*(3.5/Parametros!$B$10)^4.8 -> 145.38271 | I8: =Parametros!$B$8+(Parametros!$B$12*(1-Parametros!$B$7)+Parametros!$B$13*Parametros!$B$7)*(1-0.55*I$5/(I$5+150))*9.81*Parametros!$B$11/100000+5*($F8/200)^1.8*(3.5/Parametros!$B$10)^4.8 -> 132.43351 | J8: =Parametros!$B$8+(Parametros!$B$12*(1-Parametros!$B$7)+Parametros!$B$13*Parametros!$B$7)*(1-0.55*J$5/(J$5+150))*9.81*Parametros!$B$11/100000+5*($F8/200)^1.8*(3.5/Parametros!$B$10)^4.8 -> 123.80071 | K8: =Parametros!$B$8+(Parametros!$B$12*(1-Parametros!$B$7)+Parametros!$B$13*Parametros!$B$7)*(1-0.55*K$5/(K$5+150))*9.81*Parametros!$B$11/100000+5*($F8/200)^1.8*(3.5/Parametros!$B$10)^4.8 -> 117.63442 | L8: =Parametros!$B$8+(Parametros!$B$12*(1-Parametros!$B$7)+Parametros!$B$13*Parametros!$B$7)*(1-0.55*L$5/(L$5+150))*9.81*Parametros!$B$11/100000+5*($F8/200)^1.8*(3.5/Parametros!$B$10)^4.8 -> 113.00971 | M8: =Parametros!$B$8+(Parametros!$B$12*(1-Parametros!$B$7)+Parametros!$B$13*Parametros!$B$7)*(1-0.55*M$5/(M$5+150))*9.81*Parametros!$B$11/100000+5*($F8/200)^1.8*(3.5/Parametros!$B$10)^4.8 -> 109.41271 | N8: =Parametros!$B$8+(Parametros!$B$12*(1-Parametros!$B$7)+Parametros!$B$13*Parametros!$B$7)*(1-0.55*N$5/(N$5+150))*9.81*Parametros!$B$11/100000+5*($F8/200)^1.8*(3.5/Parametros!$B$10)^4.8 -> 106.53511 | O8: =Parametros!$B$8+(Parametros!$B$12*(1-Parametros!$B$7)+Parametros!$B$13*Parametros!$B$7)*(1-0.55*O$5/(O$5+150))*9.81*Parametros!$B$11/100000+5*($F8/200)^1.8*(3.5/Parametros!$B$10)^4.8 -> 104.18071
A9: 200 | B9: =SUMPRODUCT(--(Curvas!$B$5:$B$105>K$6:K$106)) -> 72 | C9: =IF(B9=0,0,INDEX($F$6:$F$106,MIN(B9+1,101))) -> 150 | D9: =C9-C8 -> 4.1666667 | F9: =Curvas!A8 -> 6.25 | G9: =Parametros!$B$8+(Parametros!$B$12*(1-Parametros!$B$7)+Parametros!$B$13*Parametros!$B$7)*(1-0.55*G$5/(G$5+150))*9.81*Parametros!$B$11/100000+5*($F9/200)^1.8*(3.5/Parametros!$B$10)^4.8 -> 166.96977 | H9: =Parametros!$B$8+(Parametros!$B$12*(1-Parametros!$B$7)+Parametros!$B$13*Parametros!$B$7)*(1-0.55*H$5/(H$5+150))*9.81*Parametros!$B$11/100000+5*($F9/200)^1.8*(3.5/Parametros!$B$10)^4.8 -> 145.38777 | I9: =Parametros!$B$8+(Parametros!$B$12*(1-Parametros!$B$7)+Parametros!$B$13*Parametros!$B$7)*(1-0.55*I$5/(I$5+150))*9.81*Parametros!$B$11/100000+5*($F9/200)^1.8*(3.5/Parametros!$B$10)^4.8 -> 132.43857 | J9: =Parametros!$B$8+(Parametros!$B$12*(1-Parametros!$B$7)+Parametros!$B$13*Parametros!$B$7)*(1-0.55*J$5/(J$5+150))*9.81*Parametros!$B$11/100000+5*($F9/200)^1.8*(3.5/Parametros!$B$10)^4.8 -> 123.80577 | K9: =Parametros!$B$8+(Parametros!$B$12*(1-Parametros!$B$7)+Parametros!$B$13*Parametros!$B$7)*(1-0.55*K$5/(K$5+150))*9.81*Parametros!$B$11/100000+5*($F9/200)^1.8*(3.5/Parametros!$B$10)^4.8 -> 117.63948 | L9: =Parametros!$B$8+(Parametros!$B$12*(1-Parametros!$B$7)+Parametros!$B$13*Parametros!$B$7)*(1-0.55*L$5/(L$5+150))*9.81*Parametros!$B$11/100000+5*($F9/200)^1.8*(3.5/Parametros!$B$10)^4.8 -> 113.01477 | M9: =Parametros!$B$8+(Parametros!$B$12*(1-Parametros!$B$7)+Parametros!$B$13*Parametros!$B$7)*(1-0.55*M$5/(M$5+150))*9.81*Parametros!$B$11/100000+5*($F9/200)^1.8*(3.5/Parametros!$B$10)^4.8 -> 109.41777 | N9: =Parametros!$B$8+(Parametros!$B$12*(1-Parametros!$B$7)+Parametros!$B$13*Parametros!$B$7)*(1-0.55*N$5/(N$5+150))*9.81*Parametros!$B$11/100000+5*($F9/200)^1.8*(3.5/Parametros!$B$10)^4.8 -> 106.54017 | O9: =Parametros!$B$8+(Parametros!$B$12*(1-Parametros!$B$7)+Parametros!$B$13*Parametros!$B$7)*(1-0.55*O$5/(O$5+150))*9.81*Parametros!$B$11/100000+5*($F9/200)^1.8*(3.5/Parametros!$B$10)^4.8 -> 104.18577
A10: 250 | B10: =SUMPRODUCT(--(Curvas!$B$5:$B$105>L$6:L$106)) -> 74 | C10: =IF(B10=0,0,INDEX($F$6:$F$106,MIN(B10+1,101))) -> 154.16667 | D10: =C10-C9 -> 4.1666667 | F10: =Curvas!A9 -> 8.3333333 | G10: =Parametros!$B$8+(Parametros!$B$12*(1-Parametros!$B$7)+Parametros!$B$13*Parametros!$B$7)*(1-0.55*G$5/(G$5+150))*9.81*Parametros!$B$11/100000+5*($F10/200)^1.8*(3.5/Parametros!$B$10)^4.8 -> 166.97639 | H10: =Parametros!$B$8+(Parametros!$B$12*(1-Parametros!$B$7)+Parametros!$B$13*Parametros!$B$7)*(1-0.55*H$5/(H$5+150))*9.81*Parametros!$B$11/100000+5*($F10/200)^1.8*(3.5/Parametros!$B$10)^4.8 -> 145.39439 | I10: =Parametros!$B$8+(Parametros!$B$12*(1-Parametros!$B$7)+Parametros!$B$13*Parametros!$B$7)*(1-0.55*I$5/(I$5+150))*9.81*Parametros!$B$11/100000+5*($F10/200)^1.8*(3.5/Parametros!$B$10)^4.8 -> 132.44519 | J10: =Parametros!$B$8+(Parametros!$B$12*(1-Parametros!$B$7)+Parametros!$B$13*Parametros!$B$7)*(1-0.55*J$5/(J$5+150))*9.81*Parametros!$B$11/100000+5*($F10/200)^1.8*(3.5/Parametros!$B$10)^4.8 -> 123.81239 | K10: =Parametros!$B$8+(Parametros!$B$12*(1-Parametros!$B$7)+Parametros!$B$13*Parametros!$B$7)*(1-0.55*K$5/(K$5+150))*9.81*Parametros!$B$11/100000+5*($F10/200)^1.8*(3.5/Parametros!$B$10)^4.8 -> 117.6461 | L10: =Parametros!$B$8+(Parametros!$B$12*(1-Parametros!$B$7)+Parametros!$B$13*Parametros!$B$7)*(1-0.55*L$5/(L$5+150))*9.81*Parametros!$B$11/100000+5*($F10/200)^1.8*(3.5/Parametros!$B$10)^4.8 -> 113.02139 | M10: =Parametros!$B$8+(Parametros!$B$12*(1-Parametros!$B$7)+Parametros!$B$13*Parametros!$B$7)*(1-0.55*M$5/(M$5+150))*9.81*Parametros!$B$11/100000+5*($F10/200)^1.8*(3.5/Parametros!$B$10)^4.8 -> 109.42439 | N10: =Parametros!$B$8+(Parametros!$B$12*(1-Parametros!$B$7)+Parametros!$B$13*Parametros!$B$7)*(1-0.55*N$5/(N$5+150))*9.81*Parametros!$B$11/100000+5*($F10/200)^1.8*(3.5/Parametros!$B$10)^4.8 -> 106.54679 | O10: =Parametros!$B$8+(Parametros!$B$12*(1-Parametros!$B$7)+Parametros!$B$13*Parametros!$B$7)*(1-0.55*O$5/(O$5+150))*9.81*Parametros!$B$11/100000+5*($F10/200)^1.8*(3.5/Parametros!$B$10)^4.8 -> 104.19239
A11: 300 | B11: =SUMPRODUCT(--(Curvas!$B$5:$B$105>M$6:M$106)) -> 75 | C11: =IF(B11=0,0,INDEX($F$6:$F$106,MIN(B11+1,101))) -> 156.25 | D11: =C11-C10 -> 2.0833333 | F11: =Curvas!A10 -> 10.416667 | G11: =Parametros!$B$8+(Parametros!$B$12*(1-Parametros!$B$7)+Parametros!$B$13*Parametros!$B$7)*(1-0.55*G$5/(G$5+150))*9.81*Parametros!$B$11/100000+5*($F11/200)^1.8*(3.5/Parametros!$B$10)^4.8 -> 166.98449 | H11: =Parametros!$B$8+(Parametros!$B$12*(1-Parametros!$B$7)+Parametros!$B$13*Parametros!$B$7)*(1-0.55*H$5/(H$5+150))*9.81*Parametros!$B$11/100000+5*($F11/200)^1.8*(3.5/Parametros!$B$10)^4.8 -> 145.40249 | I11: =Parametros!$B$8+(Parametros!$B$12*(1-Parametros!$B$7)+Parametros!$B$13*Parametros!$B$7)*(1-0.55*I$5/(I$5+150))*9.81*Parametros!$B$11/100000+5*($F11/200)^1.8*(3.5/Parametros!$B$10)^4.8 -> 132.45329 | J11: =Parametros!$B$8+(Parametros!$B$12*(1-Parametros!$B$7)+Parametros!$B$13*Parametros!$B$7)*(1-0.55*J$5/(J$5+150))*9.81*Parametros!$B$11/100000+5*($F11/200)^1.8*(3.5/Parametros!$B$10)^4.8 -> 123.82049 | K11: =Parametros!$B$8+(Parametros!$B$12*(1-Parametros!$B$7)+Parametros!$B$13*Parametros!$B$7)*(1-0.55*K$5/(K$5+150))*9.81*Parametros!$B$11/100000+5*($F11/200)^1.8*(3.5/Parametros!$B$10)^4.8 -> 117.65421 | L11: =Parametros!$B$8+(Parametros!$B$12*(1-Parametros!$B$7)+Parametros!$B$13*Parametros!$B$7)*(1-0.55*L$5/(L$5+150))*9.81*Parametros!$B$11/100000+5*($F11/200)^1.8*(3.5/Parametros!$B$10)^4.8 -> 113.02949 | M11: =Parametros!$B$8+(Parametros!$B$12*(1-Parametros!$B$7)+Parametros!$B$13*Parametros!$B$7)*(1-0.55*M$5/(M$5+150))*9.81*Parametros!$B$11/100000+5*($F11/200)^1.8*(3.5/Parametros!$B$10)^4.8 -> 109.43249 | N11: =Parametros!$B$8+(Parametros!$B$12*(1-Parametros!$B$7)+Parametros!$B$13*Parametros!$B$7)*(1-0.55*N$5/(N$5+150))*9.81*Parametros!$B$11/100000+5*($F11/200)^1.8*(3.5/Parametros!$B$10)^4.8 -> 106.55489 | O11: =Parametros!$B$8+(Parametros!$B$12*(1-Parametros!$B$7)+Parametros!$B$13*Parametros!$B$7)*(1-0.55*O$5/(O$5+150))*9.81*Parametros!$B$11/100000+5*($F11/200)^1.8*(3.5/Parametros!$B$10)^4.8 -> 104.20049
A12: 350 | B12: =SUMPRODUCT(--(Curvas!$B$5:$B$105>N$6:N$106)) -> 76 | C12: =IF(B12=0,0,INDEX($F$6:$F$106,MIN(B12+1,101))) -> 158.33333 | D12: =C12-C11 -> 2.0833333 | F12: =Curvas!A11 -> 12.5 | G12: =Parametros!$B$8+(Parametros!$B$12*(1-Parametros!$B$7)+Parametros!$B$13*Parametros!$B$7)*(1-0.55*G$5/(G$5+150))*9.81*Parametros!$B$11/100000+5*($F12/200)^1.8*(3.5/Parametros!$B$10)^4.8 -> 166.99401 | H12: =Parametros!$B$8+(Parametros!$B$12*(1-Parametros!$B$7)+Parametros!$B$13*Parametros!$B$7)*(1-0.55*H$5/(H$5+150))*9.81*Parametros!$B$11/100000+5*($F12/200)^1.8*(3.5/Parametros!$B$10)^4.8 -> 145.41201 | I12: =Parametros!$B$8+(Parametros!$B$12*(1-Parametros!$B$7)+Parametros!$B$13*Parametros!$B$7)*(1-0.55*I$5/(I$5+150))*9.81*Parametros!$B$11/100000+5*($F12/200)^1.8*(3.5/Parametros!$B$10)^4.8 -> 132.46281 | J12: =Parametros!$B$8+(Parametros!$B$12*(1-Parametros!$B$7)+Parametros!$B$13*Parametros!$B$7)*(1-0.55*J$5/(J$5+150))*9.81*Parametros!$B$11/100000+5*($F12/200)^1.8*(3.5/Parametros!$B$10)^4.8 -> 123.83001 | K12: =Parametros!$B$8+(Parametros!$B$12*(1-Parametros!$B$7)+Parametros!$B$13*Parametros!$B$7)*(1-0.55*K$5/(K$5+150))*9.81*Parametros!$B$11/100000+5*($F12/200)^1.8*(3.5/Parametros!$B$10)^4.8 -> 117.66372 | L12: =Parametros!$B$8+(Parametros!$B$12*(1-Parametros!$B$7)+Parametros!$B$13*Parametros!$B$7)*(1-0.55*L$5/(L$5+150))*9.81*Parametros!$B$11/100000+5*($F12/200)^1.8*(3.5/Parametros!$B$10)^4.8 -> 113.03901 | M12: =Parametros!$B$8+(Parametros!$B$12*(1-Parametros!$B$7)+Parametros!$B$13*Parametros!$B$7)*(1-0.55*M$5/(M$5+150))*9.81*Parametros!$B$11/100000+5*($F12/200)^1.8*(3.5/Parametros!$B$10)^4.8 -> 109.44201 | N12: =Parametros!$B$8+(Parametros!$B$12*(1-Parametros!$B$7)+Parametros!$B$13*Parametros!$B$7)*(1-0.55*N$5/(N$5+150))*9.81*Parametros!$B$11/100000+5*($F12/200)^1.8*(3.5/Parametros!$B$10)^4.8 -> 106.56441 | O12: =Parametros!$B$8+(Parametros!$B$12*(1-Parametros!$B$7)+Parametros!$B$13*Parametros!$B$7)*(1-0.55*O$5/(O$5+150))*9.81*Parametros!$B$11/100000+5*($F12/200)^1.8*(3.5/Parametros!$B$10)^4.8 -> 104.21001
A13: 400 | B13: =SUMPRODUCT(--(Curvas!$B$5:$B$105>O$6:O$106)) -> 77 | C13: =IF(B13=0,0,INDEX($F$6:$F$106,MIN(B13+1,101))) -> 160.41667 | D13: =C13-C12 -> 2.0833333 | F13: =Curvas!A12 -> 14.583333 | G13: =Parametros!$B$8+(Parametros!$B$12*(1-Parametros!$B$7)+Parametros!$B$13*Parametros!$B$7)*(1-0.55*G$5/(G$5+150))*9.81*Parametros!$B$11/100000+5*($F13/200)^1.8*(3.5/Parametros!$B$10)^4.8 -> 167.00488 | H13: =Parametros!$B$8+(Parametros!$B$12*(1-Parametros!$B$7)+Parametros!$B$13*Parametros!$B$7)*(1-0.55*H$5/(H$5+150))*9.81*Parametros!$B$11/100000+5*($F13/200)^1.8*(3.5/Parametros!$B$10)^4.8 -> 145.42288 | I13: =Parametros!$B$8+(Parametros!$B$12*(1-Parametros!$B$7)+Parametros!$B$13*Parametros!$B$7)*(1-0.55*I$5/(I$5+150))*9.81*Parametros!$B$11/100000+5*($F13/200)^1.8*(3.5/Parametros!$B$10)^4.8 -> 132.47368 | J13: =Parametros!$B$8+(Parametros!$B$12*(1-Parametros!$B$7)+Parametros!$B$13*Parametros!$B$7)*(1-0.55*J$5/(J$5+150))*9.81*Parametros!$B$11/100000+5*($F13/200)^1.8*(3.5/Parametros!$B$10)^4.8 -> 123.84088 | K13: =Parametros!$B$8+(Parametros!$B$12*(1-Parametros!$B$7)+Parametros!$B$13*Parametros!$B$7)*(1-0.55*K$5/(K$5+150))*9.81*Parametros!$B$11/100000+5*($F13/200)^1.8*(3.5/Parametros!$B$10)^4.8 -> 117.67459 | L13: =Parametros!$B$8+(Parametros!$B$12*(1-Parametros!$B$7)+Parametros!$B$13*Parametros!$B$7)*(1-0.55*L$5/(L$5+150))*9.81*Parametros!$B$11/100000+5*($F13/200)^1.8*(3.5/Parametros!$B$10)^4.8 -> 113.04988 | M13: =Parametros!$B$8+(Parametros!$B$12*(1-Parametros!$B$7)+Parametros!$B$13*Parametros!$B$7)*(1-0.55*M$5/(M$5+150))*9.81*Parametros!$B$11/100000+5*($F13/200)^1.8*(3.5/Parametros!$B$10)^4.8 -> 109.45288 | N13: =Parametros!$B$8+(Parametros!$B$12*(1-Parametros!$B$7)+Parametros!$B$13*Parametros!$B$7)*(1-0.55*N$5/(N$5+150))*9.81*Parametros!$B$11/100000+5*($F13/200)^1.8*(3.5/Parametros!$B$10)^4.8 -> 106.57528 | O13: =Parametros!$B$8+(Parametros!$B$12*(1-Parametros!$B$7)+Parametros!$B$13*Parametros!$B$7)*(1-0.55*O$5/(O$5+150))*9.81*Parametros!$B$11/100000+5*($F13/200)^1.8*(3.5/Parametros!$B$10)^4.8 -> 104.22088
F14: =Curvas!A13 -> 16.666667 | G14: =Parametros!$B$8+(Parametros!$B$12*(1-Parametros!$B$7)+Parametros!$B$13*Parametros!$B$7)*(1-0.55*G$5/(G$5+150))*9.81*Parametros!$B$11/100000+5*($F14/200)^1.8*(3.5/Parametros!$B$10)^4.8 -> 167.01707 | H14: =Parametros!$B$8+(Parametros!$B$12*(1-Parametros!$B$7)+Parametros!$B$13*Parametros!$B$7)*(1-0.55*H$5/(H$5+150))*9.81*Parametros!$B$11/100000+5*($F14/200)^1.8*(3.5/Parametros!$B$10)^4.8 -> 145.43507 | I14: =Parametros!$B$8+(Parametros!$B$12*(1-Parametros!$B$7)+Parametros!$B$13*Parametros!$B$7)*(1-0.55*I$5/(I$5+150))*9.81*Parametros!$B$11/100000+5*($F14/200)^1.8*(3.5/Parametros!$B$10)^4.8 -> 132.48587 | J14: =Parametros!$B$8+(Parametros!$B$12*(1-Parametros!$B$7)+Parametros!$B$13*Parametros!$B$7)*(1-0.55*J$5/(J$5+150))*9.81*Parametros!$B$11/100000+5*($F14/200)^1.8*(3.5/Parametros!$B$10)^4.8 -> 123.85307 | K14: =Parametros!$B$8+(Parametros!$B$12*(1-Parametros!$B$7)+Parametros!$B$13*Parametros!$B$7)*(1-0.55*K$5/(K$5+150))*9.81*Parametros!$B$11/100000+5*($F14/200)^1.8*(3.5/Parametros!$B$10)^4.8 -> 117.68679 | L14: =Parametros!$B$8+(Parametros!$B$12*(1-Parametros!$B$7)+Parametros!$B$13*Parametros!$B$7)*(1-0.55*L$5/(L$5+150))*9.81*Parametros!$B$11/100000+5*($F14/200)^1.8*(3.5/Parametros!$B$10)^4.8 -> 113.06207 | M14: =Parametros!$B$8+(Parametros!$B$12*(1-Parametros!$B$7)+Parametros!$B$13*Parametros!$B$7)*(1-0.55*M$5/(M$5+150))*9.81*Parametros!$B$11/100000+5*($F14/200)^1.8*(3.5/Parametros!$B$10)^4.8 -> 109.46507 | N14: =Parametros!$B$8+(Parametros!$B$12*(1-Parametros!$B$7)+Parametros!$B$13*Parametros!$B$7)*(1-0.55*N$5/(N$5+150))*9.81*Parametros!$B$11/100000+5*($F14/200)^1.8*(3.5/Parametros!$B$10)^4.8 -> 106.58747 | O14: =Parametros!$B$8+(Parametros!$B$12*(1-Parametros!$B$7)+Parametros!$B$13*Parametros!$B$7)*(1-0.55*O$5/(O$5+150))*9.81*Parametros!$B$11/100000+5*($F14/200)^1.8*(3.5/Parametros!$B$10)^4.8 -> 104.23307
A15: Gas lift: se busca el valor de gas inyectado donde el caudal deja de crecer. La matriz usa los demás parámetros de la hoja Parametros. | F15: =Curvas!A14 -> 18.75 | G15: =Parametros!$B$8+(Parametros!$B$12*(1-Parametros!$B$7)+Parametros!$B$13*Parametros!$B$7)*(1-0.55*G$5/(G$5+150))*9.81*Parametros!$B$11/100000+5*($F15/200)^1.8*(3.5/Parametros!$B$10)^4.8 -> 167.03055 | H15: =Parametros!$B$8+(Parametros!$B$12*(1-Parametros!$B$7)+Parametros!$B$13*Parametros!$B$7)*(1-0.55*H$5/(H$5+150))*9.81*Parametros!$B$11/100000+5*($F15/200)^1.8*(3.5/Parametros!$B$10)^4.8 -> 145.44855 | I15: =Parametros!$B$8+(Parametros!$B$12*(1-Parametros!$B$7)+Parametros!$B$13*Parametros!$B$7)*(1-0.55*I$5/(I$5+150))*9.81*Parametros!$B$11/100000+5*($F15/200)^1.8*(3.5/Parametros!$B$10)^4.8 -> 132.49935 | J15: =Parametros!$B$8+(Parametros!$B$12*(1-Parametros!$B$7)+Parametros!$B$13*Parametros!$B$7)*(1-0.55*J$5/(J$5+150))*9.81*Parametros!$B$11/100000+5*($F15/200)^1.8*(3.5/Parametros!$B$10)^4.8 -> 123.86655 | K15: =Parametros!$B$8+(Parametros!$B$12*(1-Parametros!$B$7)+Parametros!$B$13*Parametros!$B$7)*(1-0.55*K$5/(K$5+150))*9.81*Parametros!$B$11/100000+5*($F15/200)^1.8*(3.5/Parametros!$B$10)^4.8 -> 117.70027 | L15: =Parametros!$B$8+(Parametros!$B$12*(1-Parametros!$B$7)+Parametros!$B$13*Parametros!$B$7)*(1-0.55*L$5/(L$5+150))*9.81*Parametros!$B$11/100000+5*($F15/200)^1.8*(3.5/Parametros!$B$10)^4.8 -> 113.07555 | M15: =Parametros!$B$8+(Parametros!$B$12*(1-Parametros!$B$7)+Parametros!$B$13*Parametros!$B$7)*(1-0.55*M$5/(M$5+150))*9.81*Parametros!$B$11/100000+5*($F15/200)^1.8*(3.5/Parametros!$B$10)^4.8 -> 109.47855 | N15: =Parametros!$B$8+(Parametros!$B$12*(1-Parametros!$B$7)+Parametros!$B$13*Parametros!$B$7)*(1-0.55*N$5/(N$5+150))*9.81*Parametros!$B$11/100000+5*($F15/200)^1.8*(3.5/Parametros!$B$10)^4.8 -> 106.60095 | O15: =Parametros!$B$8+(Parametros!$B$12*(1-Parametros!$B$7)+Parametros!$B$13*Parametros!$B$7)*(1-0.55*O$5/(O$5+150))*9.81*Parametros!$B$11/100000+5*($F15/200)^1.8*(3.5/Parametros!$B$10)^4.8 -> 104.24655
F16: =Curvas!A15 -> 20.833333 | G16: =Parametros!$B$8+(Parametros!$B$12*(1-Parametros!$B$7)+Parametros!$B$13*Parametros!$B$7)*(1-0.55*G$5/(G$5+150))*9.81*Parametros!$B$11/100000+5*($F16/200)^1.8*(3.5/Parametros!$B$10)^4.8 -> 167.04529 | H16: =Parametros!$B$8+(Parametros!$B$12*(1-Parametros!$B$7)+Parametros!$B$13*Parametros!$B$7)*(1-0.55*H$5/(H$5+150))*9.81*Parametros!$B$11/100000+5*($F16/200)^1.8*(3.5/Parametros!$B$10)^4.8 -> 145.46329 | I16: =Parametros!$B$8+(Parametros!$B$12*(1-Parametros!$B$7)+Parametros!$B$13*Parametros!$B$7)*(1-0.55*I$5/(I$5+150))*9.81*Parametros!$B$11/100000+5*($F16/200)^1.8*(3.5/Parametros!$B$10)^4.8 -> 132.51409 | J16: =Parametros!$B$8+(Parametros!$B$12*(1-Parametros!$B$7)+Parametros!$B$13*Parametros!$B$7)*(1-0.55*J$5/(J$5+150))*9.81*Parametros!$B$11/100000+5*($F16/200)^1.8*(3.5/Parametros!$B$10)^4.8 -> 123.88129 | K16: =Parametros!$B$8+(Parametros!$B$12*(1-Parametros!$B$7)+Parametros!$B$13*Parametros!$B$7)*(1-0.55*K$5/(K$5+150))*9.81*Parametros!$B$11/100000+5*($F16/200)^1.8*(3.5/Parametros!$B$10)^4.8 -> 117.715 | L16: =Parametros!$B$8+(Parametros!$B$12*(1-Parametros!$B$7)+Parametros!$B$13*Parametros!$B$7)*(1-0.55*L$5/(L$5+150))*9.81*Parametros!$B$11/100000+5*($F16/200)^1.8*(3.5/Parametros!$B$10)^4.8 -> 113.09029 | M16: =Parametros!$B$8+(Parametros!$B$12*(1-Parametros!$B$7)+Parametros!$B$13*Parametros!$B$7)*(1-0.55*M$5/(M$5+150))*9.81*Parametros!$B$11/100000+5*($F16/200)^1.8*(3.5/Parametros!$B$10)^4.8 -> 109.49329 | N16: =Parametros!$B$8+(Parametros!$B$12*(1-Parametros!$B$7)+Parametros!$B$13*Parametros!$B$7)*(1-0.55*N$5/(N$5+150))*9.81*Parametros!$B$11/100000+5*($F16/200)^1.8*(3.5/Parametros!$B$10)^4.8 -> 106.61569 | O16: =Parametros!$B$8+(Parametros!$B$12*(1-Parametros!$B$7)+Parametros!$B$13*Parametros!$B$7)*(1-0.55*O$5/(O$5+150))*9.81*Parametros!$B$11/100000+5*($F16/200)^1.8*(3.5/Parametros!$B$10)^4.8 -> 104.26129
F17: =Curvas!A16 -> 22.916667 | G17: =Parametros!$B$8+(Parametros!$B$12*(1-Parametros!$B$7)+Parametros!$B$13*Parametros!$B$7)*(1-0.55*G$5/(G$5+150))*9.81*Parametros!$B$11/100000+5*($F17/200)^1.8*(3.5/Parametros!$B$10)^4.8 -> 167.06125 | H17: =Parametros!$B$8+(Parametros!$B$12*(1-Parametros!$B$7)+Parametros!$B$13*Parametros!$B$7)*(1-0.55*H$5/(H$5+150))*9.81*Parametros!$B$11/100000+5*($F17/200)^1.8*(3.5/Parametros!$B$10)^4.8 -> 145.47925 | I17: =Parametros!$B$8+(Parametros!$B$12*(1-Parametros!$B$7)+Parametros!$B$13*Parametros!$B$7)*(1-0.55*I$5/(I$5+150))*9.81*Parametros!$B$11/100000+5*($F17/200)^1.8*(3.5/Parametros!$B$10)^4.8 -> 132.53005 | J17: =Parametros!$B$8+(Parametros!$B$12*(1-Parametros!$B$7)+Parametros!$B$13*Parametros!$B$7)*(1-0.55*J$5/(J$5+150))*9.81*Parametros!$B$11/100000+5*($F17/200)^1.8*(3.5/Parametros!$B$10)^4.8 -> 123.89725 | K17: =Parametros!$B$8+(Parametros!$B$12*(1-Parametros!$B$7)+Parametros!$B$13*Parametros!$B$7)*(1-0.55*K$5/(K$5+150))*9.81*Parametros!$B$11/100000+5*($F17/200)^1.8*(3.5/Parametros!$B$10)^4.8 -> 117.73096 | L17: =Parametros!$B$8+(Parametros!$B$12*(1-Parametros!$B$7)+Parametros!$B$13*Parametros!$B$7)*(1-0.55*L$5/(L$5+150))*9.81*Parametros!$B$11/100000+5*($F17/200)^1.8*(3.5/Parametros!$B$10)^4.8 -> 113.10625 | M17: =Parametros!$B$8+(Parametros!$B$12*(1-Parametros!$B$7)+Parametros!$B$13*Parametros!$B$7)*(1-0.55*M$5/(M$5+150))*9.81*Parametros!$B$11/100000+5*($F17/200)^1.8*(3.5/Parametros!$B$10)^4.8 -> 109.50925 | N17: =Parametros!$B$8+(Parametros!$B$12*(1-Parametros!$B$7)+Parametros!$B$13*Parametros!$B$7)*(1-0.55*N$5/(N$5+150))*9.81*Parametros!$B$11/100000+5*($F17/200)^1.8*(3.5/Parametros!$B$10)^4.8 -> 106.63165 | O17: =Parametros!$B$8+(Parametros!$B$12*(1-Parametros!$B$7)+Parametros!$B$13*Parametros!$B$7)*(1-0.55*O$5/(O$5+150))*9.81*Parametros!$B$11/100000+5*($F17/200)^1.8*(3.5/Parametros!$B$10)^4.8 -> 104.27725
F18: =Curvas!A17 -> 25 | G18: =Parametros!$B$8+(Parametros!$B$12*(1-Parametros!$B$7)+Parametros!$B$13*Parametros!$B$7)*(1-0.55*G$5/(G$5+150))*9.81*Parametros!$B$11/100000+5*($F18/200)^1.8*(3.5/Parametros!$B$10)^4.8 -> 167.07842 | H18: =Parametros!$B$8+(Parametros!$B$12*(1-Parametros!$B$7)+Parametros!$B$13*Parametros!$B$7)*(1-0.55*H$5/(H$5+150))*9.81*Parametros!$B$11/100000+5*($F18/200)^1.8*(3.5/Parametros!$B$10)^4.8 -> 145.49642 | I18: =Parametros!$B$8+(Parametros!$B$12*(1-Parametros!$B$7)+Parametros!$B$13*Parametros!$B$7)*(1-0.55*I$5/(I$5+150))*9.81*Parametros!$B$11/100000+5*($F18/200)^1.8*(3.5/Parametros!$B$10)^4.8 -> 132.54722 | J18: =Parametros!$B$8+(Parametros!$B$12*(1-Parametros!$B$7)+Parametros!$B$13*Parametros!$B$7)*(1-0.55*J$5/(J$5+150))*9.81*Parametros!$B$11/100000+5*($F18/200)^1.8*(3.5/Parametros!$B$10)^4.8 -> 123.91442 | K18: =Parametros!$B$8+(Parametros!$B$12*(1-Parametros!$B$7)+Parametros!$B$13*Parametros!$B$7)*(1-0.55*K$5/(K$5+150))*9.81*Parametros!$B$11/100000+5*($F18/200)^1.8*(3.5/Parametros!$B$10)^4.8 -> 117.74813 | L18: =Parametros!$B$8+(Parametros!$B$12*(1-Parametros!$B$7)+Parametros!$B$13*Parametros!$B$7)*(1-0.55*L$5/(L$5+150))*9.81*Parametros!$B$11/100000+5*($F18/200)^1.8*(3.5/Parametros!$B$10)^4.8 -> 113.12342 | M18: =Parametros!$B$8+(Parametros!$B$12*(1-Parametros!$B$7)+Parametros!$B$13*Parametros!$B$7)*(1-0.55*M$5/(M$5+150))*9.81*Parametros!$B$11/100000+5*($F18/200)^1.8*(3.5/Parametros!$B$10)^4.8 -> 109.52642 | N18: =Parametros!$B$8+(Parametros!$B$12*(1-Parametros!$B$7)+Parametros!$B$13*Parametros!$B$7)*(1-0.55*N$5/(N$5+150))*9.81*Parametros!$B$11/100000+5*($F18/200)^1.8*(3.5/Parametros!$B$10)^4.8 -> 106.64882 | O18: =Parametros!$B$8+(Parametros!$B$12*(1-Parametros!$B$7)+Parametros!$B$13*Parametros!$B$7)*(1-0.55*O$5/(O$5+150))*9.81*Parametros!$B$11/100000+5*($F18/200)^1.8*(3.5/Parametros!$B$10)^4.8 -> 104.29442
F19: =Curvas!A18 -> 27.083333 | G19: =Parametros!$B$8+(Parametros!$B$12*(1-Parametros!$B$7)+Parametros!$B$13*Parametros!$B$7)*(1-0.55*G$5/(G$5+150))*9.81*Parametros!$B$11/100000+5*($F19/200)^1.8*(3.5/Parametros!$B$10)^4.8 -> 167.09677 | H19: =Parametros!$B$8+(Parametros!$B$12*(1-Parametros!$B$7)+Parametros!$B$13*Parametros!$B$7)*(1-0.55*H$5/(H$5+150))*9.81*Parametros!$B$11/100000+5*($F19/200)^1.8*(3.5/Parametros!$B$10)^4.8 -> 145.51477 | I19: =Parametros!$B$8+(Parametros!$B$12*(1-Parametros!$B$7)+Parametros!$B$13*Parametros!$B$7)*(1-0.55*I$5/(I$5+150))*9.81*Parametros!$B$11/100000+5*($F19/200)^1.8*(3.5/Parametros!$B$10)^4.8 -> 132.56557 | J19: =Parametros!$B$8+(Parametros!$B$12*(1-Parametros!$B$7)+Parametros!$B$13*Parametros!$B$7)*(1-0.55*J$5/(J$5+150))*9.81*Parametros!$B$11/100000+5*($F19/200)^1.8*(3.5/Parametros!$B$10)^4.8 -> 123.93277 | K19: =Parametros!$B$8+(Parametros!$B$12*(1-Parametros!$B$7)+Parametros!$B$13*Parametros!$B$7)*(1-0.55*K$5/(K$5+150))*9.81*Parametros!$B$11/100000+5*($F19/200)^1.8*(3.5/Parametros!$B$10)^4.8 -> 117.76648 | L19: =Parametros!$B$8+(Parametros!$B$12*(1-Parametros!$B$7)+Parametros!$B$13*Parametros!$B$7)*(1-0.55*L$5/(L$5+150))*9.81*Parametros!$B$11/100000+5*($F19/200)^1.8*(3.5/Parametros!$B$10)^4.8 -> 113.14177 | M19: =Parametros!$B$8+(Parametros!$B$12*(1-Parametros!$B$7)+Parametros!$B$13*Parametros!$B$7)*(1-0.55*M$5/(M$5+150))*9.81*Parametros!$B$11/100000+5*($F19/200)^1.8*(3.5/Parametros!$B$10)^4.8 -> 109.54477 | N19: =Parametros!$B$8+(Parametros!$B$12*(1-Parametros!$B$7)+Parametros!$B$13*Parametros!$B$7)*(1-0.55*N$5/(N$5+150))*9.81*Parametros!$B$11/100000+5*($F19/200)^1.8*(3.5/Parametros!$B$10)^4.8 -> 106.66717 | O19: =Parametros!$B$8+(Parametros!$B$12*(1-Parametros!$B$7)+Parametros!$B$13*Parametros!$B$7)*(1-0.55*O$5/(O$5+150))*9.81*Parametros!$B$11/100000+5*($F19/200)^1.8*(3.5/Parametros!$B$10)^4.8 -> 104.31277
F20: =Curvas!A19 -> 29.166667 | G20: =Parametros!$B$8+(Parametros!$B$12*(1-Parametros!$B$7)+Parametros!$B$13*Parametros!$B$7)*(1-0.55*G$5/(G$5+150))*9.81*Parametros!$B$11/100000+5*($F20/200)^1.8*(3.5/Parametros!$B$10)^4.8 -> 167.11628 | H20: =Parametros!$B$8+(Parametros!$B$12*(1-Parametros!$B$7)+Parametros!$B$13*Parametros!$B$7)*(1-0.55*H$5/(H$5+150))*9.81*Parametros!$B$11/100000+5*($F20/200)^1.8*(3.5/Parametros!$B$10)^4.8 -> 145.53428 | I20: =Parametros!$B$8+(Parametros!$B$12*(1-Parametros!$B$7)+Parametros!$B$13*Parametros!$B$7)*(1-0.55*I$5/(I$5+150))*9.81*Parametros!$B$11/100000+5*($F20/200)^1.8*(3.5/Parametros!$B$10)^4.8 -> 132.58508 | J20: =Parametros!$B$8+(Parametros!$B$12*(1-Parametros!$B$7)+Parametros!$B$13*Parametros!$B$7)*(1-0.55*J$5/(J$5+150))*9.81*Parametros!$B$11/100000+5*($F20/200)^1.8*(3.5/Parametros!$B$10)^4.8 -> 123.95228 | K20: =Parametros!$B$8+(Parametros!$B$12*(1-Parametros!$B$7)+Parametros!$B$13*Parametros!$B$7)*(1-0.55*K$5/(K$5+150))*9.81*Parametros!$B$11/100000+5*($F20/200)^1.8*(3.5/Parametros!$B$10)^4.8 -> 117.786 | L20: =Parametros!$B$8+(Parametros!$B$12*(1-Parametros!$B$7)+Parametros!$B$13*Parametros!$B$7)*(1-0.55*L$5/(L$5+150))*9.81*Parametros!$B$11/100000+5*($F20/200)^1.8*(3.5/Parametros!$B$10)^4.8 -> 113.16128 | M20: =Parametros!$B$8+(Parametros!$B$12*(1-Parametros!$B$7)+Parametros!$B$13*Parametros!$B$7)*(1-0.55*M$5/(M$5+150))*9.81*Parametros!$B$11/100000+5*($F20/200)^1.8*(3.5/Parametros!$B$10)^4.8 -> 109.56428 | N20: =Parametros!$B$8+(Parametros!$B$12*(1-Parametros!$B$7)+Parametros!$B$13*Parametros!$B$7)*(1-0.55*N$5/(N$5+150))*9.81*Parametros!$B$11/100000+5*($F20/200)^1.8*(3.5/Parametros!$B$10)^4.8 -> 106.68668 | O20: =Parametros!$B$8+(Parametros!$B$12*(1-Parametros!$B$7)+Parametros!$B$13*Parametros!$B$7)*(1-0.55*O$5/(O$5+150))*9.81*Parametros!$B$11/100000+5*($F20/200)^1.8*(3.5/Parametros!$B$10)^4.8 -> 104.33228
F21: =Curvas!A20 -> 31.25 | G21: =Parametros!$B$8+(Parametros!$B$12*(1-Parametros!$B$7)+Parametros!$B$13*Parametros!$B$7)*(1-0.55*G$5/(G$5+150))*9.81*Parametros!$B$11/100000+5*($F21/200)^1.8*(3.5/Parametros!$B$10)^4.8 -> 167.13695 | H21: =Parametros!$B$8+(Parametros!$B$12*(1-Parametros!$B$7)+Parametros!$B$13*Parametros!$B$7)*(1-0.55*H$5/(H$5+150))*9.81*Parametros!$B$11/100000+5*($F21/200)^1.8*(3.5/Parametros!$B$10)^4.8 -> 145.55495 | I21: =Parametros!$B$8+(Parametros!$B$12*(1-Parametros!$B$7)+Parametros!$B$13*Parametros!$B$7)*(1-0.55*I$5/(I$5+150))*9.81*Parametros!$B$11/100000+5*($F21/200)^1.8*(3.5/Parametros!$B$10)^4.8 -> 132.60575 | J21: =Parametros!$B$8+(Parametros!$B$12*(1-Parametros!$B$7)+Parametros!$B$13*Parametros!$B$7)*(1-0.55*J$5/(J$5+150))*9.81*Parametros!$B$11/100000+5*($F21/200)^1.8*(3.5/Parametros!$B$10)^4.8 -> 123.97295 | K21: =Parametros!$B$8+(Parametros!$B$12*(1-Parametros!$B$7)+Parametros!$B$13*Parametros!$B$7)*(1-0.55*K$5/(K$5+150))*9.81*Parametros!$B$11/100000+5*($F21/200)^1.8*(3.5/Parametros!$B$10)^4.8 -> 117.80666 | L21: =Parametros!$B$8+(Parametros!$B$12*(1-Parametros!$B$7)+Parametros!$B$13*Parametros!$B$7)*(1-0.55*L$5/(L$5+150))*9.81*Parametros!$B$11/100000+5*($F21/200)^1.8*(3.5/Parametros!$B$10)^4.8 -> 113.18195 | M21: =Parametros!$B$8+(Parametros!$B$12*(1-Parametros!$B$7)+Parametros!$B$13*Parametros!$B$7)*(1-0.55*M$5/(M$5+150))*9.81*Parametros!$B$11/100000+5*($F21/200)^1.8*(3.5/Parametros!$B$10)^4.8 -> 109.58495 | N21: =Parametros!$B$8+(Parametros!$B$12*(1-Parametros!$B$7)+Parametros!$B$13*Parametros!$B$7)*(1-0.55*N$5/(N$5+150))*9.81*Parametros!$B$11/100000+5*($F21/200)^1.8*(3.5/Parametros!$B$10)^4.8 -> 106.70735 | O21: =Parametros!$B$8+(Parametros!$B$12*(1-Parametros!$B$7)+Parametros!$B$13*Parametros!$B$7)*(1-0.55*O$5/(O$5+150))*9.81*Parametros!$B$11/100000+5*($F21/200)^1.8*(3.5/Parametros!$B$10)^4.8 -> 104.35295
F22: =Curvas!A21 -> 33.333333 | G22: =Parametros!$B$8+(Parametros!$B$12*(1-Parametros!$B$7)+Parametros!$B$13*Parametros!$B$7)*(1-0.55*G$5/(G$5+150))*9.81*Parametros!$B$11/100000+5*($F22/200)^1.8*(3.5/Parametros!$B$10)^4.8 -> 167.15875 | H22: =Parametros!$B$8+(Parametros!$B$12*(1-Parametros!$B$7)+Parametros!$B$13*Parametros!$B$7)*(1-0.55*H$5/(H$5+150))*9.81*Parametros!$B$11/100000+5*($F22/200)^1.8*(3.5/Parametros!$B$10)^4.8 -> 145.57675 | I22: =Parametros!$B$8+(Parametros!$B$12*(1-Parametros!$B$7)+Parametros!$B$13*Parametros!$B$7)*(1-0.55*I$5/(I$5+150))*9.81*Parametros!$B$11/100000+5*($F22/200)^1.8*(3.5/Parametros!$B$10)^4.8 -> 132.62755 | J22: =Parametros!$B$8+(Parametros!$B$12*(1-Parametros!$B$7)+Parametros!$B$13*Parametros!$B$7)*(1-0.55*J$5/(J$5+150))*9.81*Parametros!$B$11/100000+5*($F22/200)^1.8*(3.5/Parametros!$B$10)^4.8 -> 123.99475 | K22: =Parametros!$B$8+(Parametros!$B$12*(1-Parametros!$B$7)+Parametros!$B$13*Parametros!$B$7)*(1-0.55*K$5/(K$5+150))*9.81*Parametros!$B$11/100000+5*($F22/200)^1.8*(3.5/Parametros!$B$10)^4.8 -> 117.82846 | L22: =Parametros!$B$8+(Parametros!$B$12*(1-Parametros!$B$7)+Parametros!$B$13*Parametros!$B$7)*(1-0.55*L$5/(L$5+150))*9.81*Parametros!$B$11/100000+5*($F22/200)^1.8*(3.5/Parametros!$B$10)^4.8 -> 113.20375 | M22: =Parametros!$B$8+(Parametros!$B$12*(1-Parametros!$B$7)+Parametros!$B$13*Parametros!$B$7)*(1-0.55*M$5/(M$5+150))*9.81*Parametros!$B$11/100000+5*($F22/200)^1.8*(3.5/Parametros!$B$10)^4.8 -> 109.60675 | N22: =Parametros!$B$8+(Parametros!$B$12*(1-Parametros!$B$7)+Parametros!$B$13*Parametros!$B$7)*(1-0.55*N$5/(N$5+150))*9.81*Parametros!$B$11/100000+5*($F22/200)^1.8*(3.5/Parametros!$B$10)^4.8 -> 106.72915 | O22: =Parametros!$B$8+(Parametros!$B$12*(1-Parametros!$B$7)+Parametros!$B$13*Parametros!$B$7)*(1-0.55*O$5/(O$5+150))*9.81*Parametros!$B$11/100000+5*($F22/200)^1.8*(3.5/Parametros!$B$10)^4.8 -> 104.37475
F23: =Curvas!A22 -> 35.416667 | G23: =Parametros!$B$8+(Parametros!$B$12*(1-Parametros!$B$7)+Parametros!$B$13*Parametros!$B$7)*(1-0.55*G$5/(G$5+150))*9.81*Parametros!$B$11/100000+5*($F23/200)^1.8*(3.5/Parametros!$B$10)^4.8 -> 167.18166 | H23: =Parametros!$B$8+(Parametros!$B$12*(1-Parametros!$B$7)+Parametros!$B$13*Parametros!$B$7)*(1-0.55*H$5/(H$5+150))*9.81*Parametros!$B$11/100000+5*($F23/200)^1.8*(3.5/Parametros!$B$10)^4.8 -> 145.59966 | I23: =Parametros!$B$8+(Parametros!$B$12*(1-Parametros!$B$7)+Parametros!$B$13*Parametros!$B$7)*(1-0.55*I$5/(I$5+150))*9.81*Parametros!$B$11/100000+5*($F23/200)^1.8*(3.5/Parametros!$B$10)^4.8 -> 132.65046 | J23: =Parametros!$B$8+(Parametros!$B$12*(1-Parametros!$B$7)+Parametros!$B$13*Parametros!$B$7)*(1-0.55*J$5/(J$5+150))*9.81*Parametros!$B$11/100000+5*($F23/200)^1.8*(3.5/Parametros!$B$10)^4.8 -> 124.01766 | K23: =Parametros!$B$8+(Parametros!$B$12*(1-Parametros!$B$7)+Parametros!$B$13*Parametros!$B$7)*(1-0.55*K$5/(K$5+150))*9.81*Parametros!$B$11/100000+5*($F23/200)^1.8*(3.5/Parametros!$B$10)^4.8 -> 117.85138 | L23: =Parametros!$B$8+(Parametros!$B$12*(1-Parametros!$B$7)+Parametros!$B$13*Parametros!$B$7)*(1-0.55*L$5/(L$5+150))*9.81*Parametros!$B$11/100000+5*($F23/200)^1.8*(3.5/Parametros!$B$10)^4.8 -> 113.22666 | M23: =Parametros!$B$8+(Parametros!$B$12*(1-Parametros!$B$7)+Parametros!$B$13*Parametros!$B$7)*(1-0.55*M$5/(M$5+150))*9.81*Parametros!$B$11/100000+5*($F23/200)^1.8*(3.5/Parametros!$B$10)^4.8 -> 109.62966 | N23: =Parametros!$B$8+(Parametros!$B$12*(1-Parametros!$B$7)+Parametros!$B$13*Parametros!$B$7)*(1-0.55*N$5/(N$5+150))*9.81*Parametros!$B$11/100000+5*($F23/200)^1.8*(3.5/Parametros!$B$10)^4.8 -> 106.75206 | O23: =Parametros!$B$8+(Parametros!$B$12*(1-Parametros!$B$7)+Parametros!$B$13*Parametros!$B$7)*(1-0.55*O$5/(O$5+150))*9.81*Parametros!$B$11/100000+5*($F23/200)^1.8*(3.5/Parametros!$B$10)^4.8 -> 104.39766
F24: =Curvas!A23 -> 37.5 | G24: =Parametros!$B$8+(Parametros!$B$12*(1-Parametros!$B$7)+Parametros!$B$13*Parametros!$B$7)*(1-0.55*G$5/(G$5+150))*9.81*Parametros!$B$11/100000+5*($F24/200)^1.8*(3.5/Parametros!$B$10)^4.8 -> 167.20568 | H24: =Parametros!$B$8+(Parametros!$B$12*(1-Parametros!$B$7)+Parametros!$B$13*Parametros!$B$7)*(1-0.55*H$5/(H$5+150))*9.81*Parametros!$B$11/100000+5*($F24/200)^1.8*(3.5/Parametros!$B$10)^4.8 -> 145.62368 | I24: =Parametros!$B$8+(Parametros!$B$12*(1-Parametros!$B$7)+Parametros!$B$13*Parametros!$B$7)*(1-0.55*I$5/(I$5+150))*9.81*Parametros!$B$11/100000+5*($F24/200)^1.8*(3.5/Parametros!$B$10)^4.8 -> 132.67448 | J24: =Parametros!$B$8+(Parametros!$B$12*(1-Parametros!$B$7)+Parametros!$B$13*Parametros!$B$7)*(1-0.55*J$5/(J$5+150))*9.81*Parametros!$B$11/100000+5*($F24/200)^1.8*(3.5/Parametros!$B$10)^4.8 -> 124.04168 | K24: =Parametros!$B$8+(Parametros!$B$12*(1-Parametros!$B$7)+Parametros!$B$13*Parametros!$B$7)*(1-0.55*K$5/(K$5+150))*9.81*Parametros!$B$11/100000+5*($F24/200)^1.8*(3.5/Parametros!$B$10)^4.8 -> 117.8754 | L24: =Parametros!$B$8+(Parametros!$B$12*(1-Parametros!$B$7)+Parametros!$B$13*Parametros!$B$7)*(1-0.55*L$5/(L$5+150))*9.81*Parametros!$B$11/100000+5*($F24/200)^1.8*(3.5/Parametros!$B$10)^4.8 -> 113.25068 | M24: =Parametros!$B$8+(Parametros!$B$12*(1-Parametros!$B$7)+Parametros!$B$13*Parametros!$B$7)*(1-0.55*M$5/(M$5+150))*9.81*Parametros!$B$11/100000+5*($F24/200)^1.8*(3.5/Parametros!$B$10)^4.8 -> 109.65368 | N24: =Parametros!$B$8+(Parametros!$B$12*(1-Parametros!$B$7)+Parametros!$B$13*Parametros!$B$7)*(1-0.55*N$5/(N$5+150))*9.81*Parametros!$B$11/100000+5*($F24/200)^1.8*(3.5/Parametros!$B$10)^4.8 -> 106.77608 | O24: =Parametros!$B$8+(Parametros!$B$12*(1-Parametros!$B$7)+Parametros!$B$13*Parametros!$B$7)*(1-0.55*O$5/(O$5+150))*9.81*Parametros!$B$11/100000+5*($F24/200)^1.8*(3.5/Parametros!$B$10)^4.8 -> 104.42168
F25: =Curvas!A24 -> 39.583333 | G25: =Parametros!$B$8+(Parametros!$B$12*(1-Parametros!$B$7)+Parametros!$B$13*Parametros!$B$7)*(1-0.55*G$5/(G$5+150))*9.81*Parametros!$B$11/100000+5*($F25/200)^1.8*(3.5/Parametros!$B$10)^4.8 -> 167.23079 | H25: =Parametros!$B$8+(Parametros!$B$12*(1-Parametros!$B$7)+Parametros!$B$13*Parametros!$B$7)*(1-0.55*H$5/(H$5+150))*9.81*Parametros!$B$11/100000+5*($F25/200)^1.8*(3.5/Parametros!$B$10)^4.8 -> 145.64879 | I25: =Parametros!$B$8+(Parametros!$B$12*(1-Parametros!$B$7)+Parametros!$B$13*Parametros!$B$7)*(1-0.55*I$5/(I$5+150))*9.81*Parametros!$B$11/100000+5*($F25/200)^1.8*(3.5/Parametros!$B$10)^4.8 -> 132.69959 | J25: =Parametros!$B$8+(Parametros!$B$12*(1-Parametros!$B$7)+Parametros!$B$13*Parametros!$B$7)*(1-0.55*J$5/(J$5+150))*9.81*Parametros!$B$11/100000+5*($F25/200)^1.8*(3.5/Parametros!$B$10)^4.8 -> 124.06679 | K25: =Parametros!$B$8+(Parametros!$B$12*(1-Parametros!$B$7)+Parametros!$B$13*Parametros!$B$7)*(1-0.55*K$5/(K$5+150))*9.81*Parametros!$B$11/100000+5*($F25/200)^1.8*(3.5/Parametros!$B$10)^4.8 -> 117.90051 | L25: =Parametros!$B$8+(Parametros!$B$12*(1-Parametros!$B$7)+Parametros!$B$13*Parametros!$B$7)*(1-0.55*L$5/(L$5+150))*9.81*Parametros!$B$11/100000+5*($F25/200)^1.8*(3.5/Parametros!$B$10)^4.8 -> 113.27579 | M25: =Parametros!$B$8+(Parametros!$B$12*(1-Parametros!$B$7)+Parametros!$B$13*Parametros!$B$7)*(1-0.55*M$5/(M$5+150))*9.81*Parametros!$B$11/100000+5*($F25/200)^1.8*(3.5/Parametros!$B$10)^4.8 -> 109.67879 | N25: =Parametros!$B$8+(Parametros!$B$12*(1-Parametros!$B$7)+Parametros!$B$13*Parametros!$B$7)*(1-0.55*N$5/(N$5+150))*9.81*Parametros!$B$11/100000+5*($F25/200)^1.8*(3.5/Parametros!$B$10)^4.8 -> 106.80119 | O25: =Parametros!$B$8+(Parametros!$B$12*(1-Parametros!$B$7)+Parametros!$B$13*Parametros!$B$7)*(1-0.55*O$5/(O$5+150))*9.81*Parametros!$B$11/100000+5*($F25/200)^1.8*(3.5/Parametros!$B$10)^4.8 -> 104.44679
F26: =Curvas!A25 -> 41.666667 | G26: =Parametros!$B$8+(Parametros!$B$12*(1-Parametros!$B$7)+Parametros!$B$13*Parametros!$B$7)*(1-0.55*G$5/(G$5+150))*9.81*Parametros!$B$11/100000+5*($F26/200)^1.8*(3.5/Parametros!$B$10)^4.8 -> 167.25699 | H26: =Parametros!$B$8+(Parametros!$B$12*(1-Parametros!$B$7)+Parametros!$B$13*Parametros!$B$7)*(1-0.55*H$5/(H$5+150))*9.81*Parametros!$B$11/100000+5*($F26/200)^1.8*(3.5/Parametros!$B$10)^4.8 -> 145.67499 | I26: =Parametros!$B$8+(Parametros!$B$12*(1-Parametros!$B$7)+Parametros!$B$13*Parametros!$B$7)*(1-0.55*I$5/(I$5+150))*9.81*Parametros!$B$11/100000+5*($F26/200)^1.8*(3.5/Parametros!$B$10)^4.8 -> 132.72579 | J26: =Parametros!$B$8+(Parametros!$B$12*(1-Parametros!$B$7)+Parametros!$B$13*Parametros!$B$7)*(1-0.55*J$5/(J$5+150))*9.81*Parametros!$B$11/100000+5*($F26/200)^1.8*(3.5/Parametros!$B$10)^4.8 -> 124.09299 | K26: =Parametros!$B$8+(Parametros!$B$12*(1-Parametros!$B$7)+Parametros!$B$13*Parametros!$B$7)*(1-0.55*K$5/(K$5+150))*9.81*Parametros!$B$11/100000+5*($F26/200)^1.8*(3.5/Parametros!$B$10)^4.8 -> 117.9267 | L26: =Parametros!$B$8+(Parametros!$B$12*(1-Parametros!$B$7)+Parametros!$B$13*Parametros!$B$7)*(1-0.55*L$5/(L$5+150))*9.81*Parametros!$B$11/100000+5*($F26/200)^1.8*(3.5/Parametros!$B$10)^4.8 -> 113.30199 | M26: =Parametros!$B$8+(Parametros!$B$12*(1-Parametros!$B$7)+Parametros!$B$13*Parametros!$B$7)*(1-0.55*M$5/(M$5+150))*9.81*Parametros!$B$11/100000+5*($F26/200)^1.8*(3.5/Parametros!$B$10)^4.8 -> 109.70499 | N26: =Parametros!$B$8+(Parametros!$B$12*(1-Parametros!$B$7)+Parametros!$B$13*Parametros!$B$7)*(1-0.55*N$5/(N$5+150))*9.81*Parametros!$B$11/100000+5*($F26/200)^1.8*(3.5/Parametros!$B$10)^4.8 -> 106.82739 | O26: =Parametros!$B$8+(Parametros!$B$12*(1-Parametros!$B$7)+Parametros!$B$13*Parametros!$B$7)*(1-0.55*O$5/(O$5+150))*9.81*Parametros!$B$11/100000+5*($F26/200)^1.8*(3.5/Parametros!$B$10)^4.8 -> 104.47299
