Workbook

Sheet Ajuste
A1: Ajuste histórico con balance de materiales y acuífero
A2: Datos de ejemplo (sintéticos) con fines didácticos. Celdas azules sobre fondo crema = entradas editables; el resto son fórmulas.
A4: Parámetro | B4: Valor | C4: Unidad
A5: Presión inicial pi | B5: 4500 | C5: psi
A6: Compresibilidad total ct | B6: 1.2e-05 | C6: 1/psi
A7: Petróleo original N (a ajustar) | B7: 250 | C7: MMbbl
A8: Fuerza del acuífero Ca (a ajustar) | B8: 5 | C8: Mbbl/psi
A9: Incluir agua producida (1 = sí, 0 = no) | B9: 0
A10: Incertidumbre del dato de presión σp | B10: 25 | C10: psi
A11: Incertidumbre del dato de agua σw | B11: 0.12 | C11: MMbbl
A13: Ceff = N·ct + Ca (Mbbl/psi) | B13: =B7*B6*1000+B8 -> 8 | C13: Con solo presión, solo Ceff está restringido
A14: Error de ajuste (σ) | B14: =SQRT((SUMPRODUCT(((E19:E29-C19:C29)/B10)^2)+IF(B9=1,SUMPRODUCT(((F19:F29-D19:D29)/B11)^2),0))/IF(B9=1,22,11)) -> 0.84482338 | C14: Menor que 1,5: el modelo ajusta
A15: Agua acumulada a 20 años (pronóstico) | B15: =B8*(1.2*20*1000/B13)/1000 -> 15 | C15: MMbbl
A18: Año | B18: Np (MMbbl) | C18: p observada (psi) | D18: Wp observada (MMbbl) | E18: p modelo (psi) | F18: Wp modelo (MMbbl) | G18: Residual p (psi)
A19: 0 | B19: =1.2*A19 -> 0 | C19: 4470.5 | D19: 0 | E19: =$B$5-B19*1000/$B$13 -> 4500 | F19: =$B$8*(B19*1000/$B$13)/1000 -> 0 | G19: =E19-C19 -> 29.5
A20: 1 | B20: =1.2*A20 -> 1.2 | C20: 4366.7 | D20: 0.2 | E20: =$B$5-B20*1000/$B$13 -> 4350 | F20: =$B$8*(B20*1000/$B$13)/1000 -> 0.75 | G20: =E20-C20 -> -16.7
A21: 2 | B21: =1.2*A21 -> 2.4 | C21: 4196.4 | D21: 0.69 | E21: =$B$5-B21*1000/$B$13 -> 4200 | F21: =$B$8*(B21*1000/$B$13)/1000 -> 1.5 | G21: =E21-C21 -> 3.6
A22: 3 | B22: =1.2*A22 -> 3.6 | C22: 4077.5 | D22: 1.46 | E22: =$B$5-B22*1000/$B$13 -> 4050 | F22: =$B$8*(B22*1000/$B$13)/1000 -> 2.25 | G22: =E22-C22 -> -27.5
A23: 4 | B23: =1.2*A23 -> 4.8 | C23: 3933.9 | D23: 1.86 | E23: =$B$5-B23*1000/$B$13 -> 3900 | F23: =$B$8*(B23*1000/$B$13)/1000 -> 3 | G23: =E23-C23 -> -33.9
A24: 5 | B24: =1.2*A24 -> 6 | C24: 3760 | D24: 2.37 | E24: =$B$5-B24*1000/$B$13 -> 3750 | F24: =$B$8*(B24*1000/$B$13)/1000 -> 3.75 | G24: =E24-C24 -> -10
A25: 6 | B25: =1.2*A25 -> 7.2 | C25: 3581.5 | D25: 2.9 | E25: =$B$5-B25*1000/$B$13 -> 3600 | F25: =$B$8*(B25*1000/$B$13)/1000 -> 4.5 | G25: =E25-C25 -> 18.5
A26: 7 | B26: =1.2*A26 -> 8.4 | C26: 3418.6 | D26: 3.32 | E26: =$B$5-B26*1000/$B$13 -> 3450 | F26: =$B$8*(B26*1000/$B$13)/1000 -> 5.25 | G26: =E26-C26 -> 31.4
A27: 8 | B27: =1.2*A27 -> 9.6 | C27: 3317.4 | D27: 3.85 | E27: =$B$5-B27*1000/$B$13 -> 3300 | F27: =$B$8*(B27*1000/$B$13)/1000 -> 6 | G27: =E27-C27 -> -17.4
A28: 9 | B28: =1.2*A28 -> 10.8 | C28: 3139.7 | D28: 4.58 | E28: =$B$5-B28*1000/$B$13 -> 3150 | F28: =$B$8*(B28*1000/$B$13)/1000 -> 6.75 | G28: =E28-C28 -> 10.3
A29: 10 | B29: =1.2*A29 -> 12 | C29: 3001.5 | D29: 4.73 | E29: =$B$5-B29*1000/$B$13 -> 3000 | F29: =$B$8*(B29*1000/$B$13)/1000 -> 7.5 | G29: =E29-C29 -> -1.5
A32: Pronóstico (el mismo caudal de 1,2 MMbbl/año)
A33: Año | B33: Np (MMbbl) | C33: p modelo (psi) | D33: Wp modelo (MMbbl)
A34: 11 | B34: =1.2*A34 -> 13.2 | C34: =$B$5-B34*1000/$B$13 -> 2850 | D34: =$B$8*(B34*1000/$B$13)/1000 -> 8.25
A35: 12 | B35: =1.2*A35 -> 14.4 | C35: =$B$5-B35*1000/$B$13 -> 2700 | D35: =$B$8*(B35*1000/$B$13)/1000 -> 9
A36: 13 | B36: =1.2*A36 -> 15.6 | C36: =$B$5-B36*1000/$B$13 -> 2550 | D36: =$B$8*(B36*1000/$B$13)/1000 -> 9.75
A37: 14 | B37: =1.2*A37 -> 16.8 | C37: =$B$5-B37*1000/$B$13 -> 2400 | D37: =$B$8*(B37*1000/$B$13)/1000 -> 10.5
A38: 15 | B38: =1.2*A38 -> 18 | C38: =$B$5-B38*1000/$B$13 -> 2250 | D38: =$B$8*(B38*1000/$B$13)/1000 -> 11.25
A39: 16 | B39: =1.2*A39 -> 19.2 | C39: =$B$5-B39*1000/$B$13 -> 2100 | D39: =$B$8*(B39*1000/$B$13)/1000 -> 12
A40: 17 | B40: =1.2*A40 -> 20.4 | C40: =$B$5-B40*1000/$B$13 -> 1950 | D40: =$B$8*(B40*1000/$B$13)/1000 -> 12.75
A41: 18 | B41: =1.2*A41 -> 21.6 | C41: =$B$5-B41*1000/$B$13 -> 1800 | D41: =$B$8*(B41*1000/$B$13)/1000 -> 13.5
A42: 19 | B42: =1.2*A42 -> 22.8 | C42: =$B$5-B42*1000/$B$13 -> 1650 | D42: =$B$8*(B42*1000/$B$13)/1000 -> 14.25
A43: 20 | B43: =1.2*A43 -> 24 | C43: =$B$5-B43*1000/$B$13 -> 1500 | D43: =$B$8*(B43*1000/$B$13)/1000 -> 15
A46: Los datos son sintéticos (N = 400 MMbbl, Ca = 3,2 Mbbl/psi más ruido). Probá primero con solo presión, y encontrá varios pares (N, Ca) con error menor a 1,5 que den distinto pronóstico de agua. Después poné 1 en "Incluir agua" y repetí.

Sheet Mapa
A1: Mapa del error de ajuste (solo presión)
A2: Cada celda calcula σ con los datos de la hoja Ajuste. Verde: modelos que ajustan (σ < 1,5).
A4: Ca \ N | B4: 100 | C4: 150 | D4: 200 | E4: 250 | F4: 300 | G4: 350 | H4: 400 | I4: 450 | J4: 500 | K4: 550 | L4: 600 | M4: 650 | N4: 700 | O4: 750 | P4: 800
A5: 0 | B5: =SQRT(SUMPRODUCT(((Ajuste!$B$5-Ajuste!$B$19:$B$29*1000/(B$4*Ajuste!$B$6*1000+$A5)-Ajuste!$C$19:$C$29)/Ajuste!$B$10)^2)/11) -> 201.15359 | C5: =SQRT(SUMPRODUCT(((Ajuste!$B$5-Ajuste!$B$19:$B$29*1000/(C$4*Ajuste!$B$6*1000+$A5)-Ajuste!$C$19:$C$29)/Ajuste!$B$10)^2)/11) -> 122.27367 | D5: =SQRT(SUMPRODUCT(((Ajuste!$B$5-Ajuste!$B$19:$B$29*1000/(D$4*Ajuste!$B$6*1000+$A5)-Ajuste!$C$19:$C$29)/Ajuste!$B$10)^2)/11) -> 82.834527 | E5: =SQRT(SUMPRODUCT(((Ajuste!$B$5-Ajuste!$B$19:$B$29*1000/(E$4*Ajuste!$B$6*1000+$A5)-Ajuste!$C$19:$C$29)/Ajuste!$B$10)^2)/11) -> 59.171931 | F5: =SQRT(SUMPRODUCT(((Ajuste!$B$5-Ajuste!$B$19:$B$29*1000/(F$4*Ajuste!$B$6*1000+$A5)-Ajuste!$C$19:$C$29)/Ajuste!$B$10)^2)/11) -> 43.39791 | G5: =SQRT(SUMPRODUCT(((Ajuste!$B$5-Ajuste!$B$19:$B$29*1000/(G$4*Ajuste!$B$6*1000+$A5)-Ajuste!$C$19:$C$29)/Ajuste!$B$10)^2)/11) -> 32.132071 | H5: =SQRT(SUMPRODUCT(((Ajuste!$B$5-Ajuste!$B$19:$B$29*1000/(H$4*Ajuste!$B$6*1000+$A5)-Ajuste!$C$19:$C$29)/Ajuste!$B$10)^2)/11) -> 23.684492 | I5: =SQRT(SUMPRODUCT(((Ajuste!$B$5-Ajuste!$B$19:$B$29*1000/(I$4*Ajuste!$B$6*1000+$A5)-Ajuste!$C$19:$C$29)/Ajuste!$B$10)^2)/11) -> 17.116859 | ... P5: =SQRT(SUMPRODUCT(((Ajuste!$B$5-Ajuste!$B$19:$B$29*1000/(P$4*Ajuste!$B$6*1000+$A5)-Ajuste!$C$19:$C$29)/Ajuste!$B$10)^2)/11) -> 5.9710437
A6: 0.5 | B6: =SQRT(SUMPRODUCT(((Ajuste!$B$5-Ajuste!$B$19:$B$29*1000/(B$4*Ajuste!$B$6*1000+$A6)-Ajuste!$C$19:$C$29)/Ajuste!$B$10)^2)/11) -> 131.55359 | C6: =SQRT(SUMPRODUCT(((Ajuste!$B$5-Ajuste!$B$19:$B$29*1000/(C$4*Ajuste!$B$6*1000+$A6)-Ajuste!$C$19:$C$29)/Ajuste!$B$10)^2)/11) -> 87.978692 | D6: =SQRT(SUMPRODUCT(((Ajuste!$B$5-Ajuste!$B$19:$B$29*1000/(D$4*Ajuste!$B$6*1000+$A6)-Ajuste!$C$19:$C$29)/Ajuste!$B$10)^2)/11) -> 62.435659 | E6: =SQRT(SUMPRODUCT(((Ajuste!$B$5-Ajuste!$B$19:$B$29*1000/(E$4*Ajuste!$B$6*1000+$A6)-Ajuste!$C$19:$C$29)/Ajuste!$B$10)^2)/11) -> 45.651249 | F6: =SQRT(SUMPRODUCT(((Ajuste!$B$5-Ajuste!$B$19:$B$29*1000/(F$4*Ajuste!$B$6*1000+$A6)-Ajuste!$C$19:$C$29)/Ajuste!$B$10)^2)/11) -> 33.78061 | G6: =SQRT(SUMPRODUCT(((Ajuste!$B$5-Ajuste!$B$19:$B$29*1000/(G$4*Ajuste!$B$6*1000+$A6)-Ajuste!$C$19:$C$29)/Ajuste!$B$10)^2)/11) -> 24.942472 | H6: =SQRT(SUMPRODUCT(((Ajuste!$B$5-Ajuste!$B$19:$B$29*1000/(H$4*Ajuste!$B$6*1000+$A6)-Ajuste!$C$19:$C$29)/Ajuste!$B$10)^2)/11) -> 18.107931 | I6: =SQRT(SUMPRODUCT(((Ajuste!$B$5-Ajuste!$B$19:$B$29*1000/(I$4*Ajuste!$B$6*1000+$A6)-Ajuste!$C$19:$C$29)/Ajuste!$B$10)^2)/11) -> 12.667643 | ... P6: =SQRT(SUMPRODUCT(((Ajuste!$B$5-Ajuste!$B$19:$B$29*1000/(P$4*Ajuste!$B$6*1000+$A6)-Ajuste!$C$19:$C$29)/Ajuste!$B$10)^2)/11) -> 7.4235808
A7: 1 | B7: =SQRT(SUMPRODUCT(((Ajuste!$B$5-Ajuste!$B$19:$B$29*1000/(B$4*Ajuste!$B$6*1000+$A7)-Ajuste!$C$19:$C$29)/Ajuste!$B$10)^2)/11) -> 93.59054 | C7: =SQRT(SUMPRODUCT(((Ajuste!$B$5-Ajuste!$B$19:$B$29*1000/(C$4*Ajuste!$B$6*1000+$A7)-Ajuste!$C$19:$C$29)/Ajuste!$B$10)^2)/11) -> 65.932546 | D7: =SQRT(SUMPRODUCT(((Ajuste!$B$5-Ajuste!$B$19:$B$29*1000/(D$4*Ajuste!$B$6*1000+$A7)-Ajuste!$C$19:$C$29)/Ajuste!$B$10)^2)/11) -> 48.037179 | E7: =SQRT(SUMPRODUCT(((Ajuste!$B$5-Ajuste!$B$19:$B$29*1000/(E$4*Ajuste!$B$6*1000+$A7)-Ajuste!$C$19:$C$29)/Ajuste!$B$10)^2)/11) -> 35.511631 | F7: =SQRT(SUMPRODUCT(((Ajuste!$B$5-Ajuste!$B$19:$B$29*1000/(F$4*Ajuste!$B$6*1000+$A7)-Ajuste!$C$19:$C$29)/Ajuste!$B$10)^2)/11) -> 26.255225 | G7: =SQRT(SUMPRODUCT(((Ajuste!$B$5-Ajuste!$B$19:$B$29*1000/(G$4*Ajuste!$B$6*1000+$A7)-Ajuste!$C$19:$C$29)/Ajuste!$B$10)^2)/11) -> 19.137246 | H7: =SQRT(SUMPRODUCT(((Ajuste!$B$5-Ajuste!$B$19:$B$29*1000/(H$4*Ajuste!$B$6*1000+$A7)-Ajuste!$C$19:$C$29)/Ajuste!$B$10)^2)/11) -> 13.495751 | I7: =SQRT(SUMPRODUCT(((Ajuste!$B$5-Ajuste!$B$19:$B$29*1000/(I$4*Ajuste!$B$6*1000+$A7)-Ajuste!$C$19:$C$29)/Ajuste!$B$10)^2)/11) -> 8.9193202 | ... P7: =SQRT(SUMPRODUCT(((Ajuste!$B$5-Ajuste!$B$19:$B$29*1000/(P$4*Ajuste!$B$6*1000+$A7)-Ajuste!$C$19:$C$29)/Ajuste!$B$10)^2)/11) -> 8.7424954
A8: 1.5 | B8: =SQRT(SUMPRODUCT(((Ajuste!$B$5-Ajuste!$B$19:$B$29*1000/(B$4*Ajuste!$B$6*1000+$A8)-Ajuste!$C$19:$C$29)/Ajuste!$B$10)^2)/11) -> 69.688495 | C8: =SQRT(SUMPRODUCT(((Ajuste!$B$5-Ajuste!$B$19:$B$29*1000/(C$4*Ajuste!$B$6*1000+$A8)-Ajuste!$C$19:$C$29)/Ajuste!$B$10)^2)/11) -> 50.56775 | D8: =SQRT(SUMPRODUCT(((Ajuste!$B$5-Ajuste!$B$19:$B$29*1000/(D$4*Ajuste!$B$6*1000+$A8)-Ajuste!$C$19:$C$29)/Ajuste!$B$10)^2)/11) -> 37.331473 | E8: =SQRT(SUMPRODUCT(((Ajuste!$B$5-Ajuste!$B$19:$B$29*1000/(E$4*Ajuste!$B$6*1000+$A8)-Ajuste!$C$19:$C$29)/Ajuste!$B$10)^2)/11) -> 27.626394 | F8: =SQRT(SUMPRODUCT(((Ajuste!$B$5-Ajuste!$B$19:$B$29*1000/(F$4*Ajuste!$B$6*1000+$A8)-Ajuste!$C$19:$C$29)/Ajuste!$B$10)^2)/11) -> 20.207041 | G8: =SQRT(SUMPRODUCT(((Ajuste!$B$5-Ajuste!$B$19:$B$29*1000/(G$4*Ajuste!$B$6*1000+$A8)-Ajuste!$C$19:$C$29)/Ajuste!$B$10)^2)/11) -> 14.353126 | H8: =SQRT(SUMPRODUCT(((Ajuste!$B$5-Ajuste!$B$19:$B$29*1000/(H$4*Ajuste!$B$6*1000+$A8)-Ajuste!$C$19:$C$29)/Ajuste!$B$10)^2)/11) -> 9.6206803 | I8: =SQRT(SUMPRODUCT(((Ajuste!$B$5-Ajuste!$B$19:$B$29*1000/(I$4*Ajuste!$B$6*1000+$A8)-Ajuste!$C$19:$C$29)/Ajuste!$B$10)^2)/11) -> 5.7266177 | ... P8: =SQRT(SUMPRODUCT(((Ajuste!$B$5-Ajuste!$B$19:$B$29*1000/(P$4*Ajuste!$B$6*1000+$A8)-Ajuste!$C$19:$C$29)/Ajuste!$B$10)^2)/11) -> 9.9442793
A9: 2 | B9: =SQRT(SUMPRODUCT(((Ajuste!$B$5-Ajuste!$B$19:$B$29*1000/(B$4*Ajuste!$B$6*1000+$A9)-Ajuste!$C$19:$C$29)/Ajuste!$B$10)^2)/11) -> 53.256521 | C9: =SQRT(SUMPRODUCT(((Ajuste!$B$5-Ajuste!$B$19:$B$29*1000/(C$4*Ajuste!$B$6*1000+$A9)-Ajuste!$C$19:$C$29)/Ajuste!$B$10)^2)/11) -> 39.247145 | D9: =SQRT(SUMPRODUCT(((Ajuste!$B$5-Ajuste!$B$19:$B$29*1000/(D$4*Ajuste!$B$6*1000+$A9)-Ajuste!$C$19:$C$29)/Ajuste!$B$10)^2)/11) -> 29.059958 | E9: =SQRT(SUMPRODUCT(((Ajuste!$B$5-Ajuste!$B$19:$B$29*1000/(E$4*Ajuste!$B$6*1000+$A9)-Ajuste!$C$19:$C$29)/Ajuste!$B$10)^2)/11) -> 21.319733 | F9: =SQRT(SUMPRODUCT(((Ajuste!$B$5-Ajuste!$B$19:$B$29*1000/(F$4*Ajuste!$B$6*1000+$A9)-Ajuste!$C$19:$C$29)/Ajuste!$B$10)^2)/11) -> 15.24131 | G9: =SQRT(SUMPRODUCT(((Ajuste!$B$5-Ajuste!$B$19:$B$29*1000/(G$4*Ajuste!$B$6*1000+$A9)-Ajuste!$C$19:$C$29)/Ajuste!$B$10)^2)/11) -> 10.345083 | H9: =SQRT(SUMPRODUCT(((Ajuste!$B$5-Ajuste!$B$19:$B$29*1000/(H$4*Ajuste!$B$6*1000+$A9)-Ajuste!$C$19:$C$29)/Ajuste!$B$10)^2)/11) -> 6.3258514 | I9: =SQRT(SUMPRODUCT(((Ajuste!$B$5-Ajuste!$B$19:$B$29*1000/(I$4*Ajuste!$B$6*1000+$A9)-Ajuste!$C$19:$C$29)/Ajuste!$B$10)^2)/11) -> 3.0044153 | ... P9: =SQRT(SUMPRODUCT(((Ajuste!$B$5-Ajuste!$B$19:$B$29*1000/(P$4*Ajuste!$B$6*1000+$A9)-Ajuste!$C$19:$C$29)/Ajuste!$B$10)^2)/11) -> 11.043408
A10: 2.5 | B10: =SQRT(SUMPRODUCT(((Ajuste!$B$5-Ajuste!$B$19:$B$29*1000/(B$4*Ajuste!$B$6*1000+$A10)-Ajuste!$C$19:$C$29)/Ajuste!$B$10)^2)/11) -> 41.266414 | C10: =SQRT(SUMPRODUCT(((Ajuste!$B$5-Ajuste!$B$19:$B$29*1000/(C$4*Ajuste!$B$6*1000+$A10)-Ajuste!$C$19:$C$29)/Ajuste!$B$10)^2)/11) -> 30.560262 | D10: =SQRT(SUMPRODUCT(((Ajuste!$B$5-Ajuste!$B$19:$B$29*1000/(D$4*Ajuste!$B$6*1000+$A10)-Ajuste!$C$19:$C$29)/Ajuste!$B$10)^2)/11) -> 22.477939 | E10: =SQRT(SUMPRODUCT(((Ajuste!$B$5-Ajuste!$B$19:$B$29*1000/(E$4*Ajuste!$B$6*1000+$A10)-Ajuste!$C$19:$C$29)/Ajuste!$B$10)^2)/11) -> 16.161959 | F10: =SQRT(SUMPRODUCT(((Ajuste!$B$5-Ajuste!$B$19:$B$29*1000/(F$4*Ajuste!$B$6*1000+$A10)-Ajuste!$C$19:$C$29)/Ajuste!$B$10)^2)/11) -> 11.093596 | G10: =SQRT(SUMPRODUCT(((Ajuste!$B$5-Ajuste!$B$19:$B$29*1000/(G$4*Ajuste!$B$6*1000+$A10)-Ajuste!$C$19:$C$29)/Ajuste!$B$10)^2)/11) -> 6.944059 | H10: =SQRT(SUMPRODUCT(((Ajuste!$B$5-Ajuste!$B$19:$B$29*1000/(H$4*Ajuste!$B$6*1000+$A10)-Ajuste!$C$19:$C$29)/Ajuste!$B$10)^2)/11) -> 3.5119965 | I10: =SQRT(SUMPRODUCT(((Ajuste!$B$5-Ajuste!$B$19:$B$29*1000/(I$4*Ajuste!$B$6*1000+$A10)-Ajuste!$C$19:$C$29)/Ajuste!$B$10)^2)/11) -> 0.95927152 | ... P10: =SQRT(SUMPRODUCT(((Ajuste!$B$5-Ajuste!$B$19:$B$29*1000/(P$4*Ajuste!$B$6*1000+$A10)-Ajuste!$C$19:$C$29)/Ajuste!$B$10)^2)/11) -> 12.052276
A11: 3 | B11: =SQRT(SUMPRODUCT(((Ajuste!$B$5-Ajuste!$B$19:$B$29*1000/(B$4*Ajuste!$B$6*1000+$A11)-Ajuste!$C$19:$C$29)/Ajuste!$B$10)^2)/11) -> 32.132071 | C11: =SQRT(SUMPRODUCT(((Ajuste!$B$5-Ajuste!$B$19:$B$29*1000/(C$4*Ajuste!$B$6*1000+$A11)-Ajuste!$C$19:$C$29)/Ajuste!$B$10)^2)/11) -> 23.684492 | D11: =SQRT(SUMPRODUCT(((Ajuste!$B$5-Ajuste!$B$19:$B$29*1000/(D$4*Ajuste!$B$6*1000+$A11)-Ajuste!$C$19:$C$29)/Ajuste!$B$10)^2)/11) -> 17.116859 | E11: =SQRT(SUMPRODUCT(((Ajuste!$B$5-Ajuste!$B$19:$B$29*1000/(E$4*Ajuste!$B$6*1000+$A11)-Ajuste!$C$19:$C$29)/Ajuste!$B$10)^2)/11) -> 11.867369 | F11: =SQRT(SUMPRODUCT(((Ajuste!$B$5-Ajuste!$B$19:$B$29*1000/(F$4*Ajuste!$B$6*1000+$A11)-Ajuste!$C$19:$C$29)/Ajuste!$B$10)^2)/11) -> 7.581871 | G11: =SQRT(SUMPRODUCT(((Ajuste!$B$5-Ajuste!$B$19:$B$29*1000/(G$4*Ajuste!$B$6*1000+$A11)-Ajuste!$C$19:$C$29)/Ajuste!$B$10)^2)/11) -> 4.0385052 | H11: =SQRT(SUMPRODUCT(((Ajuste!$B$5-Ajuste!$B$19:$B$29*1000/(H$4*Ajuste!$B$6*1000+$A11)-Ajuste!$C$19:$C$29)/Ajuste!$B$10)^2)/11) -> 1.2455584 | I11: =SQRT(SUMPRODUCT(((Ajuste!$B$5-Ajuste!$B$19:$B$29*1000/(I$4*Ajuste!$B$6*1000+$A11)-Ajuste!$C$19:$C$29)/Ajuste!$B$10)^2)/11) -> 1.8851055 | ... P11: =SQRT(SUMPRODUCT(((Ajuste!$B$5-Ajuste!$B$19:$B$29*1000/(P$4*Ajuste!$B$6*1000+$A11)-Ajuste!$C$19:$C$29)/Ajuste!$B$10)^2)/11) -> 12.981449
A12: 3.5 | B12: =SQRT(SUMPRODUCT(((Ajuste!$B$5-Ajuste!$B$19:$B$29*1000/(B$4*Ajuste!$B$6*1000+$A12)-Ajuste!$C$19:$C$29)/Ajuste!$B$10)^2)/11) -> 24.942472 | C12: =SQRT(SUMPRODUCT(((Ajuste!$B$5-Ajuste!$B$19:$B$29*1000/(C$4*Ajuste!$B$6*1000+$A12)-Ajuste!$C$19:$C$29)/Ajuste!$B$10)^2)/11) -> 18.107931 | D12: =SQRT(SUMPRODUCT(((Ajuste!$B$5-Ajuste!$B$19:$B$29*1000/(D$4*Ajuste!$B$6*1000+$A12)-Ajuste!$C$19:$C$29)/Ajuste!$B$10)^2)/11) -> 12.667643 | E12: =SQRT(SUMPRODUCT(((Ajuste!$B$5-Ajuste!$B$19:$B$29*1000/(E$4*Ajuste!$B$6*1000+$A12)-Ajuste!$C$19:$C$29)/Ajuste!$B$10)^2)/11) -> 8.2400181 | F12: =SQRT(SUMPRODUCT(((Ajuste!$B$5-Ajuste!$B$19:$B$29*1000/(F$4*Ajuste!$B$6*1000+$A12)-Ajuste!$C$19:$C$29)/Ajuste!$B$10)^2)/11) -> 4.5831888 | G12: =SQRT(SUMPRODUCT(((Ajuste!$B$5-Ajuste!$B$19:$B$29*1000/(G$4*Ajuste!$B$6*1000+$A12)-Ajuste!$C$19:$C$29)/Ajuste!$B$10)^2)/11) -> 1.6249524 | H12: =SQRT(SUMPRODUCT(((Ajuste!$B$5-Ajuste!$B$19:$B$29*1000/(H$4*Ajuste!$B$6*1000+$A12)-Ajuste!$C$19:$C$29)/Ajuste!$B$10)^2)/11) -> 1.5319067 | I12: =SQRT(SUMPRODUCT(((Ajuste!$B$5-Ajuste!$B$19:$B$29*1000/(I$4*Ajuste!$B$6*1000+$A12)-Ajuste!$C$19:$C$29)/Ajuste!$B$10)^2)/11) -> 3.6826401 | ... P12: =SQRT(SUMPRODUCT(((Ajuste!$B$5-Ajuste!$B$19:$B$29*1000/(P$4*Ajuste!$B$6*1000+$A12)-Ajuste!$C$19:$C$29)/Ajuste!$B$10)^2)/11) -> 13.839946
A13: 4 | B13: =SQRT(SUMPRODUCT(((Ajuste!$B$5-Ajuste!$B$19:$B$29*1000/(B$4*Ajuste!$B$6*1000+$A13)-Ajuste!$C$19:$C$29)/Ajuste!$B$10)^2)/11) -> 19.137246 | C13: =SQRT(SUMPRODUCT(((Ajuste!$B$5-Ajuste!$B$19:$B$29*1000/(C$4*Ajuste!$B$6*1000+$A13)-Ajuste!$C$19:$C$29)/Ajuste!$B$10)^2)/11) -> 13.495751 | D13: =SQRT(SUMPRODUCT(((Ajuste!$B$5-Ajuste!$B$19:$B$29*1000/(D$4*Ajuste!$B$6*1000+$A13)-Ajuste!$C$19:$C$29)/Ajuste!$B$10)^2)/11) -> 8.9193202 | E13: =SQRT(SUMPRODUCT(((Ajuste!$B$5-Ajuste!$B$19:$B$29*1000/(E$4*Ajuste!$B$6*1000+$A13)-Ajuste!$C$19:$C$29)/Ajuste!$B$10)^2)/11) -> 5.1458481 | F13: =SQRT(SUMPRODUCT(((Ajuste!$B$5-Ajuste!$B$19:$B$29*1000/(F$4*Ajuste!$B$6*1000+$A13)-Ajuste!$C$19:$C$29)/Ajuste!$B$10)^2)/11) -> 2.0550167 | G13: =SQRT(SUMPRODUCT(((Ajuste!$B$5-Ajuste!$B$19:$B$29*1000/(G$4*Ajuste!$B$6*1000+$A13)-Ajuste!$C$19:$C$29)/Ajuste!$B$10)^2)/11) -> 1.2060044 | H13: =SQRT(SUMPRODUCT(((Ajuste!$B$5-Ajuste!$B$19:$B$29*1000/(H$4*Ajuste!$B$6*1000+$A13)-Ajuste!$C$19:$C$29)/Ajuste!$B$10)^2)/11) -> 3.3307693 | I13: =SQRT(SUMPRODUCT(((Ajuste!$B$5-Ajuste!$B$19:$B$29*1000/(I$4*Ajuste!$B$6*1000+$A13)-Ajuste!$C$19:$C$29)/Ajuste!$B$10)^2)/11) -> 5.3487459 | ... P13: =SQRT(SUMPRODUCT(((Ajuste!$B$5-Ajuste!$B$19:$B$29*1000/(P$4*Ajuste!$B$6*1000+$A13)-Ajuste!$C$19:$C$29)/Ajuste!$B$10)^2)/11) -> 14.635498
A14: 4.5 | B14: =SQRT(SUMPRODUCT(((Ajuste!$B$5-Ajuste!$B$19:$B$29*1000/(B$4*Ajuste!$B$6*1000+$A14)-Ajuste!$C$19:$C$29)/Ajuste!$B$10)^2)/11) -> 14.353126 | C14: =SQRT(SUMPRODUCT(((Ajuste!$B$5-Ajuste!$B$19:$B$29*1000/(C$4*Ajuste!$B$6*1000+$A14)-Ajuste!$C$19:$C$29)/Ajuste!$B$10)^2)/11) -> 9.6206803 | D14: =SQRT(SUMPRODUCT(((Ajuste!$B$5-Ajuste!$B$19:$B$29*1000/(D$4*Ajuste!$B$6*1000+$A14)-Ajuste!$C$19:$C$29)/Ajuste!$B$10)^2)/11) -> 5.7266177 | E14: =SQRT(SUMPRODUCT(((Ajuste!$B$5-Ajuste!$B$19:$B$29*1000/(E$4*Ajuste!$B$6*1000+$A14)-Ajuste!$C$19:$C$29)/Ajuste!$B$10)^2)/11) -> 2.5175131 | F14: =SQRT(SUMPRODUCT(((Ajuste!$B$5-Ajuste!$B$19:$B$29*1000/(F$4*Ajuste!$B$6*1000+$A14)-Ajuste!$C$19:$C$29)/Ajuste!$B$10)^2)/11) -> 0.94936772 | G14: =SQRT(SUMPRODUCT(((Ajuste!$B$5-Ajuste!$B$19:$B$29*1000/(G$4*Ajuste!$B$6*1000+$A14)-Ajuste!$C$19:$C$29)/Ajuste!$B$10)^2)/11) -> 2.973473 | H14: =SQRT(SUMPRODUCT(((Ajuste!$B$5-Ajuste!$B$19:$B$29*1000/(H$4*Ajuste!$B$6*1000+$A14)-Ajuste!$C$19:$C$29)/Ajuste!$B$10)^2)/11) -> 5.0282488 | I14: =SQRT(SUMPRODUCT(((Ajuste!$B$5-Ajuste!$B$19:$B$29*1000/(I$4*Ajuste!$B$6*1000+$A14)-Ajuste!$C$19:$C$29)/Ajuste!$B$10)^2)/11) -> 6.8595748 | ... P14: =SQRT(SUMPRODUCT(((Ajuste!$B$5-Ajuste!$B$19:$B$29*1000/(P$4*Ajuste!$B$6*1000+$A14)-Ajuste!$C$19:$C$29)/Ajuste!$B$10)^2)/11) -> 15.374759
A15: 5 | B15: =SQRT(SUMPRODUCT(((Ajuste!$B$5-Ajuste!$B$19:$B$29*1000/(B$4*Ajuste!$B$6*1000+$A15)-Ajuste!$C$19:$C$29)/Ajuste!$B$10)^2)/11) -> 10.345083 | C15: =SQRT(SUMPRODUCT(((Ajuste!$B$5-Ajuste!$B$19:$B$29*1000/(C$4*Ajuste!$B$6*1000+$A15)-Ajuste!$C$19:$C$29)/Ajuste!$B$10)^2)/11) -> 6.3258514 | D15: =SQRT(SUMPRODUCT(((Ajuste!$B$5-Ajuste!$B$19:$B$29*1000/(D$4*Ajuste!$B$6*1000+$A15)-Ajuste!$C$19:$C$29)/Ajuste!$B$10)^2)/11) -> 3.0044153 | E15: =SQRT(SUMPRODUCT(((Ajuste!$B$5-Ajuste!$B$19:$B$29*1000/(E$4*Ajuste!$B$6*1000+$A15)-Ajuste!$C$19:$C$29)/Ajuste!$B$10)^2)/11) -> 0.84482338 | F15: =SQRT(SUMPRODUCT(((Ajuste!$B$5-Ajuste!$B$19:$B$29*1000/(F$4*Ajuste!$B$6*1000+$A15)-Ajuste!$C$19:$C$29)/Ajuste!$B$10)^2)/11) -> 2.6118007 | G15: =SQRT(SUMPRODUCT(((Ajuste!$B$5-Ajuste!$B$19:$B$29*1000/(G$4*Ajuste!$B$6*1000+$A15)-Ajuste!$C$19:$C$29)/Ajuste!$B$10)^2)/11) -> 4.7013996 | H15: =SQRT(SUMPRODUCT(((Ajuste!$B$5-Ajuste!$B$19:$B$29*1000/(H$4*Ajuste!$B$6*1000+$A15)-Ajuste!$C$19:$C$29)/Ajuste!$B$10)^2)/11) -> 6.5692079 | I15: =SQRT(SUMPRODUCT(((Ajuste!$B$5-Ajuste!$B$19:$B$29*1000/(I$4*Ajuste!$B$6*1000+$A15)-Ajuste!$C$19:$C$29)/Ajuste!$B$10)^2)/11) -> 8.2298686 | ... P15: =SQRT(SUMPRODUCT(((Ajuste!$B$5-Ajuste!$B$19:$B$29*1000/(P$4*Ajuste!$B$6*1000+$A15)-Ajuste!$C$19:$C$29)/Ajuste!$B$10)^2)/11) -> 16.063482
A16: 5.5 | B16: =SQRT(SUMPRODUCT(((Ajuste!$B$5-Ajuste!$B$19:$B$29*1000/(B$4*Ajuste!$B$6*1000+$A16)-Ajuste!$C$19:$C$29)/Ajuste!$B$10)^2)/11) -> 6.944059 | C16: =SQRT(SUMPRODUCT(((Ajuste!$B$5-Ajuste!$B$19:$B$29*1000/(C$4*Ajuste!$B$6*1000+$A16)-Ajuste!$C$19:$C$29)/Ajuste!$B$10)^2)/11) -> 3.5119965 | D16: =SQRT(SUMPRODUCT(((Ajuste!$B$5-Ajuste!$B$19:$B$29*1000/(D$4*Ajuste!$B$6*1000+$A16)-Ajuste!$C$19:$C$29)/Ajuste!$B$10)^2)/11) -> 0.95927152 | E16: =SQRT(SUMPRODUCT(((Ajuste!$B$5-Ajuste!$B$19:$B$29*1000/(E$4*Ajuste!$B$6*1000+$A16)-Ajuste!$C$19:$C$29)/Ajuste!$B$10)^2)/11) -> 2.2477285 | F16: =SQRT(SUMPRODUCT(((Ajuste!$B$5-Ajuste!$B$19:$B$29*1000/(F$4*Ajuste!$B$6*1000+$A16)-Ajuste!$C$19:$C$29)/Ajuste!$B$10)^2)/11) -> 4.3681536 | G16: =SQRT(SUMPRODUCT(((Ajuste!$B$5-Ajuste!$B$19:$B$29*1000/(G$4*Ajuste!$B$6*1000+$A16)-Ajuste!$C$19:$C$29)/Ajuste!$B$10)^2)/11) -> 6.273077 | H16: =SQRT(SUMPRODUCT(((Ajuste!$B$5-Ajuste!$B$19:$B$29*1000/(H$4*Ajuste!$B$6*1000+$A16)-Ajuste!$C$19:$C$29)/Ajuste!$B$10)^2)/11) -> 7.9662186 | I16: =SQRT(SUMPRODUCT(((Ajuste!$B$5-Ajuste!$B$19:$B$29*1000/(I$4*Ajuste!$B$6*1000+$A16)-Ajuste!$C$19:$C$29)/Ajuste!$B$10)^2)/11) -> 9.4766465 | ... P16: =SQRT(SUMPRODUCT(((Ajuste!$B$5-Ajuste!$B$19:$B$29*1000/(P$4*Ajuste!$B$6*1000+$A16)-Ajuste!$C$19:$C$29)/Ajuste!$B$10)^2)/11) -> 16.706669
... A21: 8 | B21: =SQRT(SUMPRODUCT(((Ajuste!$B$5-Ajuste!$B$19:$B$29*1000/(B$4*Ajuste!$B$6*1000+$A21)-Ajuste!$C$19:$C$29)/Ajuste!$B$10)^2)/11) -> 4.7013996 | C21: =SQRT(SUMPRODUCT(((Ajuste!$B$5-Ajuste!$B$19:$B$29*1000/(C$4*Ajuste!$B$6*1000+$A21)-Ajuste!$C$19:$C$29)/Ajuste!$B$10)^2)/11) -> 6.5692079 | D21: =SQRT(SUMPRODUCT(((Ajuste!$B$5-Ajuste!$B$19:$B$29*1000/(D$4*Ajuste!$B$6*1000+$A21)-Ajuste!$C$19:$C$29)/Ajuste!$B$10)^2)/11) -> 8.2298686 | E21: =SQRT(SUMPRODUCT(((Ajuste!$B$5-Ajuste!$B$19:$B$29*1000/(E$4*Ajuste!$B$6*1000+$A21)-Ajuste!$C$19:$C$29)/Ajuste!$B$10)^2)/11) -> 9.712567 | F21: =SQRT(SUMPRODUCT(((Ajuste!$B$5-Ajuste!$B$19:$B$29*1000/(F$4*Ajuste!$B$6*1000+$A21)-Ajuste!$C$19:$C$29)/Ajuste!$B$10)^2)/11) -> 11.043408 | G21: =SQRT(SUMPRODUCT(((Ajuste!$B$5-Ajuste!$B$19:$B$29*1000/(G$4*Ajuste!$B$6*1000+$A21)-Ajuste!$C$19:$C$29)/Ajuste!$B$10)^2)/11) -> 12.244177 | H21: =SQRT(SUMPRODUCT(((Ajuste!$B$5-Ajuste!$B$19:$B$29*1000/(H$4*Ajuste!$B$6*1000+$A21)-Ajuste!$C$19:$C$29)/Ajuste!$B$10)^2)/11) -> 13.332869 | I21: =SQRT(SUMPRODUCT(((Ajuste!$B$5-Ajuste!$B$19:$B$29*1000/(I$4*Ajuste!$B$6*1000+$A21)-Ajuste!$C$19:$C$29)/Ajuste!$B$10)^2)/11) -> 14.324383 | ... P21: =SQRT(SUMPRODUCT(((Ajuste!$B$5-Ajuste!$B$19:$B$29*1000/(P$4*Ajuste!$B$6*1000+$A21)-Ajuste!$C$19:$C$29)/Ajuste!$B$10)^2)/11) -> 19.375041

Sheet Dispersion
A1: Dispersión numérica: esquema upwind de Buckley y Leverett
A2: Malla de 20 celdas. Cambiá M, el Courant y los volúmenes porales inyectados y mirá el perfil final contra el frente analítico.
A4: Parámetro | B4: Valor | D4: S | E4: f′(S) | F4: f(S)/S | G4: f(S)
A5: Razón de movilidad M | B5: 2 | L5: Evolución (cada fila es un paso; la fila 7 es el estado final elegido)
A6: 0.01 | B6: 0.8 | D6: =A6 -> 0.01 | E6: =(G6-0)/(A6-0) -> 0.020401918 | F6: =G6/A6 -> 0.020401918 | G6: =A6^2/(A6^2+(1-A6)^2/$B$5) -> 0.00020401918 | L6: Paso | M6: 1 | N6: 2 | O6: 3 | P6: 4 | Q6: 5 | R6: 6 | S6: 7 | T6: 8 | U6: 9 | V6: 10 | W6: 11 | X6: 12 | Y6: 13 | Z6: 14 | AA6: 15 | AB6: 16 | AC6: 17 | AD6: 18 | AE6: 19 | AF6: 20
A7: 0.02 | B7: 0.4 | D7: =A7 -> 0.02 | E7: =(G7-G6)/(A7-A6) -> 0.062827379 | F7: =G7/A7 -> 0.041614648 | G7: =A7^2/(A7^2+(1-A7)^2/$B$5) -> 0.00083229297 | L7: Final | M7: =INDEX(M10:M259,MIN($B$12,250)+1) -> 0.88216627 | N7: =INDEX(N10:N259,MIN($B$12,250)+1) -> 0.82879331 | O7: =INDEX(O10:O259,MIN($B$12,250)+1) -> 0.78715094 | P7: =INDEX(P10:P259,MIN($B$12,250)+1) -> 0.75188669 | Q7: =INDEX(Q10:Q259,MIN($B$12,250)+1) -> 0.72062189 | R7: =INDEX(R10:R259,MIN($B$12,250)+1) -> 0.69192396 | S7: =INDEX(S10:S259,MIN($B$12,250)+1) -> 0.6647061 | T7: =INDEX(T10:T259,MIN($B$12,250)+1) -> 0.6378864 | ... AF7: =INDEX(AF10:AF259,MIN($B$12,250)+1) -> 0
A8: 0.03 | B8: 20 | D8: =A8 -> 0.03 | E8: =(G8-G7)/(A8-A7) -> 0.10771162 | F8: =G8/A8 -> 0.063646971 | G8: =A8^2/(A8^2+(1-A8)^2/$B$5) -> 0.0019094091
A9: 0.04 | B9: =1/B8 -> 0.05 | D9: =A9 -> 0.04 | E9: =(G9-G8)/(A9-A8) -> 0.15507985 | F9: =G9/A9 -> 0.08650519 | G9: =A9^2/(A9^2+(1-A9)^2/$B$5) -> 0.0034602076 | L9: n | M9: celda 1 | N9: celda 2 | O9: celda 3 | P9: celda 4 | Q9: celda 5 | R9: celda 6 | S9: celda 7 | T9: celda 8 | U9: celda 9 | V9: celda 10 | W9: celda 11 | X9: celda 12 | Y9: celda 13 | Z9: celda 14 | AA9: celda 15 | AB9: celda 16 | AC9: celda 17 | AD9: celda 18 | AE9: celda 19 | AF9: celda 20
A10: 0.05 | B10: =MAX(E6:E105) -> 2.0804544 | D10: =A10 -> 0.05 | E10: =(G10-G9)/(A10-A9) -> 0.20494343 | F10: =G10/A10 -> 0.11019284 | G10: =A10^2/(A10^2+(1-A10)^2/$B$5) -> 0.0055096419 | L10: 0 | M10: 0 | N10: 0 | O10: 0 | P10: 0 | Q10: 0 | R10: 0 | S10: 0 | T10: 0 | U10: 0 | V10: 0 | W10: 0 | X10: 0 | Y10: 0 | Z10: 0 | AA10: 0 | AB10: 0 | AC10: 0 | AD10: 0 | AE10: 0 | AF10: 0
A11: 0.06 | B11: =B6*B9/B10 -> 0.019226569 | D11: =A11 -> 0.06 | E11: =(G11-G10)/(A11-A10) -> 0.25729805 | F11: =G11/A11 -> 0.13471037 | G11: =A11^2/(A11^2+(1-A11)^2/$B$5) -> 0.0080826224 | L11: 1 | M11: =IF(ABS(M10-$B$11/$B$9*((MAX(0,MIN(1,M10))^2/(MAX(0,MIN(1,M10))^2+(1-MAX(0,MIN(1,M10)))^2/$B$5))-(MAX(0,MIN(1,1))^2/(MAX(0,MIN(1,1))^2+(1-MAX(0,MIN(1,1)))^2/$B$5))))<0.000000001,0,M10-$B$11/$B$9*((MAX(0,MIN(1,M10))^2/(MAX(0,MIN(1,M10))^2+(1-MAX(0,MIN(1,M10)))^2/$B$5))-(MAX(0,MIN(1,1))^2/(MAX(0,MIN(1,1))^2+(1-MAX(0,MIN(1,1)))^2/$B$5)))) -> 0.38453139 | N11: =IF(ABS(N10-$B$11/$B$9*((MAX(0,MIN(1,N10))^2/(MAX(0,MIN(1,N10))^2+(1-MAX(0,MIN(1,N10)))^2/$B$5))-(MAX(0,MIN(1,M10))^2/(MAX(0,MIN(1,M10))^2+(1-MAX(0,MIN(1,M10)))^2/$B$5))))<0.000000001,0,N10-$B$11/$B$9*((MAX(0,MIN(1,N10))^2/(MAX(0,MIN(1,N10))^2+(1-MAX(0,MIN(1,N10)))^2/$B$5))-(MAX(0,MIN(1,M10))^2/(MAX(0,MIN(1,M10))^2+(1-MAX(0,MIN(1,M10)))^2/$B$5)))) -> 0 | O11: =IF(ABS(O10-$B$11/$B$9*((MAX(0,MIN(1,O10))^2/(MAX(0,MIN(1,O10))^2+(1-MAX(0,MIN(1,O10)))^2/$B$5))-(MAX(0,MIN(1,N10))^2/(MAX(0,MIN(1,N10))^2+(1-MAX(0,MIN(1,N10)))^2/$B$5))))<0.000000001,0,O10-$B$11/$B$9*((MAX(0,MIN(1,O10))^2/(MAX(0,MIN(1,O10))^2+(1-MAX(0,MIN(1,O10)))^2/$B$5))-(MAX(0,MIN(1,N10))^2/(MAX(0,MIN(1,N10))^2+(1-MAX(0,MIN(1,N10)))^2/$B$5)))) -> 0 | P11: =IF(ABS(P10-$B$11/$B$9*((MAX(0,MIN(1,P10))^2/(MAX(0,MIN(1,P10))^2+(1-MAX(0,MIN(1,P10)))^2/$B$5))-(MAX(0,MIN(1,O10))^2/(MAX(0,MIN(1,O10))^2+(1-MAX(0,MIN(1,O10)))^2/$B$5))))<0.000000001,0,P10-$B$11/$B$9*((MAX(0,MIN(1,P10))^2/(MAX(0,MIN(1,P10))^2+(1-MAX(0,MIN(1,P10)))^2/$B$5))-(MAX(0,MIN(1,O10))^2/(MAX(0,MIN(1,O10))^2+(1-MAX(0,MIN(1,O10)))^2/$B$5)))) -> 0 | Q11: =IF(ABS(Q10-$B$11/$B$9*((MAX(0,MIN(1,Q10))^2/(MAX(0,MIN(1,Q10))^2+(1-MAX(0,MIN(1,Q10)))^2/$B$5))-(MAX(0,MIN(1,P10))^2/(MAX(0,MIN(1,P10))^2+(1-MAX(0,MIN(1,P10)))^2/$B$5))))<0.000000001,0,Q10-$B$11/$B$9*((MAX(0,MIN(1,Q10))^2/(MAX(0,MIN(1,Q10))^2+(1-MAX(0,MIN(1,Q10)))^2/$B$5))-(MAX(0,MIN(1,P10))^2/(MAX(0,MIN(1,P10))^2+(1-MAX(0,MIN(1,P10)))^2/$B$5)))) -> 0 | R11: =IF(ABS(R10-$B$11/$B$9*((MAX(0,MIN(1,R10))^2/(MAX(0,MIN(1,R10))^2+(1-MAX(0,MIN(1,R10)))^2/$B$5))-(MAX(0,MIN(1,Q10))^2/(MAX(0,MIN(1,Q10))^2+(1-MAX(0,MIN(1,Q10)))^2/$B$5))))<0.000000001,0,R10-$B$11/$B$9*((MAX(0,MIN(1,R10))^2/(MAX(0,MIN(1,R10))^2+(1-MAX(0,MIN(1,R10)))^2/$B$5))-(MAX(0,MIN(1,Q10))^2/(MAX(0,MIN(1,Q10))^2+(1-MAX(0,MIN(1,Q10)))^2/$B$5)))) -> 0 | S11: =IF(ABS(S10-$B$11/$B$9*((MAX(0,MIN(1,S10))^2/(MAX(0,MIN(1,S10))^2+(1-MAX(0,MIN(1,S10)))^2/$B$5))-(MAX(0,MIN(1,R10))^2/(MAX(0,MIN(1,R10))^2+(1-MAX(0,MIN(1,R10)))^2/$B$5))))<0.000000001,0,S10-$B$11/$B$9*((MAX(0,MIN(1,S10))^2/(MAX(0,MIN(1,S10))^2+(1-MAX(0,MIN(1,S10)))^2/$B$5))-(MAX(0,MIN(1,R10))^2/(MAX(0,MIN(1,R10))^2+(1-MAX(0,MIN(1,R10)))^2/$B$5)))) -> 0 | T11: =IF(ABS(T10-$B$11/$B$9*((MAX(0,MIN(1,T10))^2/(MAX(0,MIN(1,T10))^2+(1-MAX(0,MIN(1,T10)))^2/$B$5))-(MAX(0,MIN(1,S10))^2/(MAX(0,MIN(1,S10))^2+(1-MAX(0,MIN(1,S10)))^2/$B$5))))<0.000000001,0,T10-$B$11/$B$9*((MAX(0,MIN(1,T10))^2/(MAX(0,MIN(1,T10))^2+(1-MAX(0,MIN(1,T10)))^2/$B$5))-(MAX(0,MIN(1,S10))^2/(MAX(0,MIN(1,S10))^2+(1-MAX(0,MIN(1,S10)))^2/$B$5)))) -> 0 | U11: =IF(ABS(U10-$B$11/$B$9*((MAX(0,MIN(1,U10))^2/(MAX(0,MIN(1,U10))^2+(1-MAX(0,MIN(1,U10)))^2/$B$5))-(MAX(0,MIN(1,T10))^2/(MAX(0,MIN(1,T10))^2+(1-MAX(0,MIN(1,T10)))^2/$B$5))))<0.000000001,0,U10-$B$11/$B$9*((MAX(0,MIN(1,U10))^2/(MAX(0,MIN(1,U10))^2+(1-MAX(0,MIN(1,U10)))^2/$B$5))-(MAX(0,MIN(1,T10))^2/(MAX(0,MIN(1,T10))^2+(1-MAX(0,MIN(1,T10)))^2/$B$5)))) -> 0 | ... AF11: =IF(ABS(AF10-$B$11/$B$9*((MAX(0,MIN(1,AF10))^2/(MAX(0,MIN(1,AF10))^2+(1-MAX(0,MIN(1,AF10)))^2/$B$5))-(MAX(0,MIN(1,AE10))^2/(MAX(0,MIN(1,AE10))^2+(1-MAX(0,MIN(1,AE10)))^2/$B$5))))<0.000000001,0,AF10-$B$11/$B$9*((MAX(0,MIN(1,AF10))^2/(MAX(0,MIN(1,AF10))^2+(1-MAX(0,MIN(1,AF10)))^2/$B$5))-(MAX(0,MIN(1,AE10))^2/(MAX(0,MIN(1,AE10))^2+(1-MAX(0,MIN(1,AE10)))^2/$B$5)))) -> 0
A12: 0.07 | B12: =ROUND(B7/B11,0) -> 21 | D12: =A12 -> 0.07 | E12: =(G12-G11)/(A12-A11) -> 0.3121219 | F12: =G12/A12 -> 0.16005488 | G12: =A12^2/(A12^2+(1-A12)^2/$B$5) -> 0.011203841 | L12: 2 | M12: =IF(ABS(M11-$B$11/$B$9*((MAX(0,MIN(1,M11))^2/(MAX(0,MIN(1,M11))^2+(1-MAX(0,MIN(1,M11)))^2/$B$5))-(MAX(0,MIN(1,1))^2/(MAX(0,MIN(1,1))^2+(1-MAX(0,MIN(1,1)))^2/$B$5))))<0.000000001,0,M11-$B$11/$B$9*((MAX(0,MIN(1,M11))^2/(MAX(0,MIN(1,M11))^2+(1-MAX(0,MIN(1,M11)))^2/$B$5))-(MAX(0,MIN(1,1))^2/(MAX(0,MIN(1,1))^2+(1-MAX(0,MIN(1,1)))^2/$B$5)))) -> 0.60047586 | N12: =IF(ABS(N11-$B$11/$B$9*((MAX(0,MIN(1,N11))^2/(MAX(0,MIN(1,N11))^2+(1-MAX(0,MIN(1,N11)))^2/$B$5))-(MAX(0,MIN(1,M11))^2/(MAX(0,MIN(1,M11))^2+(1-MAX(0,MIN(1,M11)))^2/$B$5))))<0.000000001,0,N11-$B$11/$B$9*((MAX(0,MIN(1,N11))^2/(MAX(0,MIN(1,N11))^2+(1-MAX(0,MIN(1,N11)))^2/$B$5))-(MAX(0,MIN(1,M11))^2/(MAX(0,MIN(1,M11))^2+(1-MAX(0,MIN(1,M11)))^2/$B$5)))) -> 0.16858691 | O12: =IF(ABS(O11-$B$11/$B$9*((MAX(0,MIN(1,O11))^2/(MAX(0,MIN(1,O11))^2+(1-MAX(0,MIN(1,O11)))^2/$B$5))-(MAX(0,MIN(1,N11))^2/(MAX(0,MIN(1,N11))^2+(1-MAX(0,MIN(1,N11)))^2/$B$5))))<0.000000001,0,O11-$B$11/$B$9*((MAX(0,MIN(1,O11))^2/(MAX(0,MIN(1,O11))^2+(1-MAX(0,MIN(1,O11)))^2/$B$5))-(MAX(0,MIN(1,N11))^2/(MAX(0,MIN(1,N11))^2+(1-MAX(0,MIN(1,N11)))^2/$B$5)))) -> 0 | P12: =IF(ABS(P11-$B$11/$B$9*((MAX(0,MIN(1,P11))^2/(MAX(0,MIN(1,P11))^2+(1-MAX(0,MIN(1,P11)))^2/$B$5))-(MAX(0,MIN(1,O11))^2/(MAX(0,MIN(1,O11))^2+(1-MAX(0,MIN(1,O11)))^2/$B$5))))<0.000000001,0,P11-$B$11/$B$9*((MAX(0,MIN(1,P11))^2/(MAX(0,MIN(1,P11))^2+(1-MAX(0,MIN(1,P11)))^2/$B$5))-(MAX(0,MIN(1,O11))^2/(MAX(0,MIN(1,O11))^2+(1-MAX(0,MIN(1,O11)))^2/$B$5)))) -> 0 | Q12: =IF(ABS(Q11-$B$11/$B$9*((MAX(0,MIN(1,Q11))^2/(MAX(0,MIN(1,Q11))^2+(1-MAX(0,MIN(1,Q11)))^2/$B$5))-(MAX(0,MIN(1,P11))^2/(MAX(0,MIN(1,P11))^2+(1-MAX(0,MIN(1,P11)))^2/$B$5))))<0.000000001,0,Q11-$B$11/$B$9*((MAX(0,MIN(1,Q11))^2/(MAX(0,MIN(1,Q11))^2+(1-MAX(0,MIN(1,Q11)))^2/$B$5))-(MAX(0,MIN(1,P11))^2/(MAX(0,MIN(1,P11))^2+(1-MAX(0,MIN(1,P11)))^2/$B$5)))) -> 0 | R12: =IF(ABS(R11-$B$11/$B$9*((MAX(0,MIN(1,R11))^2/(MAX(0,MIN(1,R11))^2+(1-MAX(0,MIN(1,R11)))^2/$B$5))-(MAX(0,MIN(1,Q11))^2/(MAX(0,MIN(1,Q11))^2+(1-MAX(0,MIN(1,Q11)))^2/$B$5))))<0.000000001,0,R11-$B$11/$B$9*((MAX(0,MIN(1,R11))^2/(MAX(0,MIN(1,R11))^2+(1-MAX(0,MIN(1,R11)))^2/$B$5))-(MAX(0,MIN(1,Q11))^2/(MAX(0,MIN(1,Q11))^2+(1-MAX(0,MIN(1,Q11)))^2/$B$5)))) -> 0 | S12: =IF(ABS(S11-$B$11/$B$9*((MAX(0,MIN(1,S11))^2/(MAX(0,MIN(1,S11))^2+(1-MAX(0,MIN(1,S11)))^2/$B$5))-(MAX(0,MIN(1,R11))^2/(MAX(0,MIN(1,R11))^2+(1-MAX(0,MIN(1,R11)))^2/$B$5))))<0.000000001,0,S11-$B$11/$B$9*((MAX(0,MIN(1,S11))^2/(MAX(0,MIN(1,S11))^2+(1-MAX(0,MIN(1,S11)))^2/$B$5))-(MAX(0,MIN(1,R11))^2/(MAX(0,MIN(1,R11))^2+(1-MAX(0,MIN(1,R11)))^2/$B$5)))) -> 0 | T12: =IF(ABS(T11-$B$11/$B$9*((MAX(0,MIN(1,T11))^2/(MAX(0,MIN(1,T11))^2+(1-MAX(0,MIN(1,T11)))^2/$B$5))-(MAX(0,MIN(1,S11))^2/(MAX(0,MIN(1,S11))^2+(1-MAX(0,MIN(1,S11)))^2/$B$5))))<0.000000001,0,T11-$B$11/$B$9*((MAX(0,MIN(1,T11))^2/(MAX(0,MIN(1,T11))^2+(1-MAX(0,MIN(1,T11)))^2/$B$5))-(MAX(0,MIN(1,S11))^2/(MAX(0,MIN(1,S11))^2+(1-MAX(0,MIN(1,S11)))^2/$B$5)))) -> 0 | U12: =IF(ABS(U11-$B$11/$B$9*((MAX(0,MIN(1,U11))^2/(MAX(0,MIN(1,U11))^2+(1-MAX(0,MIN(1,U11)))^2/$B$5))-(MAX(0,MIN(1,T11))^2/(MAX(0,MIN(1,T11))^2+(1-MAX(0,MIN(1,T11)))^2/$B$5))))<0.000000001,0,U11-$B$11/$B$9*((MAX(0,MIN(1,U11))^2/(MAX(0,MIN(1,U11))^2+(1-MAX(0,MIN(1,U11)))^2/$B$5))-(MAX(0,MIN(1,T11))^2/(MAX(0,MIN(1,T11))^2+(1-MAX(0,MIN(1,T11)))^2/$B$5)))) -> 0 | ... AF12: =IF(ABS(AF11-$B$11/$B$9*((MAX(0,MIN(1,AF11))^2/(MAX(0,MIN(1,AF11))^2+(1-MAX(0,MIN(1,AF11)))^2/$B$5))-(MAX(0,MIN(1,AE11))^2/(MAX(0,MIN(1,AE11))^2+(1-MAX(0,MIN(1,AE11)))^2/$B$5))))<0.000000001,0,AF11-$B$11/$B$9*((MAX(0,MIN(1,AF11))^2/(MAX(0,MIN(1,AF11))^2+(1-MAX(0,MIN(1,AF11)))^2/$B$5))-(MAX(0,MIN(1,AE11))^2/(MAX(0,MIN(1,AE11))^2+(1-MAX(0,MIN(1,AE11)))^2/$B$5)))) -> 0
A13: 0.08 | B13: =INDEX(A6:A105,MATCH(MAX(F6:F105),F6:F105,0)) -> 0.58 | D13: =A13 -> 0.08 | E13: =(G13-G12)/(A13-A12) -> 0.36937378 | F13: =G13/A13 -> 0.18621974 | G13: =A13^2/(A13^2+(1-A13)^2/$B$5) -> 0.014897579 | L13: 3 | M13: =IF(ABS(M12-$B$11/$B$9*((MAX(0,MIN(1,M12))^2/(MAX(0,MIN(1,M12))^2+(1-MAX(0,MIN(1,M12)))^2/$B$5))-(MAX(0,MIN(1,1))^2/(MAX(0,MIN(1,1))^2+(1-MAX(0,MIN(1,1)))^2/$B$5))))<0.000000001,0,M12-$B$11/$B$9*((MAX(0,MIN(1,M12))^2/(MAX(0,MIN(1,M12))^2+(1-MAX(0,MIN(1,M12)))^2/$B$5))-(MAX(0,MIN(1,1))^2/(MAX(0,MIN(1,1))^2+(1-MAX(0,MIN(1,1)))^2/$B$5)))) -> 0.67016406 | N13: =IF(ABS(N12-$B$11/$B$9*((MAX(0,MIN(1,N12))^2/(MAX(0,MIN(1,N12))^2+(1-MAX(0,MIN(1,N12)))^2/$B$5))-(MAX(0,MIN(1,M12))^2/(MAX(0,MIN(1,M12))^2+(1-MAX(0,MIN(1,M12)))^2/$B$5))))<0.000000001,0,N12-$B$11/$B$9*((MAX(0,MIN(1,N12))^2/(MAX(0,MIN(1,N12))^2+(1-MAX(0,MIN(1,N12)))^2/$B$5))-(MAX(0,MIN(1,M12))^2/(MAX(0,MIN(1,M12))^2+(1-MAX(0,MIN(1,M12)))^2/$B$5)))) -> 0.45421178 | O13: =IF(ABS(O12-$B$11/$B$9*((MAX(0,MIN(1,O12))^2/(MAX(0,MIN(1,O12))^2+(1-MAX(0,MIN(1,O12)))^2/$B$5))-(MAX(0,MIN(1,N12))^2/(MAX(0,MIN(1,N12))^2+(1-MAX(0,MIN(1,N12)))^2/$B$5))))<0.000000001,0,O12-$B$11/$B$9*((MAX(0,MIN(1,O12))^2/(MAX(0,MIN(1,O12))^2+(1-MAX(0,MIN(1,O12)))^2/$B$5))-(MAX(0,MIN(1,N12))^2/(MAX(0,MIN(1,N12))^2+(1-MAX(0,MIN(1,N12)))^2/$B$5)))) -> 0.029218315 | P13: =IF(ABS(P12-$B$11/$B$9*((MAX(0,MIN(1,P12))^2/(MAX(0,MIN(1,P12))^2+(1-MAX(0,MIN(1,P12)))^2/$B$5))-(MAX(0,MIN(1,O12))^2/(MAX(0,MIN(1,O12))^2+(1-MAX(0,MIN(1,O12)))^2/$B$5))))<0.000000001,0,P12-$B$11/$B$9*((MAX(0,MIN(1,P12))^2/(MAX(0,MIN(1,P12))^2+(1-MAX(0,MIN(1,P12)))^2/$B$5))-(MAX(0,MIN(1,O12))^2/(MAX(0,MIN(1,O12))^2+(1-MAX(0,MIN(1,O12)))^2/$B$5)))) -> 0 | Q13: =IF(ABS(Q12-$B$11/$B$9*((MAX(0,MIN(1,Q12))^2/(MAX(0,MIN(1,Q12))^2+(1-MAX(0,MIN(1,Q12)))^2/$B$5))-(MAX(0,MIN(1,P12))^2/(MAX(0,MIN(1,P12))^2+(1-MAX(0,MIN(1,P12)))^2/$B$5))))<0.000000001,0,Q12-$B$11/$B$9*((MAX(0,MIN(1,Q12))^2/(MAX(0,MIN(1,Q12))^2+(1-MAX(0,MIN(1,Q12)))^2/$B$5))-(MAX(0,MIN(1,P12))^2/(MAX(0,MIN(1,P12))^2+(1-MAX(0,MIN(1,P12)))^2/$B$5)))) -> 0 | R13: =IF(ABS(R12-$B$11/$B$9*((MAX(0,MIN(1,R12))^2/(MAX(0,MIN(1,R12))^2+(1-MAX(0,MIN(1,R12)))^2/$B$5))-(MAX(0,MIN(1,Q12))^2/(MAX(0,MIN(1,Q12))^2+(1-MAX(0,MIN(1,Q12)))^2/$B$5))))<0.000000001,0,R12-$B$11/$B$9*((MAX(0,MIN(1,R12))^2/(MAX(0,MIN(1,R12))^2+(1-MAX(0,MIN(1,R12)))^2/$B$5))-(MAX(0,MIN(1,Q12))^2/(MAX(0,MIN(1,Q12))^2+(1-MAX(0,MIN(1,Q12)))^2/$B$5)))) -> 0 | S13: =IF(ABS(S12-$B$11/$B$9*((MAX(0,MIN(1,S12))^2/(MAX(0,MIN(1,S12))^2+(1-MAX(0,MIN(1,S12)))^2/$B$5))-(MAX(0,MIN(1,R12))^2/(MAX(0,MIN(1,R12))^2+(1-MAX(0,MIN(1,R12)))^2/$B$5))))<0.000000001,0,S12-$B$11/$B$9*((MAX(0,MIN(1,S12))^2/(MAX(0,MIN(1,S12))^2+(1-MAX(0,MIN(1,S12)))^2/$B$5))-(MAX(0,MIN(1,R12))^2/(MAX(0,MIN(1,R12))^2+(1-MAX(0,MIN(1,R12)))^2/$B$5)))) -> 0 | T13: =IF(ABS(T12-$B$11/$B$9*((MAX(0,MIN(1,T12))^2/(MAX(0,MIN(1,T12))^2+(1-MAX(0,MIN(1,T12)))^2/$B$5))-(MAX(0,MIN(1,S12))^2/(MAX(0,MIN(1,S12))^2+(1-MAX(0,MIN(1,S12)))^2/$B$5))))<0.000000001,0,T12-$B$11/$B$9*((MAX(0,MIN(1,T12))^2/(MAX(0,MIN(1,T12))^2+(1-MAX(0,MIN(1,T12)))^2/$B$5))-(MAX(0,MIN(1,S12))^2/(MAX(0,MIN(1,S12))^2+(1-MAX(0,MIN(1,S12)))^2/$B$5)))) -> 0 | U13: =IF(ABS(U12-$B$11/$B$9*((MAX(0,MIN(1,U12))^2/(MAX(0,MIN(1,U12))^2+(1-MAX(0,MIN(1,U12)))^2/$B$5))-(MAX(0,MIN(1,T12))^2/(MAX(0,MIN(1,T12))^2+(1-MAX(0,MIN(1,T12)))^2/$B$5))))<0.000000001,0,U12-$B$11/$B$9*((MAX(0,MIN(1,U12))^2/(MAX(0,MIN(1,U12))^2+(1-MAX(0,MIN(1,U12)))^2/$B$5))-(MAX(0,MIN(1,T12))^2/(MAX(0,MIN(1,T12))^2+(1-MAX(0,MIN(1,T12)))^2/$B$5)))) -> 0 | ... AF13: =IF(ABS(AF12-$B$11/$B$9*((MAX(0,MIN(1,AF12))^2/(MAX(0,MIN(1,AF12))^2+(1-MAX(0,MIN(1,AF12)))^2/$B$5))-(MAX(0,MIN(1,AE12))^2/(MAX(0,MIN(1,AE12))^2+(1-MAX(0,MIN(1,AE12)))^2/$B$5))))<0.000000001,0,AF12-$B$11/$B$9*((MAX(0,MIN(1,AF12))^2/(MAX(0,MIN(1,AF12))^2+(1-MAX(0,MIN(1,AF12)))^2/$B$5))-(MAX(0,MIN(1,AE12))^2/(MAX(0,MIN(1,AE12))^2+(1-MAX(0,MIN(1,AE12)))^2/$B$5)))) -> 0
A14: 0.09 | B14: =MIN(1,B7*MAX(F6:F105)) -> 0.54639661 | D14: =A14 -> 0.09 | E14: =(G14-G13)/(A14-A13) -> 0.42899135 | F14: =G14/A14 -> 0.21319436 | G14: =A14^2/(A14^2+(1-A14)^2/$B$5) -> 0.019187493 | L14: 4 | M14: =IF(ABS(M13-$B$11/$B$9*((MAX(0,MIN(1,M13))^2/(MAX(0,MIN(1,M13))^2+(1-MAX(0,MIN(1,M13)))^2/$B$5))-(MAX(0,MIN(1,1))^2/(MAX(0,MIN(1,1))^2+(1-MAX(0,MIN(1,1)))^2/$B$5))))<0.000000001,0,M13-$B$11/$B$9*((MAX(0,MIN(1,M13))^2/(MAX(0,MIN(1,M13))^2+(1-MAX(0,MIN(1,M13)))^2/$B$5))-(MAX(0,MIN(1,1))^2/(MAX(0,MIN(1,1))^2+(1-MAX(0,MIN(1,1)))^2/$B$5)))) -> 0.7117058 | N14: =IF(ABS(N13-$B$11/$B$9*((MAX(0,MIN(1,N13))^2/(MAX(0,MIN(1,N13))^2+(1-MAX(0,MIN(1,N13)))^2/$B$5))-(MAX(0,MIN(1,M13))^2/(MAX(0,MIN(1,M13))^2+(1-MAX(0,MIN(1,M13)))^2/$B$5))))<0.000000001,0,N13-$B$11/$B$9*((MAX(0,MIN(1,N13))^2/(MAX(0,MIN(1,N13))^2+(1-MAX(0,MIN(1,N13)))^2/$B$5))-(MAX(0,MIN(1,M13))^2/(MAX(0,MIN(1,M13))^2+(1-MAX(0,MIN(1,M13)))^2/$B$5)))) -> 0.57388863 | O14: =IF(ABS(O13-$B$11/$B$9*((MAX(0,MIN(1,O13))^2/(MAX(0,MIN(1,O13))^2+(1-MAX(0,MIN(1,O13)))^2/$B$5))-(MAX(0,MIN(1,N13))^2/(MAX(0,MIN(1,N13))^2+(1-MAX(0,MIN(1,N13)))^2/$B$5))))<0.000000001,0,O13-$B$11/$B$9*((MAX(0,MIN(1,O13))^2/(MAX(0,MIN(1,O13))^2+(1-MAX(0,MIN(1,O13)))^2/$B$5))-(MAX(0,MIN(1,N13))^2/(MAX(0,MIN(1,N13))^2+(1-MAX(0,MIN(1,N13)))^2/$B$5)))) -> 0.25183569 | P14: =IF(ABS(P13-$B$11/$B$9*((MAX(0,MIN(1,P13))^2/(MAX(0,MIN(1,P13))^2+(1-MAX(0,MIN(1,P13)))^2/$B$5))-(MAX(0,MIN(1,O13))^2/(MAX(0,MIN(1,O13))^2+(1-MAX(0,MIN(1,O13)))^2/$B$5))))<0.000000001,0,P13-$B$11/$B$9*((MAX(0,MIN(1,P13))^2/(MAX(0,MIN(1,P13))^2+(1-MAX(0,MIN(1,P13)))^2/$B$5))-(MAX(0,MIN(1,O13))^2/(MAX(0,MIN(1,O13))^2+(1-MAX(0,MIN(1,O13)))^2/$B$5)))) -> 0.00069541309 | Q14: =IF(ABS(Q13-$B$11/$B$9*((MAX(0,MIN(1,Q13))^2/(MAX(0,MIN(1,Q13))^2+(1-MAX(0,MIN(1,Q13)))^2/$B$5))-(MAX(0,MIN(1,P13))^2/(MAX(0,MIN(1,P13))^2+(1-MAX(0,MIN(1,P13)))^2/$B$5))))<0.000000001,0,Q13-$B$11/$B$9*((MAX(0,MIN(1,Q13))^2/(MAX(0,MIN(1,Q13))^2+(1-MAX(0,MIN(1,Q13)))^2/$B$5))-(MAX(0,MIN(1,P13))^2/(MAX(0,MIN(1,P13))^2+(1-MAX(0,MIN(1,P13)))^2/$B$5)))) -> 0 | R14: =IF(ABS(R13-$B$11/$B$9*((MAX(0,MIN(1,R13))^2/(MAX(0,MIN(1,R13))^2+(1-MAX(0,MIN(1,R13)))^2/$B$5))-(MAX(0,MIN(1,Q13))^2/(MAX(0,MIN(1,Q13))^2+(1-MAX(0,MIN(1,Q13)))^2/$B$5))))<0.000000001,0,R13-$B$11/$B$9*((MAX(0,MIN(1,R13))^2/(MAX(0,MIN(1,R13))^2+(1-MAX(0,MIN(1,R13)))^2/$B$5))-(MAX(0,MIN(1,Q13))^2/(MAX(0,MIN(1,Q13))^2+(1-MAX(0,MIN(1,Q13)))^2/$B$5)))) -> 0 | S14: =IF(ABS(S13-$B$11/$B$9*((MAX(0,MIN(1,S13))^2/(MAX(0,MIN(1,S13))^2+(1-MAX(0,MIN(1,S13)))^2/$B$5))-(MAX(0,MIN(1,R13))^2/(MAX(0,MIN(1,R13))^2+(1-MAX(0,MIN(1,R13)))^2/$B$5))))<0.000000001,0,S13-$B$11/$B$9*((MAX(0,MIN(1,S13))^2/(MAX(0,MIN(1,S13))^2+(1-MAX(0,MIN(1,S13)))^2/$B$5))-(MAX(0,MIN(1,R13))^2/(MAX(0,MIN(1,R13))^2+(1-MAX(0,MIN(1,R13)))^2/$B$5)))) -> 0 | T14: =IF(ABS(T13-$B$11/$B$9*((MAX(0,MIN(1,T13))^2/(MAX(0,MIN(1,T13))^2+(1-MAX(0,MIN(1,T13)))^2/$B$5))-(MAX(0,MIN(1,S13))^2/(MAX(0,MIN(1,S13))^2+(1-MAX(0,MIN(1,S13)))^2/$B$5))))<0.000000001,0,T13-$B$11/$B$9*((MAX(0,MIN(1,T13))^2/(MAX(0,MIN(1,T13))^2+(1-MAX(0,MIN(1,T13)))^2/$B$5))-(MAX(0,MIN(1,S13))^2/(MAX(0,MIN(1,S13))^2+(1-MAX(0,MIN(1,S13)))^2/$B$5)))) -> 0 | U14: =IF(ABS(U13-$B$11/$B$9*((MAX(0,MIN(1,U13))^2/(MAX(0,MIN(1,U13))^2+(1-MAX(0,MIN(1,U13)))^2/$B$5))-(MAX(0,MIN(1,T13))^2/(MAX(0,MIN(1,T13))^2+(1-MAX(0,MIN(1,T13)))^2/$B$5))))<0.000000001,0,U13-$B$11/$B$9*((MAX(0,MIN(1,U13))^2/(MAX(0,MIN(1,U13))^2+(1-MAX(0,MIN(1,U13)))^2/$B$5))-(MAX(0,MIN(1,T13))^2/(MAX(0,MIN(1,T13))^2+(1-MAX(0,MIN(1,T13)))^2/$B$5)))) -> 0 | ... AF14: =IF(ABS(AF13-$B$11/$B$9*((MAX(0,MIN(1,AF13))^2/(MAX(0,MIN(1,AF13))^2+(1-MAX(0,MIN(1,AF13)))^2/$B$5))-(MAX(0,MIN(1,AE13))^2/(MAX(0,MIN(1,AE13))^2+(1-MAX(0,MIN(1,AE13)))^2/$B$5))))<0.000000001,0,AF13-$B$11/$B$9*((MAX(0,MIN(1,AF13))^2/(MAX(0,MIN(1,AF13))^2+(1-MAX(0,MIN(1,AF13)))^2/$B$5))-(MAX(0,MIN(1,AE13))^2/(MAX(0,MIN(1,AE13))^2+(1-MAX(0,MIN(1,AE13)))^2/$B$5)))) -> 0
A15: 0.1 | B15: =COUNTIF(M7:AF7,">="&B13/2)*B9 -> 0.6 | D15: =A15 -> 0.1 | E15: =(G15-G14)/(A15-A14) -> 0.49088929 | F15: =G15/A15 -> 0.24096386 | G15: =A15^2/(A15^2+(1-A15)^2/$B$5) -> 0.024096386 | L15: 5 | M15: =IF(ABS(M14-$B$11/$B$9*((MAX(0,MIN(1,M14))^2/(MAX(0,MIN(1,M14))^2+(1-MAX(0,MIN(1,M14)))^2/$B$5))-(MAX(0,MIN(1,1))^2/(MAX(0,MIN(1,1))^2+(1-MAX(0,MIN(1,1)))^2/$B$5))))<0.000000001,0,M14-$B$11/$B$9*((MAX(0,MIN(1,M14))^2/(MAX(0,MIN(1,M14))^2+(1-MAX(0,MIN(1,M14)))^2/$B$5))-(MAX(0,MIN(1,1))^2/(MAX(0,MIN(1,1))^2+(1-MAX(0,MIN(1,1)))^2/$B$5)))) -> 0.74086181 | N15: =IF(ABS(N14-$B$11/$B$9*((MAX(0,MIN(1,N14))^2/(MAX(0,MIN(1,N14))^2+(1-MAX(0,MIN(1,N14)))^2/$B$5))-(MAX(0,MIN(1,M14))^2/(MAX(0,MIN(1,M14))^2+(1-MAX(0,MIN(1,M14)))^2/$B$5))))<0.000000001,0,N14-$B$11/$B$9*((MAX(0,MIN(1,N14))^2/(MAX(0,MIN(1,N14))^2+(1-MAX(0,MIN(1,N14)))^2/$B$5))-(MAX(0,MIN(1,M14))^2/(MAX(0,MIN(1,M14))^2+(1-MAX(0,MIN(1,M14)))^2/$B$5)))) -> 0.62782489 | O15: =IF(ABS(O14-$B$11/$B$9*((MAX(0,MIN(1,O14))^2/(MAX(0,MIN(1,O14))^2+(1-MAX(0,MIN(1,O14)))^2/$B$5))-(MAX(0,MIN(1,N14))^2/(MAX(0,MIN(1,N14))^2+(1-MAX(0,MIN(1,N14)))^2/$B$5))))<0.000000001,0,O14-$B$11/$B$9*((MAX(0,MIN(1,O14))^2/(MAX(0,MIN(1,O14))^2+(1-MAX(0,MIN(1,O14)))^2/$B$5))-(MAX(0,MIN(1,N14))^2/(MAX(0,MIN(1,N14))^2+(1-MAX(0,MIN(1,N14)))^2/$B$5)))) -> 0.48223571 | P15: =IF(ABS(P14-$B$11/$B$9*((MAX(0,MIN(1,P14))^2/(MAX(0,MIN(1,P14))^2+(1-MAX(0,MIN(1,P14)))^2/$B$5))-(MAX(0,MIN(1,O14))^2/(MAX(0,MIN(1,O14))^2+(1-MAX(0,MIN(1,O14)))^2/$B$5))))<0.000000001,0,P14-$B$11/$B$9*((MAX(0,MIN(1,P14))^2/(MAX(0,MIN(1,P14))^2+(1-MAX(0,MIN(1,P14)))^2/$B$5))-(MAX(0,MIN(1,O14))^2/(MAX(0,MIN(1,O14))^2+(1-MAX(0,MIN(1,O14)))^2/$B$5)))) -> 0.07173414 | Q15: =IF(ABS(Q14-$B$11/$B$9*((MAX(0,MIN(1,Q14))^2/(MAX(0,MIN(1,Q14))^2+(1-MAX(0,MIN(1,Q14)))^2/$B$5))-(MAX(0,MIN(1,P14))^2/(MAX(0,MIN(1,P14))^2+(1-MAX(0,MIN(1,P14)))^2/$B$5))))<0.000000001,0,Q14-$B$11/$B$9*((MAX(0,MIN(1,Q14))^2/(MAX(0,MIN(1,Q14))^2+(1-MAX(0,MIN(1,Q14)))^2/$B$5))-(MAX(0,MIN(1,P14))^2/(MAX(0,MIN(1,P14))^2+(1-MAX(0,MIN(1,P14)))^2/$B$5)))) -> 3.7243572e-07 | R15: =IF(ABS(R14-$B$11/$B$9*((MAX(0,MIN(1,R14))^2/(MAX(0,MIN(1,R14))^2+(1-MAX(0,MIN(1,R14)))^2/$B$5))-(MAX(0,MIN(1,Q14))^2/(MAX(0,MIN(1,Q14))^2+(1-MAX(0,MIN(1,Q14)))^2/$B$5))))<0.000000001,0,R14-$B$11/$B$9*((MAX(0,MIN(1,R14))^2/(MAX(0,MIN(1,R14))^2+(1-MAX(0,MIN(1,R14)))^2/$B$5))-(MAX(0,MIN(1,Q14))^2/(MAX(0,MIN(1,Q14))^2+(1-MAX(0,MIN(1,Q14)))^2/$B$5)))) -> 0 | S15: =IF(ABS(S14-$B$11/$B$9*((MAX(0,MIN(1,S14))^2/(MAX(0,MIN(1,S14))^2+(1-MAX(0,MIN(1,S14)))^2/$B$5))-(MAX(0,MIN(1,R14))^2/(MAX(0,MIN(1,R14))^2+(1-MAX(0,MIN(1,R14)))^2/$B$5))))<0.000000001,0,S14-$B$11/$B$9*((MAX(0,MIN(1,S14))^2/(MAX(0,MIN(1,S14))^2+(1-MAX(0,MIN(1,S14)))^2/$B$5))-(MAX(0,MIN(1,R14))^2/(MAX(0,MIN(1,R14))^2+(1-MAX(0,MIN(1,R14)))^2/$B$5)))) -> 0 | T15: =IF(ABS(T14-$B$11/$B$9*((MAX(0,MIN(1,T14))^2/(MAX(0,MIN(1,T14))^2+(1-MAX(0,MIN(1,T14)))^2/$B$5))-(MAX(0,MIN(1,S14))^2/(MAX(0,MIN(1,S14))^2+(1-MAX(0,MIN(1,S14)))^2/$B$5))))<0.000000001,0,T14-$B$11/$B$9*((MAX(0,MIN(1,T14))^2/(MAX(0,MIN(1,T14))^2+(1-MAX(0,MIN(1,T14)))^2/$B$5))-(MAX(0,MIN(1,S14))^2/(MAX(0,MIN(1,S14))^2+(1-MAX(0,MIN(1,S14)))^2/$B$5)))) -> 0 | U15: =IF(ABS(U14-$B$11/$B$9*((MAX(0,MIN(1,U14))^2/(MAX(0,MIN(1,U14))^2+(1-MAX(0,MIN(1,U14)))^2/$B$5))-(MAX(0,MIN(1,T14))^2/(MAX(0,MIN(1,T14))^2+(1-MAX(0,MIN(1,T14)))^2/$B$5))))<0.000000001,0,U14-$B$11/$B$9*((MAX(0,MIN(1,U14))^2/(MAX(0,MIN(1,U14))^2+(1-MAX(0,MIN(1,U14)))^2/$B$5))-(MAX(0,MIN(1,T14))^2/(MAX(0,MIN(1,T14))^2+(1-MAX(0,MIN(1,T14)))^2/$B$5)))) -> 0 | ... AF15: =IF(ABS(AF14-$B$11/$B$9*((MAX(0,MIN(1,AF14))^2/(MAX(0,MIN(1,AF14))^2+(1-MAX(0,MIN(1,AF14)))^2/$B$5))-(MAX(0,MIN(1,AE14))^2/(MAX(0,MIN(1,AE14))^2+(1-MAX(0,MIN(1,AE14)))^2/$B$5))))<0.000000001,0,AF14-$B$11/$B$9*((MAX(0,MIN(1,AF14))^2/(MAX(0,MIN(1,AF14))^2+(1-MAX(0,MIN(1,AF14)))^2/$B$5))-(MAX(0,MIN(1,AE14))^2/(MAX(0,MIN(1,AE14))^2+(1-MAX(0,MIN(1,AE14)))^2/$B$5)))) -> 0
A16: 0.11 | B16: =IF(B6>1,"Courant > 1: inestable","Estable") -> Estable | D16: =A16 -> 0.11 | E16: =(G16-G15)/(A16-A15) -> 0.5549578 | F16: =G16/A16 -> 0.26950876 | G16: =A16^2/(A16^2+(1-A16)^2/$B$5) -> 0.029645963 | L16: 6 | M16: =IF(ABS(M15-$B$11/$B$9*((MAX(0,MIN(1,M15))^2/(MAX(0,MIN(1,M15))^2+(1-MAX(0,MIN(1,M15)))^2/$B$5))-(MAX(0,MIN(1,1))^2/(MAX(0,MIN(1,1))^2+(1-MAX(0,MIN(1,1)))^2/$B$5))))<0.000000001,0,M15-$B$11/$B$9*((MAX(0,MIN(1,M15))^2/(MAX(0,MIN(1,M15))^2+(1-MAX(0,MIN(1,M15)))^2/$B$5))-(MAX(0,MIN(1,1))^2/(MAX(0,MIN(1,1))^2+(1-MAX(0,MIN(1,1)))^2/$B$5)))) -> 0.76302867 | N16: =IF(ABS(N15-$B$11/$B$9*((MAX(0,MIN(1,N15))^2/(MAX(0,MIN(1,N15))^2+(1-MAX(0,MIN(1,N15)))^2/$B$5))-(MAX(0,MIN(1,M15))^2/(MAX(0,MIN(1,M15))^2+(1-MAX(0,MIN(1,M15)))^2/$B$5))))<0.000000001,0,N15-$B$11/$B$9*((MAX(0,MIN(1,N15))^2/(MAX(0,MIN(1,N15))^2+(1-MAX(0,MIN(1,N15)))^2/$B$5))-(MAX(0,MIN(1,M15))^2/(MAX(0,MIN(1,M15))^2+(1-MAX(0,MIN(1,M15)))^2/$B$5)))) -> 0.66312529 | O16: =IF(ABS(O15-$B$11/$B$9*((MAX(0,MIN(1,O15))^2/(MAX(0,MIN(1,O15))^2+(1-MAX(0,MIN(1,O15)))^2/$B$5))-(MAX(0,MIN(1,N15))^2/(MAX(0,MIN(1,N15))^2+(1-MAX(0,MIN(1,N15)))^2/$B$5))))<0.000000001,0,O15-$B$11/$B$9*((MAX(0,MIN(1,O15))^2/(MAX(0,MIN(1,O15))^2+(1-MAX(0,MIN(1,O15)))^2/$B$5))-(MAX(0,MIN(1,N15))^2/(MAX(0,MIN(1,N15))^2+(1-MAX(0,MIN(1,N15)))^2/$B$5)))) -> 0.565368 | P16: =IF(ABS(P15-$B$11/$B$9*((MAX(0,MIN(1,P15))^2/(MAX(0,MIN(1,P15))^2+(1-MAX(0,MIN(1,P15)))^2/$B$5))-(MAX(0,MIN(1,O15))^2/(MAX(0,MIN(1,O15))^2+(1-MAX(0,MIN(1,O15)))^2/$B$5))))<0.000000001,0,P15-$B$11/$B$9*((MAX(0,MIN(1,P15))^2/(MAX(0,MIN(1,P15))^2+(1-MAX(0,MIN(1,P15)))^2/$B$5))-(MAX(0,MIN(1,O15))^2/(MAX(0,MIN(1,O15))^2+(1-MAX(0,MIN(1,O15)))^2/$B$5)))) -> 0.31112747 | Q16: =IF(ABS(Q15-$B$11/$B$9*((MAX(0,MIN(1,Q15))^2/(MAX(0,MIN(1,Q15))^2+(1-MAX(0,MIN(1,Q15)))^2/$B$5))-(MAX(0,MIN(1,P15))^2/(MAX(0,MIN(1,P15))^2+(1-MAX(0,MIN(1,P15)))^2/$B$5))))<0.000000001,0,Q15-$B$11/$B$9*((MAX(0,MIN(1,Q15))^2/(MAX(0,MIN(1,Q15))^2+(1-MAX(0,MIN(1,Q15)))^2/$B$5))-(MAX(0,MIN(1,P15))^2/(MAX(0,MIN(1,P15))^2+(1-MAX(0,MIN(1,P15)))^2/$B$5)))) -> 0.0045388741 | R16: =IF(ABS(R15-$B$11/$B$9*((MAX(0,MIN(1,R15))^2/(MAX(0,MIN(1,R15))^2+(1-MAX(0,MIN(1,R15)))^2/$B$5))-(MAX(0,MIN(1,Q15))^2/(MAX(0,MIN(1,Q15))^2+(1-MAX(0,MIN(1,Q15)))^2/$B$5))))<0.000000001,0,R15-$B$11/$B$9*((MAX(0,MIN(1,R15))^2/(MAX(0,MIN(1,R15))^2+(1-MAX(0,MIN(1,R15)))^2/$B$5))-(MAX(0,MIN(1,Q15))^2/(MAX(0,MIN(1,Q15))^2+(1-MAX(0,MIN(1,Q15)))^2/$B$5)))) -> 0 | S16: =IF(ABS(S15-$B$11/$B$9*((MAX(0,MIN(1,S15))^2/(MAX(0,MIN(1,S15))^2+(1-MAX(0,MIN(1,S15)))^2/$B$5))-(MAX(0,MIN(1,R15))^2/(MAX(0,MIN(1,R15))^2+(1-MAX(0,MIN(1,R15)))^2/$B$5))))<0.000000001,0,S15-$B$11/$B$9*((MAX(0,MIN(1,S15))^2/(MAX(0,MIN(1,S15))^2+(1-MAX(0,MIN(1,S15)))^2/$B$5))-(MAX(0,MIN(1,R15))^2/(MAX(0,MIN(1,R15))^2+(1-MAX(0,MIN(1,R15)))^2/$B$5)))) -> 0 | T16: =IF(ABS(T15-$B$11/$B$9*((MAX(0,MIN(1,T15))^2/(MAX(0,MIN(1,T15))^2+(1-MAX(0,MIN(1,T15)))^2/$B$5))-(MAX(0,MIN(1,S15))^2/(MAX(0,MIN(1,S15))^2+(1-MAX(0,MIN(1,S15)))^2/$B$5))))<0.000000001,0,T15-$B$11/$B$9*((MAX(0,MIN(1,T15))^2/(MAX(0,MIN(1,T15))^2+(1-MAX(0,MIN(1,T15)))^2/$B$5))-(MAX(0,MIN(1,S15))^2/(MAX(0,MIN(1,S15))^2+(1-MAX(0,MIN(1,S15)))^2/$B$5)))) -> 0 | U16: =IF(ABS(U15-$B$11/$B$9*((MAX(0,MIN(1,U15))^2/(MAX(0,MIN(1,U15))^2+(1-MAX(0,MIN(1,U15)))^2/$B$5))-(MAX(0,MIN(1,T15))^2/(MAX(0,MIN(1,T15))^2+(1-MAX(0,MIN(1,T15)))^2/$B$5))))<0.000000001,0,U15-$B$11/$B$9*((MAX(0,MIN(1,U15))^2/(MAX(0,MIN(1,U15))^2+(1-MAX(0,MIN(1,U15)))^2/$B$5))-(MAX(0,MIN(1,T15))^2/(MAX(0,MIN(1,T15))^2+(1-MAX(0,MIN(1,T15)))^2/$B$5)))) -> 0 | ... AF16: =IF(ABS(AF15-$B$11/$B$9*((MAX(0,MIN(1,AF15))^2/(MAX(0,MIN(1,AF15))^2+(1-MAX(0,MIN(1,AF15)))^2/$B$5))-(MAX(0,MIN(1,AE15))^2/(MAX(0,MIN(1,AE15))^2+(1-MAX(0,MIN(1,AE15)))^2/$B$5))))<0.000000001,0,AF15-$B$11/$B$9*((MAX(0,MIN(1,AF15))^2/(MAX(0,MIN(1,AF15))^2+(1-MAX(0,MIN(1,AF15)))^2/$B$5))-(MAX(0,MIN(1,AE15))^2/(MAX(0,MIN(1,AE15))^2+(1-MAX(0,MIN(1,AE15)))^2/$B$5)))) -> 0
A17: 0.12 | D17: =A17 -> 0.12 | E17: =(G17-G16)/(A17-A16) -> 0.62106102 | F17: =G17/A17 -> 0.29880478 | G17: =A17^2/(A17^2+(1-A17)^2/$B$5) -> 0.035856574 | L17: 7 | M17: =IF(ABS(M16-$B$11/$B$9*((MAX(0,MIN(1,M16))^2/(MAX(0,MIN(1,M16))^2+(1-MAX(0,MIN(1,M16)))^2/$B$5))-(MAX(0,MIN(1,1))^2/(MAX(0,MIN(1,1))^2+(1-MAX(0,MIN(1,1)))^2/$B$5))))<0.000000001,0,M16-$B$11/$B$9*((MAX(0,MIN(1,M16))^2/(MAX(0,MIN(1,M16))^2+(1-MAX(0,MIN(1,M16)))^2/$B$5))-(MAX(0,MIN(1,1))^2/(MAX(0,MIN(1,1))^2+(1-MAX(0,MIN(1,1)))^2/$B$5)))) -> 0.78071985 | N17: =IF(ABS(N16-$B$11/$B$9*((MAX(0,MIN(1,N16))^2/(MAX(0,MIN(1,N16))^2+(1-MAX(0,MIN(1,N16)))^2/$B$5))-(MAX(0,MIN(1,M16))^2/(MAX(0,MIN(1,M16))^2+(1-MAX(0,MIN(1,M16)))^2/$B$5))))<0.000000001,0,N16-$B$11/$B$9*((MAX(0,MIN(1,N16))^2/(MAX(0,MIN(1,N16))^2+(1-MAX(0,MIN(1,N16)))^2/$B$5))-(MAX(0,MIN(1,M16))^2/(MAX(0,MIN(1,M16))^2+(1-MAX(0,MIN(1,M16)))^2/$B$5)))) -> 0.68938211 | O17: =IF(ABS(O16-$B$11/$B$9*((MAX(0,MIN(1,O16))^2/(MAX(0,MIN(1,O16))^2+(1-MAX(0,MIN(1,O16)))^2/$B$5))-(MAX(0,MIN(1,N16))^2/(MAX(0,MIN(1,N16))^2+(1-MAX(0,MIN(1,N16)))^2/$B$5))))<0.000000001,0,O16-$B$11/$B$9*((MAX(0,MIN(1,O16))^2/(MAX(0,MIN(1,O16))^2+(1-MAX(0,MIN(1,O16)))^2/$B$5))-(MAX(0,MIN(1,N16))^2/(MAX(0,MIN(1,N16))^2+(1-MAX(0,MIN(1,N16)))^2/$B$5)))) -> 0.60912954 | P17: =IF(ABS(P16-$B$11/$B$9*((MAX(0,MIN(1,P16))^2/(MAX(0,MIN(1,P16))^2+(1-MAX(0,MIN(1,P16)))^2/$B$5))-(MAX(0,MIN(1,O16))^2/(MAX(0,MIN(1,O16))^2+(1-MAX(0,MIN(1,O16)))^2/$B$5))))<0.000000001,0,P16-$B$11/$B$9*((MAX(0,MIN(1,P16))^2/(MAX(0,MIN(1,P16))^2+(1-MAX(0,MIN(1,P16)))^2/$B$5))-(MAX(0,MIN(1,O16))^2/(MAX(0,MIN(1,O16))^2+(1-MAX(0,MIN(1,O16)))^2/$B$5)))) -> 0.49652829 | Q17: =IF(ABS(Q16-$B$11/$B$9*((MAX(0,MIN(1,Q16))^2/(MAX(0,MIN(1,Q16))^2+(1-MAX(0,MIN(1,Q16)))^2/$B$5))-(MAX(0,MIN(1,P16))^2/(MAX(0,MIN(1,P16))^2+(1-MAX(0,MIN(1,P16)))^2/$B$5))))<0.000000001,0,Q16-$B$11/$B$9*((MAX(0,MIN(1,Q16))^2/(MAX(0,MIN(1,Q16))^2+(1-MAX(0,MIN(1,Q16)))^2/$B$5))-(MAX(0,MIN(1,P16))^2/(MAX(0,MIN(1,P16))^2+(1-MAX(0,MIN(1,P16)))^2/$B$5)))) -> 0.11594391 | R17: =IF(ABS(R16-$B$11/$B$9*((MAX(0,MIN(1,R16))^2/(MAX(0,MIN(1,R16))^2+(1-MAX(0,MIN(1,R16)))^2/$B$5))-(MAX(0,MIN(1,Q16))^2/(MAX(0,MIN(1,Q16))^2+(1-MAX(0,MIN(1,Q16)))^2/$B$5))))<0.000000001,0,R16-$B$11/$B$9*((MAX(0,MIN(1,R16))^2/(MAX(0,MIN(1,R16))^2+(1-MAX(0,MIN(1,R16)))^2/$B$5))-(MAX(0,MIN(1,Q16))^2/(MAX(0,MIN(1,Q16))^2+(1-MAX(0,MIN(1,Q16)))^2/$B$5)))) -> 1.5987899e-05 | S17: =IF(ABS(S16-$B$11/$B$9*((MAX(0,MIN(1,S16))^2/(MAX(0,MIN(1,S16))^2+(1-MAX(0,MIN(1,S16)))^2/$B$5))-(MAX(0,MIN(1,R16))^2/(MAX(0,MIN(1,R16))^2+(1-MAX(0,MIN(1,R16)))^2/$B$5))))<0.000000001,0,S16-$B$11/$B$9*((MAX(0,MIN(1,S16))^2/(MAX(0,MIN(1,S16))^2+(1-MAX(0,MIN(1,S16)))^2/$B$5))-(MAX(0,MIN(1,R16))^2/(MAX(0,MIN(1,R16))^2+(1-MAX(0,MIN(1,R16)))^2/$B$5)))) -> 0 | T17: =IF(ABS(T16-$B$11/$B$9*((MAX(0,MIN(1,T16))^2/(MAX(0,MIN(1,T16))^2+(1-MAX(0,MIN(1,T16)))^2/$B$5))-(MAX(0,MIN(1,S16))^2/(MAX(0,MIN(1,S16))^2+(1-MAX(0,MIN(1,S16)))^2/$B$5))))<0.000000001,0,T16-$B$11/$B$9*((MAX(0,MIN(1,T16))^2/(MAX(0,MIN(1,T16))^2+(1-MAX(0,MIN(1,T16)))^2/$B$5))-(MAX(0,MIN(1,S16))^2/(MAX(0,MIN(1,S16))^2+(1-MAX(0,MIN(1,S16)))^2/$B$5)))) -> 0 | U17: =IF(ABS(U16-$B$11/$B$9*((MAX(0,MIN(1,U16))^2/(MAX(0,MIN(1,U16))^2+(1-MAX(0,MIN(1,U16)))^2/$B$5))-(MAX(0,MIN(1,T16))^2/(MAX(0,MIN(1,T16))^2+(1-MAX(0,MIN(1,T16)))^2/$B$5))))<0.000000001,0,U16-$B$11/$B$9*((MAX(0,MIN(1,U16))^2/(MAX(0,MIN(1,U16))^2+(1-MAX(0,MIN(1,U16)))^2/$B$5))-(MAX(0,MIN(1,T16))^2/(MAX(0,MIN(1,T16))^2+(1-MAX(0,MIN(1,T16)))^2/$B$5)))) -> 0 | ... AF17: =IF(ABS(AF16-$B$11/$B$9*((MAX(0,MIN(1,AF16))^2/(MAX(0,MIN(1,AF16))^2+(1-MAX(0,MIN(1,AF16)))^2/$B$5))-(MAX(0,MIN(1,AE16))^2/(MAX(0,MIN(1,AE16))^2+(1-MAX(0,MIN(1,AE16)))^2/$B$5))))<0.000000001,0,AF16-$B$11/$B$9*((MAX(0,MIN(1,AF16))^2/(MAX(0,MIN(1,AF16))^2+(1-MAX(0,MIN(1,AF16)))^2/$B$5))-(MAX(0,MIN(1,AE16))^2/(MAX(0,MIN(1,AE16))^2+(1-MAX(0,MIN(1,AE16)))^2/$B$5)))) -> 0
A18: 0.13 | D18: =A18 -> 0.13 | E18: =(G18-G17)/(A18-A17) -> 0.68903594 | F18: =G18/A18 -> 0.32882256 | G18: =A18^2/(A18^2+(1-A18)^2/$B$5) -> 0.042746933 | L18: 8 | M18: =IF(ABS(M17-$B$11/$B$9*((MAX(0,MIN(1,M17))^2/(MAX(0,MIN(1,M17))^2+(1-MAX(0,MIN(1,M17)))^2/$B$5))-(MAX(0,MIN(1,1))^2/(MAX(0,MIN(1,1))^2+(1-MAX(0,MIN(1,1)))^2/$B$5))))<0.000000001,0,M17-$B$11/$B$9*((MAX(0,MIN(1,M17))^2/(MAX(0,MIN(1,M17))^2+(1-MAX(0,MIN(1,M17)))^2/$B$5))-(MAX(0,MIN(1,1))^2/(MAX(0,MIN(1,1))^2+(1-MAX(0,MIN(1,1)))^2/$B$5)))) -> 0.79531165 | N18: =IF(ABS(N17-$B$11/$B$9*((MAX(0,MIN(1,N17))^2/(MAX(0,MIN(1,N17))^2+(1-MAX(0,MIN(1,N17)))^2/$B$5))-(MAX(0,MIN(1,M17))^2/(MAX(0,MIN(1,M17))^2+(1-MAX(0,MIN(1,M17)))^2/$B$5))))<0.000000001,0,N17-$B$11/$B$9*((MAX(0,MIN(1,N17))^2/(MAX(0,MIN(1,N17))^2+(1-MAX(0,MIN(1,N17)))^2/$B$5))-(MAX(0,MIN(1,M17))^2/(MAX(0,MIN(1,M17))^2+(1-MAX(0,MIN(1,M17)))^2/$B$5)))) -> 0.71022648 | O18: =IF(ABS(O17-$B$11/$B$9*((MAX(0,MIN(1,O17))^2/(MAX(0,MIN(1,O17))^2+(1-MAX(0,MIN(1,O17)))^2/$B$5))-(MAX(0,MIN(1,N17))^2/(MAX(0,MIN(1,N17))^2+(1-MAX(0,MIN(1,N17)))^2/$B$5))))<0.000000001,0,O17-$B$11/$B$9*((MAX(0,MIN(1,O17))^2/(MAX(0,MIN(1,O17))^2+(1-MAX(0,MIN(1,O17)))^2/$B$5))-(MAX(0,MIN(1,N17))^2/(MAX(0,MIN(1,N17))^2+(1-MAX(0,MIN(1,N17)))^2/$B$5)))) -> 0.63934472 | P18: =IF(ABS(P17-$B$11/$B$9*((MAX(0,MIN(1,P17))^2/(MAX(0,MIN(1,P17))^2+(1-MAX(0,MIN(1,P17)))^2/$B$5))-(MAX(0,MIN(1,O17))^2/(MAX(0,MIN(1,O17))^2+(1-MAX(0,MIN(1,O17)))^2/$B$5))))<0.000000001,0,P17-$B$11/$B$9*((MAX(0,MIN(1,P17))^2/(MAX(0,MIN(1,P17))^2+(1-MAX(0,MIN(1,P17)))^2/$B$5))-(MAX(0,MIN(1,O17))^2/(MAX(0,MIN(1,O17))^2+(1-MAX(0,MIN(1,O17)))^2/$B$5)))) -> 0.56143829 | Q18: =IF(ABS(Q17-$B$11/$B$9*((MAX(0,MIN(1,Q17))^2/(MAX(0,MIN(1,Q17))^2+(1-MAX(0,MIN(1,Q17)))^2/$B$5))-(MAX(0,MIN(1,P17))^2/(MAX(0,MIN(1,P17))^2+(1-MAX(0,MIN(1,P17)))^2/$B$5))))<0.000000001,0,Q17-$B$11/$B$9*((MAX(0,MIN(1,Q17))^2/(MAX(0,MIN(1,Q17))^2+(1-MAX(0,MIN(1,Q17)))^2/$B$5))-(MAX(0,MIN(1,P17))^2/(MAX(0,MIN(1,P17))^2+(1-MAX(0,MIN(1,P17)))^2/$B$5)))) -> 0.35712575 | R18: =IF(ABS(R17-$B$11/$B$9*((MAX(0,MIN(1,R17))^2/(MAX(0,MIN(1,R17))^2+(1-MAX(0,MIN(1,R17)))^2/$B$5))-(MAX(0,MIN(1,Q17))^2/(MAX(0,MIN(1,Q17))^2+(1-MAX(0,MIN(1,Q17)))^2/$B$5))))<0.000000001,0,R17-$B$11/$B$9*((MAX(0,MIN(1,R17))^2/(MAX(0,MIN(1,R17))^2+(1-MAX(0,MIN(1,R17)))^2/$B$5))-(MAX(0,MIN(1,Q17))^2/(MAX(0,MIN(1,Q17))^2+(1-MAX(0,MIN(1,Q17)))^2/$B$5)))) -> 0.012804184 | S18: =IF(ABS(S17-$B$11/$B$9*((MAX(0,MIN(1,S17))^2/(MAX(0,MIN(1,S17))^2+(1-MAX(0,MIN(1,S17)))^2/$B$5))-(MAX(0,MIN(1,R17))^2/(MAX(0,MIN(1,R17))^2+(1-MAX(0,MIN(1,R17)))^2/$B$5))))<0.000000001,0,S17-$B$11/$B$9*((MAX(0,MIN(1,S17))^2/(MAX(0,MIN(1,S17))^2+(1-MAX(0,MIN(1,S17)))^2/$B$5))-(MAX(0,MIN(1,R17))^2/(MAX(0,MIN(1,R17))^2+(1-MAX(0,MIN(1,R17)))^2/$B$5)))) -> 0 | T18: =IF(ABS(T17-$B$11/$B$9*((MAX(0,MIN(1,T17))^2/(MAX(0,MIN(1,T17))^2+(1-MAX(0,MIN(1,T17)))^2/$B$5))-(MAX(0,MIN(1,S17))^2/(MAX(0,MIN(1,S17))^2+(1-MAX(0,MIN(1,S17)))^2/$B$5))))<0.000000001,0,T17-$B$11/$B$9*((MAX(0,MIN(1,T17))^2/(MAX(0,MIN(1,T17))^2+(1-MAX(0,MIN(1,T17)))^2/$B$5))-(MAX(0,MIN(1,S17))^2/(MAX(0,MIN(1,S17))^2+(1-MAX(0,MIN(1,S17)))^2/$B$5)))) -> 0 | U18: =IF(ABS(U17-$B$11/$B$9*((MAX(0,MIN(1,U17))^2/(MAX(0,MIN(1,U17))^2+(1-MAX(0,MIN(1,U17)))^2/$B$5))-(MAX(0,MIN(1,T17))^2/(MAX(0,MIN(1,T17))^2+(1-MAX(0,MIN(1,T17)))^2/$B$5))))<0.000000001,0,U17-$B$11/$B$9*((MAX(0,MIN(1,U17))^2/(MAX(0,MIN(1,U17))^2+(1-MAX(0,MIN(1,U17)))^2/$B$5))-(MAX(0,MIN(1,T17))^2/(MAX(0,MIN(1,T17))^2+(1-MAX(0,MIN(1,T17)))^2/$B$5)))) -> 0 | ... AF18: =IF(ABS(AF17-$B$11/$B$9*((MAX(0,MIN(1,AF17))^2/(MAX(0,MIN(1,AF17))^2+(1-MAX(0,MIN(1,AF17)))^2/$B$5))-(MAX(0,MIN(1,AE17))^2/(MAX(0,MIN(1,AE17))^2+(1-MAX(0,MIN(1,AE17)))^2/$B$5))))<0.000000001,0,AF17-$B$11/$B$9*((MAX(0,MIN(1,AF17))^2/(MAX(0,MIN(1,AF17))^2+(1-MAX(0,MIN(1,AF17)))^2/$B$5))-(MAX(0,MIN(1,AE17))^2/(MAX(0,MIN(1,AE17))^2+(1-MAX(0,MIN(1,AE17)))^2/$B$5)))) -> 0
A19: 0.14 | D19: =A19 -> 0.14 | E19: =(G19-G18)/(A19-A18) -> 0.75869138 | F19: =G19/A19 -> 0.35952748 | G19: =A19^2/(A19^2+(1-A19)^2/$B$5) -> 0.050333847 | L19: 9 | M19: =IF(ABS(M18-$B$11/$B$9*((MAX(0,MIN(1,M18))^2/(MAX(0,MIN(1,M18))^2+(1-MAX(0,MIN(1,M18)))^2/$B$5))-(MAX(0,MIN(1,1))^2/(MAX(0,MIN(1,1))^2+(1-MAX(0,MIN(1,1)))^2/$B$5))))<0.000000001,0,M18-$B$11/$B$9*((MAX(0,MIN(1,M18))^2/(MAX(0,MIN(1,M18))^2+(1-MAX(0,MIN(1,M18)))^2/$B$5))-(MAX(0,MIN(1,1))^2/(MAX(0,MIN(1,1))^2+(1-MAX(0,MIN(1,1)))^2/$B$5)))) -> 0.80763881 | N19: =IF(ABS(N18-$B$11/$B$9*((MAX(0,MIN(1,N18))^2/(MAX(0,MIN(1,N18))^2+(1-MAX(0,MIN(1,N18)))^2/$B$5))-(MAX(0,MIN(1,M18))^2/(MAX(0,MIN(1,M18))^2+(1-MAX(0,MIN(1,M18)))^2/$B$5))))<0.000000001,0,N18-$B$11/$B$9*((MAX(0,MIN(1,N18))^2/(MAX(0,MIN(1,N18))^2+(1-MAX(0,MIN(1,N18)))^2/$B$5))-(MAX(0,MIN(1,M18))^2/(MAX(0,MIN(1,M18))^2+(1-MAX(0,MIN(1,M18)))^2/$B$5)))) -> 0.72744567 | O19: =IF(ABS(O18-$B$11/$B$9*((MAX(0,MIN(1,O18))^2/(MAX(0,MIN(1,O18))^2+(1-MAX(0,MIN(1,O18)))^2/$B$5))-(MAX(0,MIN(1,N18))^2/(MAX(0,MIN(1,N18))^2+(1-MAX(0,MIN(1,N18)))^2/$B$5))))<0.000000001,0,O18-$B$11/$B$9*((MAX(0,MIN(1,O18))^2/(MAX(0,MIN(1,O18))^2+(1-MAX(0,MIN(1,O18)))^2/$B$5))-(MAX(0,MIN(1,N18))^2/(MAX(0,MIN(1,N18))^2+(1-MAX(0,MIN(1,N18)))^2/$B$5)))) -> 0.66258129 | P19: =IF(ABS(P18-$B$11/$B$9*((MAX(0,MIN(1,P18))^2/(MAX(0,MIN(1,P18))^2+(1-MAX(0,MIN(1,P18)))^2/$B$5))-(MAX(0,MIN(1,O18))^2/(MAX(0,MIN(1,O18))^2+(1-MAX(0,MIN(1,O18)))^2/$B$5))))<0.000000001,0,P18-$B$11/$B$9*((MAX(0,MIN(1,P18))^2/(MAX(0,MIN(1,P18))^2+(1-MAX(0,MIN(1,P18)))^2/$B$5))-(MAX(0,MIN(1,O18))^2/(MAX(0,MIN(1,O18))^2+(1-MAX(0,MIN(1,O18)))^2/$B$5)))) -> 0.59854692 | Q19: =IF(ABS(Q18-$B$11/$B$9*((MAX(0,MIN(1,Q18))^2/(MAX(0,MIN(1,Q18))^2+(1-MAX(0,MIN(1,Q18)))^2/$B$5))-(MAX(0,MIN(1,P18))^2/(MAX(0,MIN(1,P18))^2+(1-MAX(0,MIN(1,P18)))^2/$B$5))))<0.000000001,0,Q18-$B$11/$B$9*((MAX(0,MIN(1,Q18))^2/(MAX(0,MIN(1,Q18))^2+(1-MAX(0,MIN(1,Q18)))^2/$B$5))-(MAX(0,MIN(1,P18))^2/(MAX(0,MIN(1,P18))^2+(1-MAX(0,MIN(1,P18)))^2/$B$5)))) -> 0.50501141 | R19: =IF(ABS(R18-$B$11/$B$9*((MAX(0,MIN(1,R18))^2/(MAX(0,MIN(1,R18))^2+(1-MAX(0,MIN(1,R18)))^2/$B$5))-(MAX(0,MIN(1,Q18))^2/(MAX(0,MIN(1,Q18))^2+(1-MAX(0,MIN(1,Q18)))^2/$B$5))))<0.000000001,0,R18-$B$11/$B$9*((MAX(0,MIN(1,R18))^2/(MAX(0,MIN(1,R18))^2+(1-MAX(0,MIN(1,R18)))^2/$B$5))-(MAX(0,MIN(1,Q18))^2/(MAX(0,MIN(1,Q18))^2+(1-MAX(0,MIN(1,Q18)))^2/$B$5)))) -> 0.15942903 | S19: =IF(ABS(S18-$B$11/$B$9*((MAX(0,MIN(1,S18))^2/(MAX(0,MIN(1,S18))^2+(1-MAX(0,MIN(1,S18)))^2/$B$5))-(MAX(0,MIN(1,R18))^2/(MAX(0,MIN(1,R18))^2+(1-MAX(0,MIN(1,R18)))^2/$B$5))))<0.000000001,0,S18-$B$11/$B$9*((MAX(0,MIN(1,S18))^2/(MAX(0,MIN(1,S18))^2+(1-MAX(0,MIN(1,S18)))^2/$B$5))-(MAX(0,MIN(1,R18))^2/(MAX(0,MIN(1,R18))^2+(1-MAX(0,MIN(1,R18)))^2/$B$5)))) -> 0.00012933405 | T19: =IF(ABS(T18-$B$11/$B$9*((MAX(0,MIN(1,T18))^2/(MAX(0,MIN(1,T18))^2+(1-MAX(0,MIN(1,T18)))^2/$B$5))-(MAX(0,MIN(1,S18))^2/(MAX(0,MIN(1,S18))^2+(1-MAX(0,MIN(1,S18)))^2/$B$5))))<0.000000001,0,T18-$B$11/$B$9*((MAX(0,MIN(1,T18))^2/(MAX(0,MIN(1,T18))^2+(1-MAX(0,MIN(1,T18)))^2/$B$5))-(MAX(0,MIN(1,S18))^2/(MAX(0,MIN(1,S18))^2+(1-MAX(0,MIN(1,S18)))^2/$B$5)))) -> 0 | U19: =IF(ABS(U18-$B$11/$B$9*((MAX(0,MIN(1,U18))^2/(MAX(0,MIN(1,U18))^2+(1-MAX(0,MIN(1,U18)))^2/$B$5))-(MAX(0,MIN(1,T18))^2/(MAX(0,MIN(1,T18))^2+(1-MAX(0,MIN(1,T18)))^2/$B$5))))<0.000000001,0,U18-$B$11/$B$9*((MAX(0,MIN(1,U18))^2/(MAX(0,MIN(1,U18))^2+(1-MAX(0,MIN(1,U18)))^2/$B$5))-(MAX(0,MIN(1,T18))^2/(MAX(0,MIN(1,T18))^2+(1-MAX(0,MIN(1,T18)))^2/$B$5)))) -> 0 | ... AF19: =IF(ABS(AF18-$B$11/$B$9*((MAX(0,MIN(1,AF18))^2/(MAX(0,MIN(1,AF18))^2+(1-MAX(0,MIN(1,AF18)))^2/$B$5))-(MAX(0,MIN(1,AE18))^2/(MAX(0,MIN(1,AE18))^2+(1-MAX(0,MIN(1,AE18)))^2/$B$5))))<0.000000001,0,AF18-$B$11/$B$9*((MAX(0,MIN(1,AF18))^2/(MAX(0,MIN(1,AF18))^2+(1-MAX(0,MIN(1,AF18)))^2/$B$5))-(MAX(0,MIN(1,AE18))^2/(MAX(0,MIN(1,AE18))^2+(1-MAX(0,MIN(1,AE18)))^2/$B$5)))) -> 0
